Workbook

Sheet PASH.r1
A1: Samples | B1: Time.raw | C1: Time | D1: Strain | E1: Light | F1: Substrate | G1: HCO3 | H1: NO2 | I1: NH4 | J1: TIN | K1: S2O3 | L1: HCO3_raw | M1: NO2_Raw | N1: NH4_Raw | O1: S_Raw | P1: NH4_1 | Q1: NH4_2 | R1: NH4_3 | S1: OD600.raw1 | T1: OD600.raw2 | U1: OD600.raw3
A2: P1-D-3.29 | B2: 48 | C2: 0 | D2: Paracoccus | E2: Dark | F2: NH4-HCO3 | G2: =30*(L2-0.0549)/0.0239 -> 92.216952 | H2: =(3.9165*M2-0.5231)*30 -> -0.78460053 | I2: =(11.007*N2-0.65)*20 -> 30.301538 | J2: =H2+I2 -> 29.516937 | K2: =(0.3548*O2 + 0.0099)*30 -> 6.9519652 | L2: 0.12836617 | M2: 0.12688539 | N2: =AVERAGE(P2:R2) -> 0.1967 | O2: 0.6252316 | P2: 0.1964 | Q2: 0.197
A3: P2 | B3: 48 | C3: 0 | D3: Paracoccus | E3: Dark | F3: NH4-HCO3 | G3: =30*(L3-0.0549)/0.0239 -> 88.213117 | H3: =(3.9165*M3-0.5231)*30 -> -3.9435 | I3: =(11.007*N3-0.65)*20 -> 27.428711 | J3: =H3+I3 -> 23.485211 | K3: =(0.3548*O3 + 0.0099)*30 -> 7.0515705 | L3: 0.12517645 | M3: 0.1 | N3: =AVERAGE(P3:R3) -> 0.18365 | O3: 0.63458949 | P3: 0.1826 | Q3: 0.1847
A4: P3 | B4: 48 | C4: 0 | D4: Paracoccus | E4: Dark | F4: NH4-HCO3 | G4: =30*(L4-0.0549)/0.0239 -> 91.181488 | H4: =(3.9165*M4-0.5231)*30 -> -10.779679 | I4: =(11.007*N4-0.65)*20 -> 26.063843 | J4: =H4+I4 -> 15.284164 | K4: =(0.3548*O4 + 0.0099)*30 -> 6.9966132 | L4: 0.12754125 | M4: 0.04181728 | N4: =AVERAGE(P4:R4) -> 0.17745 | O4: 0.62942627 | P4: 0.1782 | Q4: 0.1767
A5: A1 | B5: 48 | C5: 0 | D5: Aliidiomarina | E5: Dark | F5: NH4-HCO3 | G5: =30*(L5-0.0549)/0.0239 -> 93.923263 | H5: =(3.9165*M5-0.5231)*30 -> -0.061916216 | I5: =(11.007*N5-0.65)*20 -> 23.334107 | J5: =H5+I5 -> 23.272191 | K5: =(0.3548*O5 + 0.0099)*30 -> 7.2069003 | L5: 0.12972553 | M5: 0.13303616 | N5: =AVERAGE(P5:R5) -> 0.16505 | O5: 0.64918267 | P5: 0.165 | Q5: 0.1651
A6: A2 | B6: 48 | C6: 0 | D6: Aliidiomarina | E6: Dark | F6: NH4-HCO3 | G6: =30*(L6-0.0549)/0.0239 -> 100.86378 | H6: =(3.9165*M6-0.5231)*30 -> -3.9435 | I6: =(11.007*N6-0.65)*20 -> 22.288442 | J6: =H6+I6 -> 18.344942 | K6: =(0.3548*O6 + 0.0099)*30 -> 7.1787638 | L6: 0.13525481 | M6: 0.1 | N6: =AVERAGE(P6:R6) -> 0.1603 | O6: 0.64653926 | P6: 0.1592 | Q6: 0.1614
A7: A3 | B7: 48 | C7: 0 | D7: Aliidiomarina | E7: Dark | F7: NH4-HCO3 | G7: =30*(L7-0.0549)/0.0239 -> 93.54486 | H7: =(3.9165*M7-0.5231)*30 -> -0.068714281 | I7: =(11.007*N7-0.65)*20 -> 27.153536 | J7: =H7+I7 -> 27.084822 | K7: =(0.3548*O7 + 0.0099)*30 -> 7.3368125 | L7: 0.12942407 | M7: 0.1329783 | N7: =AVERAGE(P7:R7) -> 0.1824 | O7: 0.66138787 | P7: 0.1823 | Q7: 0.1825
A8: S1 | B8: 48 | C8: 0 | D8: SynCom | E8: Dark | F8: NH4-HCO3 | G8: =30*(L8-0.0549)/0.0239 -> 91.212494 | H8: =(3.9165*M8-0.5231)*30 -> 0.77411434 | I8: =(11.007*N8-0.65)*20 -> 27.362669 | J8: =H8+I8 -> 28.136783 | K8: =(0.3548*O8 + 0.0099)*30 -> 7.3501958 | L8: 0.12756595 | M8: 0.14015162 | N8: =AVERAGE(P8:R8) -> 0.18335 | O8: 0.66264522 | P8: 0.1946 | Q8: 0.1721
A9: S2 | B9: 48 | C9: 0 | D9: SynCom | E9: Dark | F9: NH4-HCO3 | G9: =30*(L9-0.0549)/0.0239 -> 102.43378 | H9: =(3.9165*M9-0.5231)*30 -> -2.822673 | I9: =(11.007*N9-0.65)*20 -> 27.076487 | J9: =H9+I9 -> 24.253814 | K9: =(0.3548*O9 + 0.0099)*30 -> 7.1809441 | L9: 0.13650558 | M9: 0.10953936 | N9: =AVERAGE(P9:R9) -> 0.18205 | O9: 0.64674409 | P9: 0.1833 | Q9: 0.1808
A10: S3 | B10: 48 | C10: 0 | D10: SynCom | E10: Dark | F10: NH4-HCO3 | G10: =30*(L10-0.0549)/0.0239 -> 99.101772 | H10: =(3.9165*M10-0.5231)*30 -> 0.082443921 | I10: =(11.007*N10-0.65)*20 -> 24.720989 | J10: =H10+I10 -> 24.803433 | K10: =(0.3548*O10 + 0.0099)*30 -> 7.2046695 | L10: 0.13385108 | M10: 0.13426481 | N10: =AVERAGE(P10:R10) -> 0.17135 | O10: 0.64897308 | P10: 0.1727 | Q10: 0.17
A11: P1-I | B11: 48 | C11: 0 | D11: Paracoccus | E11: IR | F11: NH4-HCO3 | G11: =30*(L11-0.0549)/0.0239 -> 100.23247 | H11: =(3.9165*M11-0.5231)*30 -> -0.06056533 | I11: =(11.007*N11-0.65)*20 -> 32.546966 | J11: =H11+I11 -> 32.486401 | K11: =(0.3548*O11 + 0.0099)*30 -> 6.9854292 | L11: 0.13475187 | M11: 0.13304766 | N11: =AVERAGE(P11:R11) -> 0.2069 | O11: 0.62837553 | P11: 0.1959 | Q11: 0.2179
A12: P2 | B12: 48 | C12: 0 | D12: Paracoccus | E12: IR | F12: NH4-HCO3 | G12: =30*(L12-0.0549)/0.0239 -> 98.256178 | H12: =(3.9165*M12-0.5231)*30 -> -12.388083 | I12: =(11.007*N12-0.65)*20 -> 25.733633 | J12: =H12+I12 -> 13.34555 | K12: =(0.3548*O12 + 0.0099)*30 -> 7.0763265 | L12: 0.13317742 | M12: 0.028128153 | N12: =AVERAGE(P12:R12) -> 0.17595 | O12: 0.63691531 | P12: 0.1771 | Q12: 0.1748
A13: P3 | B13: 48 | C13: 0 | D13: Paracoccus | E13: IR | F13: NH4-HCO3 | G13: =30*(L13-0.0549)/0.0239 -> 98.73075 | H13: =(3.9165*M13-0.5231)*30 -> -12.554143 | I13: =(11.007*N13-0.65)*20 -> 26.085857 | J13: =H13+I13 -> 13.531714 | K13: =(0.3548*O13 + 0.0099)*30 -> 6.9908027 | L13: 0.1335555 | M13: 0.026714812 | N13: =AVERAGE(P13:R13) -> 0.17755 | O13: 0.62888037 | P13: 0.1808 | Q13: 0.1743
... A31: H3-I | B31: 48 | C31: 0 | D31: Halomonas | E31: IR | F31: NO2 | G31: =30*(L31-0.0549)/0.0239 -> 108.36708 | H31: =(3.9165*M31-0.5231)*30 -> 32.455689 | I31: =(11.007*N31-0.65)*20 -> 27.879998 | J31: =H31+I31 -> 60.335687 | K31: =(0.3548*O31 + 0.0099)*30 -> 7.4790143 | L31: 0.14123244 | M31: 0.40979352 | N31: =AVERAGE(P31:R31) -> 0.1857 | O31: 0.67474768 | P31: 0.1757 | Q31: 0.1957
A32: P1-D-3.31 | B32: 96 | C32: =B32-48 -> 48 | D32: Paracoccus | E32: Dark | F32: NH4-HCO3 | G32: =30*(L32-0.0549)/0.0239 -> 84.233628 | H32: =(3.9165*M32-0.5231)*30 -> -3.9435 | I32: =(11.007*N32-0.65)*20 -> 43.884176 | J32: =H32+I32 -> 39.940676 | K32: =(0.3548*O32 + 0.0099)*30 -> 5.9371857 | L32: 0.12200612 | M32: 0.1 | N32: =AVERAGE(P32:R32) -> 0.2584 | O32: 0.52989344 | P32: 0.2584
A33: P2 | B33: 96 | C33: =B33-48 -> 48 | D33: Paracoccus | E33: Dark | F33: NH4-HCO3 | G33: =30*(L33-0.0549)/0.0239 -> 72.110771 | H33: =(3.9165*M33-0.5231)*30 -> -3.9435 | I33: =(11.007*N33-0.65)*20 -> 48.705242 | J33: =H33+I33 -> 44.761742 | K33: =(0.3548*O33 + 0.0099)*30 -> 6.1888985 | L33: 0.11234825 | M33: 0.1 | N33: =AVERAGE(P33:R33) -> 0.2803 | O33: 0.55354177 | P33: 0.2803
A34: P3 | B34: 96 | C34: =B34-48 -> 48 | D34: Paracoccus | E34: Dark | F34: NH4-HCO3 | G34: =30*(L34-0.0549)/0.0239 -> 78.70551 | H34: =(3.9165*M34-0.5231)*30 -> -3.9435 | I34: =(11.007*N34-0.65)*20 -> 39.657488 | J34: =H34+I34 -> 35.713988 | K34: =(0.3548*O34 + 0.0099)*30 -> 6.32357 | L34: 0.11760206 | M34: 0.1 | N34: =AVERAGE(P34:R34) -> 0.2392 | O34: 0.5661941 | P34: 0.2392
A35: A1 | B35: 96 | C35: =B35-48 -> 48 | D35: Aliidiomarina | E35: Dark | F35: NH4-HCO3 | G35: =30*(L35-0.0549)/0.0239 -> 47.222154 | H35: =(3.9165*M35-0.5231)*30 -> -3.9435 | I35: =(11.007*N35-0.65)*20 -> 46.283702 | J35: =H35+I35 -> 42.340202 | K35: =(0.3548*O35 + 0.0099)*30 -> 4.7192518 | L35: 0.092520316 | M35: 0.1 | N35: =AVERAGE(P35:R35) -> 0.2693 | O35: 0.41546898 | P35: 0.2693
A36: A2 | B36: 96 | C36: =B36-48 -> 48 | D36: Aliidiomarina | E36: Dark | F36: NH4-HCO3 | G36: =30*(L36-0.0549)/0.0239 -> 80.712119 | H36: =(3.9165*M36-0.5231)*30 -> -3.9435 | I36: =(11.007*N36-0.65)*20 -> 47.120234 | J36: =H36+I36 -> 43.176734 | K36: =(0.3548*O36 + 0.0099)*30 -> 6.9471768 | L36: 0.11920065 | M36: 0.1 | N36: =AVERAGE(P36:R36) -> 0.2731 | O36: 0.62478174 | P36: 0.2731
A37: A3 | B37: 96 | C37: =B37-48 -> 48 | D37: Aliidiomarina | E37: Dark | F37: NH4-HCO3 | G37: =30*(L37-0.0549)/0.0239 -> 84.123105 | H37: =(3.9165*M37-0.5231)*30 -> -3.9435 | I37: =(11.007*N37-0.65)*20 -> 42.761462 | J37: =H37+I37 -> 38.817962 | K37: =(0.3548*O37 + 0.0099)*30 -> 7.0409296 | L37: 0.12191807 | M37: 0.1 | N37: =AVERAGE(P37:R37) -> 0.2533 | O37: 0.63358978 | P37: 0.2533
A38: S1 | B38: 96 | C38: =B38-48 -> 48 | D38: SynCom | E38: Dark | F38: NH4-HCO3 | G38: =30*(L38-0.0549)/0.0239 -> 79.162023 | H38: =(3.9165*M38-0.5231)*30 -> -1.4811051 | I38: =(11.007*N38-0.65)*20 -> 37.279976 | J38: =H38+I38 -> 35.798871 | K38: =(0.3548*O38 + 0.0099)*30 -> 6.885246 | L38: 0.11796574 | M38: 0.12095744 | N38: =AVERAGE(P38:R38) -> 0.2284 | O38: 0.61896336 | P38: 0.2284
A39: S2 | B39: 96 | C39: =B39-48 -> 48 | D39: SynCom | E39: Dark | F39: NH4-HCO3 | G39: =30*(L39-0.0549)/0.0239 -> 88.625741 | H39: =(3.9165*M39-0.5231)*30 -> -0.31119714 | I39: =(11.007*N39-0.65)*20 -> 44.808764 | J39: =H39+I39 -> 44.497567 | K39: =(0.3548*O39 + 0.0099)*30 -> 6.909748 | L39: 0.12550517 | M39: 0.13091453 | N39: =AVERAGE(P39:R39) -> 0.2626 | O39: 0.62126532 | P39: 0.2626
A40: S3 | B40: 96 | C40: =B40-48 -> 48 | D40: SynCom | E40: Dark | F40: NH4-HCO3 | G40: =30*(L40-0.0549)/0.0239 -> 85.244312 | H40: =(3.9165*M40-0.5231)*30 -> -3.9435 | I40: =(11.007*N40-0.65)*20 -> 43.311812 | J40: =H40+I40 -> 39.368312 | K40: =(0.3548*O40 + 0.0099)*30 -> 6.8640842 | L40: 0.1228113 | M40: 0.1 | N40: =AVERAGE(P40:R40) -> 0.2558 | O40: 0.61697522 | P40: 0.2558
A41: P1-I | B41: 96 | C41: =B41-48 -> 48 | D41: Paracoccus | E41: IR | F41: NH4-HCO3 | G41: =30*(L41-0.0549)/0.0239 -> 95.040467 | H41: =(3.9165*M41-0.5231)*30 -> 17.78902 | I41: =(11.007*N41-0.65)*20 -> 41.220482 | J41: =H41+I41 -> 59.009502 | K41: =(0.3548*O41 + 0.0099)*30 -> 6.4904854 | L41: 0.13061557 | M41: 0.28496549 | N41: =AVERAGE(P41:R41) -> 0.2463 | O41: 0.58187574 | P41: 0.2463
A42: P2 | B42: 96 | C42: =B42-48 -> 48 | D42: Paracoccus | E42: IR | F42: NH4-HCO3 | G42: =30*(L42-0.0549)/0.0239 -> 88.503019 | H42: =(3.9165*M42-0.5231)*30 -> -0.81193488 | I42: =(11.007*N42-0.65)*20 -> 41.638748 | J42: =H42+I42 -> 40.826813 | K42: =(0.3548*O42 + 0.0099)*30 -> 6.5062559 | L42: 0.1254074 | M42: 0.12665275 | N42: =AVERAGE(P42:R42) -> 0.2482 | O42: 0.58335737 | P42: 0.2482
A43: P3 | B43: 96 | C43: =B43-48 -> 48 | D43: Paracoccus | E43: IR | F43: NH4-HCO3 | G43: =30*(L43-0.0549)/0.0239 -> 82.833656 | H43: =(3.9165*M43-0.5231)*30 -> -11.383437 | I43: =(11.007*N43-0.65)*20 -> 42.541322 | J43: =H43+I43 -> 31.157885 | K43: =(0.3548*O43 + 0.0099)*30 -> 6.6404367 | L43: 0.12089081 | M43: 0.036678696 | N43: =AVERAGE(P43:R43) -> 0.2523 | O43: 0.59596361 | P43: 0.2523
... A61: H3-I | B61: 96 | C61: =B61-48 -> 48 | D61: Halomonas | E61: IR | F61: NO2 | G61: =30*(L61-0.0549)/0.0239 -> 70.320244 | H61: =(3.9165*M61-0.5231)*30 -> 31.971267 | I61: =(11.007*N61-0.65)*20 -> 50.862614 | J61: =H61+I61 -> 82.833881 | K61: =(0.3548*O61 + 0.0099)*30 -> 6.7664741 | L61: 0.11092179 | M61: 0.4056706 | N61: =AVERAGE(P61:R61) -> 0.2901 | O61: 0.60780478 | P61: 0.2901
A62: P1-D-4.2 | B62: =B32+48 -> 144 | C62: =B62-48 -> 96 | D62: Paracoccus | E62: Dark | F62: NH4-HCO3 | G62: =30*(L62-0.0549)/0.0239 -> 82.762709 | H62: =(3.9165*M62-0.5231)*30 -> -3.9435 | I62: =(11.007*N62-0.65)*20 -> 26.449088 | J62: =H62+I62 -> 22.505588 | K62: =(0.3548*O62 + 0.0099)*30 -> 6.2444176 | L62: 0.12083429 | M62: 0.1 | N62: =AVERAGE(P62:R62) -> 0.1792 | O62: 0.55875776 | P62: 0.1792
A63: P2 | B63: =B33+48 -> 144 | C63: =B63-48 -> 96 | D63: Paracoccus | E63: Dark | F63: NH4-HCO3 | G63: =30*(L63-0.0549)/0.0239 -> 45.080972 | H63: =(3.9165*M63-0.5231)*30 -> -3.9435 | I63: =(11.007*N63-0.65)*20 -> 16.366676 | J63: =H63+I63 -> 12.423176 | K63: =(0.3548*O63 + 0.0099)*30 -> 5.4949952 | L63: 0.090814508 | M63: 0.1 | N63: =AVERAGE(P63:R63) -> 0.1334 | O63: 0.48834979 | P63: 0.1334
A64: P3 | B64: =B34+48 -> 144 | C64: =B64-48 -> 96 | D64: Paracoccus | E64: Dark | F64: NH4-HCO3 | G64: =30*(L64-0.0549)/0.0239 -> 57.739802 | H64: =(3.9165*M64-0.5231)*30 -> -3.9435 | I64: =(11.007*N64-0.65)*20 -> 22.33247 | J64: =H64+I64 -> 18.38897 | K64: =(0.3548*O64 + 0.0099)*30 -> 5.9907867 | L64: 0.10089938 | M64: 0.1 | N64: =AVERAGE(P64:R64) -> 0.1605 | O64: 0.53492923 | P64: 0.1605
A65: A1 | B65: =B35+48 -> 144 | C65: =B65-48 -> 96 | D65: Aliidiomarina | E65: Dark | F65: NH4-HCO3 | G65: =30*(L65-0.0549)/0.0239 -> 22.657313 | H65: =(3.9165*M65-0.5231)*30 -> -3.9435 | I65: =(11.007*N65-0.65)*20 -> 25.08422 | J65: =H65+I65 -> 21.14072 | K65: =(0.3548*O65 + 0.0099)*30 -> 1.992886 | L65: 0.072950326 | M65: 0.1 | N65: =AVERAGE(P65:R65) -> 0.173 | O65: 0.15932789 | P65: 0.173
A66: A2 | B66: =B36+48 -> 144 | C66: =B66-48 -> 96 | D66: Aliidiomarina | E66: Dark | F66: NH4-HCO3 | G66: =30*(L66-0.0549)/0.0239 -> 44.095761 | H66: =(3.9165*M66-0.5231)*30 -> -3.9435 | I66: =(11.007*N66-0.65)*20 -> 24.665954 | J66: =H66+I66 -> 20.722454 | K66: =(0.3548*O66 + 0.0099)*30 -> 4.1757459 | L66: 0.090029623 | M66: 0.1 | N66: =AVERAGE(P66:R66) -> 0.1711 | O66: 0.36440679 | P66: 0.1711
A67: A3 | B67: =B37+48 -> 144 | C67: =B67-48 -> 96 | D67: Aliidiomarina | E67: Dark | F67: NH4-HCO3 | G67: =30*(L67-0.0549)/0.0239 -> 46.344076 | H67: =(3.9165*M67-0.5231)*30 -> -3.9435 | I67: =(11.007*N67-0.65)*20 -> 29.619104 | J67: =H67+I67 -> 25.675604 | K67: =(0.3548*O67 + 0.0099)*30 -> 5.0230628 | L67: 0.09182078 | M67: 0.1 | N67: =AVERAGE(P67:R67) -> 0.1936 | O67: 0.44401191 | P67: 0.1936
A68: S1 | B68: =B38+48 -> 144 | C68: =B68-48 -> 96 | D68: SynCom | E68: Dark | F68: NH4-HCO3 | G68: =30*(L68-0.0549)/0.0239 -> 70.904705 | H68: =(3.9165*M68-0.5231)*30 -> -3.9435 | I68: =(11.007*N68-0.65)*20 -> 18.36995 | J68: =H68+I68 -> 14.42645 | K68: =(0.3548*O68 + 0.0099)*30 -> 6.7527328 | L68: 0.11138741 | M68: 0.1 | N68: =AVERAGE(P68:R68) -> 0.1425 | O68: 0.60651379 | P68: 0.1425
A69: S2 | B69: =B39+48 -> 144 | C69: =B69-48 -> 96 | D69: SynCom | E69: Dark | F69: NH4-HCO3 | G69: =30*(L69-0.0549)/0.0239 -> 37.41366 | H69: =(3.9165*M69-0.5231)*30 -> -3.9435 | I69: =(11.007*N69-0.65)*20 -> 24.687968 | J69: =H69+I69 -> 20.744468 | K69: =(0.3548*O69 + 0.0099)*30 -> 3.8593612 | L69: 0.084706216 | M69: 0.1 | N69: =AVERAGE(P69:R69) -> 0.1712 | O69: 0.33468256 | P69: 0.1712
A70: S3 | B70: =B40+48 -> 144 | C70: =B70-48 -> 96 | D70: SynCom | E70: Dark | F70: NH4-HCO3 | G70: =30*(L70-0.0549)/0.0239 -> 79.253849 | H70: =(3.9165*M70-0.5231)*30 -> -3.9435 | I70: =(11.007*N70-0.65)*20 -> 23.191016 | J70: =H70+I70 -> 19.247516 | K70: =(0.3548*O70 + 0.0099)*30 -> 6.4521232 | L70: 0.1180389 | M70: 0.1 | N70: =AVERAGE(P70:R70) -> 0.1644 | O70: 0.57827163 | P70: 0.1644
A71: P1-I | B71: =B41+48 -> 144 | C71: =B71-48 -> 96 | D71: Paracoccus | E71: IR | F71: NH4-HCO3 | G71: =30*(L71-0.0549)/0.0239 -> 82.841598 | H71: =(3.9165*M71-0.5231)*30 -> -1.3338594 | I71: =(11.007*N71-0.65)*20 -> 24.357758 | J71: =H71+I71 -> 23.023899 | K71: =(0.3548*O71 + 0.0099)*30 -> 6.2241591 | L71: 0.12089714 | M71: 0.12221065 | N71: =AVERAGE(P71:R71) -> 0.1697 | O71: 0.55685448 | P71: 0.1697
A72: P2 | B72: =B42+48 -> 144 | C72: =B72-48 -> 96 | D72: Paracoccus | E72: IR | F72: NH4-HCO3 | G72: =30*(L72-0.0549)/0.0239 -> 76.466033 | H72: =(3.9165*M72-0.5231)*30 -> -3.9435 | I72: =(11.007*N72-0.65)*20 -> 20.923574 | J72: =H72+I72 -> 16.980074 | K72: =(0.3548*O72 + 0.0099)*30 -> 6.2778434 | L72: 0.11581794 | M72: 0.1 | N72: =AVERAGE(P72:R72) -> 0.1541 | O72: 0.5618981 | P72: 0.1541
A73: P3 | B73: =B43+48 -> 144 | C73: =B73-48 -> 96 | D73: Paracoccus | E73: IR | F73: NH4-HCO3 | G73: =30*(L73-0.0549)/0.0239 -> 64.154152 | H73: =(3.9165*M73-0.5231)*30 -> -1.293843 | I73: =(11.007*N73-0.65)*20 -> 24.842066 | J73: =H73+I73 -> 23.548223 | K73: =(0.3548*O73 + 0.0099)*30 -> 5.74128 | L73: 0.10600947 | M73: 0.12255123 | N73: =AVERAGE(P73:R73) -> 0.1719 | O73: 0.51148816 | P73: 0.1719
... A81: P2-NO2 | B81: =B51+48 -> 144 | C81: =B81-48 -> 96 | D81: Paracoccus | E81: IR | F81: NO2 | G81: =30*(L81-0.0549)/0.0239 -> 30.71681 | H81: =(3.9165*M81-0.5231)*30 -> 34.446601 | I81: =(11.007*N81-0.65)*20 -> 23.080946 | J81: =H81+I81 -> 57.527547 | K81: =(0.3548*O81 + 0.0099)*30 -> 2.2957607 | L81: 0.079371058 | M81: 0.42673817 | N81: =AVERAGE(P81:R81) -> 0.1639 | O81: 0.18778285 | P81: 0.1639
...

Sheet PASH.r2
A1: Samples | B1: Time.raw | C1: Time | D1: Strain | E1: Light | F1: Substrate | G1: HCO3 | H1: NO2 | I1: NH4 | J1: Abs697 | K1: TIN | L1: CH3COO | M1: S2O3 | N1: OD600 | O1: Growth | P1: HCO3_raw | Q1: NO2_Raw | R1: NH4_Raw | S1: Acetate_Raw | T1: S_Raw | U1: Abs697_raw | V1: NH4_1 | W1: NH4_2 | X1: NH4_3 | Y1: OD600.raw1 | Z1: OD600.raw2 | AA1: OD600.raw3
A2: P1-D-4.6' | B2: =PASH.r1!B152+2 -> 268 | C2: 0 | D2: Paracoccus | E2: Dark | F2: NH4-HCO3 | G2: =30*(P2-0.0549)/0.0239 -> 257.91261 | H2: =(3.9165*Q2-0.5231)*30 -> -3.9435 | I2: =(11.007*R2-0.65)*20 -> 64.92956 | K2: =H2+I2 -> 60.98606 | L2: =(S2*0.0433 - 0.0001)*30 -> 0.00030472787 | M2: =(0.3548*T2 + 0.0099)*30 -> 9.9088153 | P2: 0.26037038 | Q2: 0.1 | R2: =AVERAGE(V2:X2) -> 0.354 | S2: 0.0025440553 | T2: 0.90302662 | V2: 0.354
A3: P2 | B3: =PASH.r1!B153+2 -> 268 | C3: 0 | D3: Paracoccus | E3: Dark | F3: NH4-HCO3 | G3: =30*(P3-0.0549)/0.0239 -> 255.74329 | H3: =(3.9165*Q3-0.5231)*30 -> -3.9435 | I3: =(11.007*R3-0.65)*20 -> 42.299168 | K3: =H3+I3 -> 38.355668 | L3: =(S3*0.0433 - 0.0001)*30 -> -0.0001106764 | M3: =(0.3548*T3 + 0.0099)*30 -> 10.446678 | P3: 0.25864216 | Q3: 0.1 | R3: =AVERAGE(V3:X3) -> 0.2512 | S3: 0.0022242676 | T3: 0.95355863 | V3: 0.2512
A4: P3 | B4: =PASH.r1!B154+2 -> 268 | C4: 0 | D4: Paracoccus | E4: Dark | F4: NH4-HCO3 | G4: =30*(P4-0.0549)/0.0239 -> 235.14289 | H4: =(3.9165*Q4-0.5231)*30 -> -3.9435 | I4: =(11.007*R4-0.65)*20 -> 43.267784 | K4: =H4+I4 -> 39.324284 | L4: =(S4*0.0433 - 0.0001)*30 -> 0.0002015869 | M4: =(0.3548*T4 + 0.0099)*30 -> 10.186637 | P4: 0.24223051 | Q4: 0.1 | R4: =AVERAGE(V4:X4) -> 0.2556 | S4: 0.002464655 | T4: 0.92912789 | V4: 0.2556
A5: A1 | B5: =PASH.r1!B155+2 -> 268 | C5: 0 | D5: Aliidiomarina | E5: Dark | F5: NH4-HCO3 | G5: =30*(P5-0.0549)/0.0239 -> 227.33158 | H5: =(3.9165*Q5-0.5231)*30 -> -5.4688679 | I5: =(11.007*R5-0.65)*20 -> 42.14507 | K5: =H5+I5 -> 36.676202 | L5: =(S5*0.0433 - 0.0001)*30 -> -6.2847806e-05 | M5: =(0.3548*T5 + 0.0099)*30 -> 10.017376 | P5: 0.23600749 | Q5: 0.087017593 | R5: =AVERAGE(V5:X5) -> 0.2505 | S5: 0.0022610871 | T5: 0.91322588 | V5: 0.2505
A6: A2 | B6: =PASH.r1!B156+2 -> 268 | C6: 0 | D6: Aliidiomarina | E6: Dark | F6: NH4-HCO3 | G6: =30*(P6-0.0549)/0.0239 -> 246.04196 | H6: =(3.9165*Q6-0.5231)*30 -> -6.0215652 | I6: =(11.007*R6-0.65)*20 -> 41.616734 | K6: =H6+I6 -> 35.595169 | L6: =(S6*0.0433 - 0.0001)*30 -> -0.00011909059 | M6: =(0.3548*T6 + 0.0099)*30 -> 10.36199 | P6: 0.25091342 | Q6: 0.082313586 | R6: =AVERAGE(V6:X6) -> 0.2481 | S6: 0.0022177902 | T6: 0.94560225 | V6: 0.2481
A7: A3 | B7: =PASH.r1!B157+2 -> 268 | C7: 0 | D7: Aliidiomarina | E7: Dark | F7: NH4-HCO3 | G7: =30*(P7-0.0549)/0.0239 -> 249.05955 | H7: =(3.9165*Q7-0.5231)*30 -> -3.9435 | I7: =(11.007*R7-0.65)*20 -> 43.267784 | K7: =H7+I7 -> 39.324284 | L7: =(S7*0.0433 - 0.0001)*30 -> 1.6745752e-05 | M7: =(0.3548*T7 + 0.0099)*30 -> 10.567046 | P7: 0.25331744 | Q7: 0.1 | R7: =AVERAGE(V7:X7) -> 0.2556 | S7: 0.0023223601 | T7: 0.96486717 | V7: 0.2556
A8: S1 | B8: =PASH.r1!B158+2 -> 268 | C8: 0 | D8: SynCom | E8: Dark | F8: NH4-HCO3 | G8: =30*(P8-0.0549)/0.0239 -> 270.71183 | H8: =(3.9165*Q8-0.5231)*30 -> -3.9435 | I8: =(11.007*R8-0.65)*20 -> 38.644844 | K8: =H8+I8 -> 34.701344 | L8: =(S8*0.0433 - 0.0001)*30 -> -0.00031304318 | M8: =(0.3548*T8 + 0.0099)*30 -> 14.722158 | P8: 0.27056709 | Q8: 0.1 | R8: =AVERAGE(V8:X8) -> 0.2346 | S8: 0.002068481 | T8: 1.3552384 | V8: 0.2346
A9: S2 | B9: =PASH.r1!B159+2 -> 268 | C9: 0 | D9: SynCom | E9: Dark | F9: NH4-HCO3 | G9: =30*(P9-0.0549)/0.0239 -> 214.32828 | H9: =(3.9165*Q9-0.5231)*30 -> -3.9435 | I9: =(11.007*R9-0.65)*20 -> 40.097768 | K9: =H9+I9 -> 36.154268 | L9: =(S9*0.0433 - 0.0001)*30 -> 0.00051106071 | M9: =(0.3548*T9 + 0.0099)*30 -> 10.424448 | P9: 0.2256482 | Q9: 0.1 | R9: =AVERAGE(V9:X9) -> 0.2412 | S9: 0.0027028951 | T9: 0.95147017 | V9: 0.2412
A10: S3 | B10: =PASH.r1!B160+2 -> 268 | C10: 0 | D10: SynCom | E10: Dark | F10: NH4-HCO3 | G10: =30*(P10-0.0549)/0.0239 -> 253.14722 | H10: =(3.9165*Q10-0.5231)*30 -> -3.9435 | I10: =(11.007*R10-0.65)*20 -> 42.717434 | K10: =H10+I10 -> 38.773934 | L10: =(S10*0.0433 - 0.0001)*30 -> 0.0073022488 | M10: =(0.3548*T10 + 0.0099)*30 -> 9.95687 | P10: 0.25657395 | Q10: 0.1 | R10: =AVERAGE(V10:X10) -> 0.2531 | S10: 0.0079309075 | T10: 0.90754133 | V10: 0.2531
A11: P1-I | B11: =PASH.r1!B161+2 -> 268 | C11: 0 | D11: Paracoccus | E11: IR | F11: NH4-HCO3 | G11: =30*(P11-0.0549)/0.0239 -> 234.05189 | H11: =(3.9165*Q11-0.5231)*30 -> -3.9435 | I11: =(11.007*R11-0.65)*20 -> 42.827504 | K11: =H11+I11 -> 38.884004 | L11: =(S11*0.0433 - 0.0001)*30 -> 0.025555324 | M11: =(0.3548*T11 + 0.0099)*30 -> 9.4656082 | P11: 0.24136134 | Q11: 0.1 | R11: =AVERAGE(V11:X11) -> 0.2536 | S11: 0.021982544 | T11: 0.86138747 | V11: 0.2536
A12: P2 | B12: =PASH.r1!B162+2 -> 268 | C12: 0 | D12: Paracoccus | E12: IR | F12: NH4-HCO3 | G12: =30*(P12-0.0549)/0.0239 -> 243.87826 | H12: =(3.9165*Q12-0.5231)*30 -> -3.9435 | I12: =(11.007*R12-0.65)*20 -> 44.280428 | K12: =H12+I12 -> 40.336928 | L12: =(S12*0.0433 - 0.0001)*30 -> 0.007972519 | M12: =(0.3548*T12 + 0.0099)*30 -> 12.169156 | P12: 0.24918968 | Q12: 0.1 | R12: =AVERAGE(V12:X12) -> 0.2602 | S12: 0.0084468968 | T12: 1.1153848 | V12: 0.2602
A13: P3 | B13: =PASH.r1!B163+2 -> 268 | C13: 0 | D13: Paracoccus | E13: IR | F13: NH4-HCO3 | G13: =30*(P13-0.0549)/0.0239 -> 253.78978 | H13: =(3.9165*Q13-0.5231)*30 -> -3.9435 | I13: =(11.007*R13-0.65)*20 -> 41.396594 | K13: =H13+I13 -> 37.453094 | L13: =(S13*0.0433 - 0.0001)*30 -> 0.004222895 | M13: =(0.3548*T13 + 0.0099)*30 -> 10.393181 | P13: 0.25708586 | Q13: 0.1 | R13: =AVERAGE(V13:X13) -> 0.2471 | S13: 0.0055603503 | T13: 0.9485326 | V13: 0.2471
... A31: H3-I | B31: =PASH.r1!B181+2 -> 268 | C31: 0 | D31: Halomonas | E31: IR | F31: NO2 | G31: =30*(P31-0.0549)/0.0239 -> 307.27614 | H31: =(3.9165*Q31-0.5231)*30 -> 37.209016 | I31: =(11.007*R31-0.65)*20 -> 46.019534 | K31: =H31+I31 -> 83.22855 | L31: =(S31*0.0433 - 0.0001)*30 -> -0.00025337513 | M31: =(0.3548*T31 + 0.0099)*30 -> 18.376095 | P31: 0.29969666 | Q31: 0.45024908 | R31: =AVERAGE(V31:X31) -> 0.2681 | S31: 0.0021144148 | T31: 1.6985245 | V31: 0.2681
A32: P1-D-4.7 | B32: =B2+24 -> 292 | C32: =B32-268 -> 24 | D32: Paracoccus | E32: Dark | F32: NH4-HCO3 | G32: =30*(P32-0.0549)/0.0239 -> 272.01414 | H32: =(3.9165*Q32-0.5231)*30 -> 3.2836693 | L32: =(S32*0.0433 - 0.0001)*30 -> 0.00013209272 | M32: =(0.3548*T32 + 0.0099)*30 -> 7.2672481 | P32: 0.2716046 | Q32: 0.16151044 | R32: =AVERAGE(V32:X32) -> 0.169 | S32: 0.0024111568 | T32: 0.65485232 | W32: 0.169
A33: P2 | B33: =B3+24 -> 292 | C33: =B33-268 -> 24 | D33: Paracoccus | E33: Dark | F33: NH4-HCO3 | G33: =30*(P33-0.0549)/0.0239 -> 227.8055 | H33: =(3.9165*Q33-0.5231)*30 -> 19.135788 | L33: =(S33*0.0433 - 0.0001)*30 -> -0.00083789742 | M33: =(0.3548*T33 + 0.0099)*30 -> 11.255597 | P33: 0.23638505 | Q33: 0.29642783 | R33: =AVERAGE(V33:X33) -> 0.1347 | S33: 0.0016644362 | T33: 1.0295562 | W33: 0.1347
A34: P3 | B34: =B4+24 -> 292 | C34: =B34-268 -> 24 | D34: Paracoccus | E34: Dark | F34: NH4-HCO3 | G34: =30*(P34-0.0549)/0.0239 -> 215.41169 | H34: =(3.9165*Q34-0.5231)*30 -> 22.239944 | L34: =(S34*0.0433 - 0.0001)*30 -> -0.0010657008 | M34: =(0.3548*T34 + 0.0099)*30 -> 10.51058 | P34: 0.22651131 | Q34: 0.3228473 | R34: =AVERAGE(V34:X34) -> 0.1453 | S34: 0.0014890679 | T34: 0.95956217 | W34: 0.1453
A35: A1 | B35: =B5+24 -> 292 | C35: =B35-268 -> 24 | D35: Aliidiomarina | E35: Dark | F35: NH4-HCO3 | G35: =30*(P35-0.0549)/0.0239 -> 235.1892 | H35: =(3.9165*Q35-0.5231)*30 -> -3.051356 | L35: =(S35*0.0433 - 0.0001)*30 -> 0.00026595921 | M35: =(0.3548*T35 + 0.0099)*30 -> 7.931315 | P35: 0.2422674 | Q35: 0.10759304 | R35: =AVERAGE(V35:X35) -> 0.1374 | S35: 0.0025142103 | T35: 0.71724117 | W35: 0.1374
A36: A2 | B36: =B6+24 -> 292 | C36: =B36-268 -> 24 | D36: Aliidiomarina | E36: Dark | F36: NH4-HCO3 | G36: =30*(P36-0.0549)/0.0239 -> 238.84263 | H36: =(3.9165*Q36-0.5231)*30 -> -3.9435 | L36: =(S36*0.0433 - 0.0001)*30 -> 0.0011786314 | M36: =(0.3548*T36 + 0.0099)*30 -> 9.1005761 | P36: 0.24517796 | Q36: 0.1 | R36: =AVERAGE(V36:X36) -> 0.136 | S36: 0.0032168063 | T36: 0.82709283 | W36: 0.136
A37: A3 | B37: =B7+24 -> 292 | C37: =B37-268 -> 24 | D37: Aliidiomarina | E37: Dark | F37: NH4-HCO3 | G37: =30*(P37-0.0549)/0.0239 -> 248.90427 | H37: =(3.9165*Q37-0.5231)*30 -> -3.9435 | L37: =(S37*0.0433 - 0.0001)*30 -> 0.0016584166 | M37: =(0.3548*T37 + 0.0099)*30 -> 9.6195346 | P37: 0.25319374 | Q37: 0.1 | R37: =AVERAGE(V37:X37) -> 0.1415 | S37: 0.0035861559 | T37: 0.8758488 | W37: 0.1415
A38: S1 | B38: =B8+24 -> 292 | C38: =B38-268 -> 24 | D38: SynCom | E38: Dark | F38: NH4-HCO3 | G38: =30*(P38-0.0549)/0.0239 -> 268.65068 | H38: =(3.9165*Q38-0.5231)*30 -> -3.9435 | L38: =(S38*0.0433 - 0.0001)*30 -> 0.0031622475 | M38: =(0.3548*T38 + 0.0099)*30 -> 14.661905 | P38: 0.26892504 | Q38: 0.1 | R38: =AVERAGE(V38:X38) -> 0.101 | S38: 0.0047438395 | T38: 1.3495777 | W38: 0.101
A39: S2 | B39: =B9+24 -> 292 | C39: =B39-268 -> 24 | D39: SynCom | E39: Dark | F39: NH4-HCO3 | G39: =30*(P39-0.0549)/0.0239 -> 200.35633 | H39: =(3.9165*Q39-0.5231)*30 -> -3.9435 | L39: =(S39*0.0433 - 0.0001)*30 -> 0.0032823273 | M39: =(0.3548*T39 + 0.0099)*30 -> 7.1048447 | P39: 0.21451721 | Q39: 0.1 | R39: =AVERAGE(V39:X39) -> 0.125 | S39: 0.0048362797 | T39: 0.63959458 | W39: 0.125
A40: S3 | B40: =B10+24 -> 292 | C40: =B40-268 -> 24 | D40: SynCom | E40: Dark | F40: NH4-HCO3 | G40: =30*(P40-0.0549)/0.0239 -> 203.31707 | H40: =(3.9165*Q40-0.5231)*30 -> -3.9435 | L40: =(S40*0.0433 - 0.0001)*30 -> 0.0012023097 | M40: =(0.3548*T40 + 0.0099)*30 -> 6.9747185 | P40: 0.21687593 | Q40: 0.1 | R40: =AVERAGE(V40:X40) -> 0.1296 | S40: 0.0032350344 | T40: 0.62736927 | W40: 0.1296
A41: P1-I | B41: =B11+24 -> 292 | C41: =B41-268 -> 24 | D41: Paracoccus | E41: IR | F41: NH4-HCO3 | G41: =30*(P41-0.0549)/0.0239 -> 210.92287 | H41: =(3.9165*Q41-0.5231)*30 -> -5.3127452 | L41: =(S41*0.0433 - 0.0001)*30 -> 0.00038696833 | M41: =(0.3548*T41 + 0.0099)*30 -> 8.0236478 | P41: 0.22293522 | Q41: 0.088346354 | R41: =AVERAGE(V41:X41) -> 0.1263 | S41: 0.0026073659 | T41: 0.7259158 | W41: 0.1263
A42: P2 | B42: =B12+24 -> 292 | C42: =B42-268 -> 24 | D42: Paracoccus | E42: IR | F42: NH4-HCO3 | G42: =30*(P42-0.0549)/0.0239 -> 230.17005 | H42: =(3.9165*Q42-0.5231)*30 -> -5.5676726 | L42: =(S42*0.0433 - 0.0001)*30 -> 0.0035792158 | M42: =(0.3548*T42 + 0.0099)*30 -> 9.6648412 | P42: 0.23826881 | Q42: 0.086176666 | R42: =AVERAGE(V42:X42) -> 0.133 | S42: 0.0050648312 | T42: 0.88010533 | W42: 0.133
A43: P3 | B43: =B13+24 -> 292 | C43: =B43-268 -> 24 | D43: Paracoccus | E43: IR | F43: NH4-HCO3 | G43: =30*(P43-0.0549)/0.0239 -> 220.97402 | H43: =(3.9165*Q43-0.5231)*30 -> -3.9435 | L43: =(S43*0.0433 - 0.0001)*30 -> 0.00017657646 | M43: =(0.3548*T43 + 0.0099)*30 -> 8.5763038 | P43: 0.23094263 | Q43: 0.1 | R43: =AVERAGE(V43:X43) -> 0.1368 | S43: 0.0024454014 | T43: 0.77783763 | W43: 0.1368
... A61: H3-I | B61: =B31+24 -> 292 | C61: =B61-268 -> 24 | D61: Halomonas | E61: IR | F61: NO2 | G61: =30*(P61-0.0549)/0.0239 -> 310.12287 | H61: =(3.9165*Q61-0.5231)*30 -> 38.564773 | L61: =(S61*0.0433 - 0.0001)*30 -> 0.024909618 | M61: =(0.3548*T61 + 0.0099)*30 -> 16.911635 | P61: 0.30196455 | Q61: 0.46178793 | R61: =AVERAGE(V61:X61) -> 0.0949 | S61: 0.021485464 | T61: 1.5609391 | W61: 0.0949
A62: P1-D-4.9 | B62: =B32+48 -> 340 | C62: =B62-268 -> 72 | D62: Paracoccus | E62: Dark | F62: NH4-HCO3 | G62: =30*(P62-0.0549)/0.0239 -> 240.99337 | H62: =(3.9165*Q62-0.5231)*30 -> -3.9435 | I62: =(11.007*R62-0.65)*20 -> 62.243852 | J62: =(1.584*U62 - 0.0774)*40 -> 8.955072 | K62: =H62+I62 -> 58.300352 | L62: =(S62*0.0433 - 0.0001)*30 -> 0.0034822035 | M62: =(0.3548*T62 + 0.0099)*30 -> 1.3860405 | P62: 0.24689139 | Q62: 0.1 | R62: =AVERAGE(V62:X62) -> 0.3418 | S62: 0.004990149 | T62: 0.10231497 | U62: 0.1902 | V62: 0.3418
A63: P2 | B63: =B33+48 -> 340 | C63: =B63-268 -> 72 | D63: Paracoccus | E63: Dark | F63: NH4-HCO3 | G63: =30*(P63-0.0549)/0.0239 -> 149.32878 | H63: =(3.9165*Q63-0.5231)*30 -> -3.9435 | I63: =(11.007*R63-0.65)*20 -> 41.066384 | J63: =(1.584*U63 - 0.0774)*40 -> 10.025856 | K63: =H63+I63 -> 37.122884 | L63: =(S63*0.0433 - 0.0001)*30 -> 0.0053819428 | M63: =(0.3548*T63 + 0.0099)*30 -> 0.88400702 | P63: 0.17386526 | Q63: 0.1 | R63: =AVERAGE(V63:X63) -> 0.2456 | S63: 0.0064526119 | T63: 0.0551491 | U63: 0.2071 | V63: 0.2456
A64: P3 | B64: =B34+48 -> 340 | C64: =B64-268 -> 72 | D64: Paracoccus | E64: Dark | F64: NH4-HCO3 | G64: =30*(P64-0.0549)/0.0239 -> 161.96809 | H64: =(3.9165*Q64-0.5231)*30 -> -3.9435 | I64: =(11.007*R64-0.65)*20 -> 42.167084 | J64: =(1.584*U64 - 0.0774)*40 -> 13.307904 | K64: =H64+I64 -> 38.223584 | L64: =(S64*0.0433 - 0.0001)*30 -> 0.0027052503 | M64: 0 | P64: 0.18393458 | Q64: 0.1 | R64: =AVERAGE(V64:X64) -> 0.2506 | S64: 0.0043920326 | T64: n.a. | U64: 0.2589 | V64: 0.2506
A65: A1 | B65: =B35+48 -> 340 | C65: =B65-268 -> 72 | D65: Aliidiomarina | E65: Dark | F65: NH4-HCO3 | G65: =30*(P65-0.0549)/0.0239 -> 171.92344 | H65: =(3.9165*Q65-0.5231)*30 -> -3.9435 | I65: =(11.007*R65-0.65)*20 -> 40.516034 | J65: =(1.584*U65 - 0.0774)*40 -> 10.798848 | K65: =H65+I65 -> 36.572534 | L65: =(S65*0.0433 - 0.0001)*30 -> 0.00015261371 | M65: =(0.3548*T65 + 0.0099)*30 -> 0.53972702 | P65: 0.19186568 | Q65: 0.1 | R65: =AVERAGE(V65:X65) -> 0.2431 | S65: 0.0024269544 | T65: 0.022804117 | U65: 0.2193 | V65: 0.2431
A66: A2 | B66: =B36+48 -> 340 | C66: =B66-268 -> 72 | D66: Aliidiomarina | E66: Dark | F66: NH4-HCO3 | G66: =30*(P66-0.0549)/0.0239 -> 219.67863 | H66: =(3.9165*Q66-0.5231)*30 -> -0.8400486 | I66: =(11.007*R66-0.65)*20 -> 40.71416 | J66: =(1.584*U66 - 0.0774)*40 -> 10.760832 | K66: =H66+I66 -> 39.874111 | L66: =(S66*0.0433 - 0.0001)*30 -> 0.00013831454 | M66: =(0.3548*T66 + 0.0099)*30 -> 3.4486856 | P66: 0.22991065 | Q66: 0.12641348 | R66: =AVERAGE(V66:X66) -> 0.244 | S66: 0.0024159465 | T66: 0.29609973 | U66: 0.2187 | V66: 0.244
A67: A3 | B67: =B37+48 -> 340 | C67: =B67-268 -> 72 | D67: Aliidiomarina | E67: Dark | F67: NH4-HCO3 | G67: =30*(P67-0.0549)/0.0239 -> 219.36214 | H67: =(3.9165*Q67-0.5231)*30 -> -3.9435 | I67: =(11.007*R67-0.65)*20 -> 40.05374 | J67: =(1.584*U67 - 0.0774)*40 -> 10.253952 | K67: =H67+I67 -> 36.11024 | L67: =(S67*0.0433 - 0.0001)*30 -> 0.01145749 | M67: =(0.3548*T67 + 0.0099)*30 -> 1.9490366 | P67: 0.22965851 | Q67: 0.1 | R67: =AVERAGE(V67:X67) -> 0.241 | S67: 0.011129707 | T67: 0.15520825 | U67: 0.2107 | V67: 0.241
A68: S1 | B68: =B38+48 -> 340 | C68: =B68-268 -> 72 | D68: SynCom | E68: Dark | F68: NH4-HCO3 | G68: =30*(P68-0.0549)/0.0239 -> 320.06979 | H68: =(3.9165*Q68-0.5231)*30 -> -3.9435 | I68: =(11.007*R68-0.65)*20 -> 33.735722 | J68: =(1.584*U68 - 0.0774)*40 -> 3.689856 | K68: =H68+I68 -> 29.792222 | L68: =(S68*0.0433 - 0.0001)*30 -> 0.0085982998 | M68: =(0.3548*T68 + 0.0099)*30 -> 17.146655 | P68: 0.30988893 | Q68: 0.1 | R68: =AVERAGE(V68:X68) -> 0.2123 | S68: 0.0089286373 | T68: 1.5830191 | U68: 0.1071 | V68: 0.2123
A69: S2 | B69: =B39+48 -> 340 | C69: =B69-268 -> 72 | D69: SynCom | E69: Dark | F69: NH4-HCO3 | G69: =30*(P69-0.0549)/0.0239 -> 184.76364 | H69: =(3.9165*Q69-0.5231)*30 -> -3.9435 | I69: =(11.007*R69-0.65)*20 -> 39.591446 | J69: =(1.584*U69 - 0.0774)*40 -> 9.873792 | K69: =H69+I69 -> 35.647946 | L69: =(S69*0.0433 - 0.0001)*30 -> 0.0040342508 | M69: =(0.3548*T69 + 0.0099)*30 -> 3.64151 | P69: 0.20209504 | Q69: 0.1 | R69: =AVERAGE(V69:X69) -> 0.2389 | S69: 0.0054151277 | T69: 0.31421552 | U69: 0.2047 | V69: 0.2389
A70: S3 | B70: =B40+48 -> 340 | C70: =B70-268 -> 72 | D70: SynCom | E70: Dark | F70: NH4-HCO3 | G70: =30*(P70-0.0549)/0.0239 -> 182.72658 | H70: =(3.9165*Q70-0.5231)*30 -> -4.77865 | I70: =(11.007*R70-0.65)*20 -> 40.912286 | J70: =(1.584*U70 - 0.0774)*40 -> 11.217024 | K70: =H70+I70 -> 36.133636 | L70: =(S70*0.0433 - 0.0001)*30 -> 0.0033267329 | M70: =(0.3548*T70 + 0.0099)*30 -> 0.52207909 | P70: 0.20047217 | Q70: 0.092892038 | R70: =AVERAGE(V70:X70) -> 0.2449 | S70: 0.0048704641 | T70: 0.0211461 | U70: 0.2259 | V70: 0.2449
A71: P1-I | B71: =B41+48 -> 340 | C71: =B71-268 -> 72 | D71: Paracoccus | E71: IR | F71: NH4-HCO3 | G71: =30*(P71-0.0549)/0.0239 -> 179.39992 | H71: =(3.9165*Q71-0.5231)*30 -> -5.4335059 | I71: =(11.007*R71-0.65)*20 -> 42.80549 | J71: =(1.584*U71 - 0.0774)*40 -> 11.236032 | K71: =H71+I71 -> 37.371984 | L71: =(S71*0.0433 - 0.0001)*30 -> 0.00074486149 | M71: 0 | P71: 0.19782194 | Q71: 0.087318559 | R71: =AVERAGE(V71:X71) -> 0.2535 | S71: 0.0028828803 | T71: n.a. | U71: 0.2262 | V71: 0.2535
A72: P2 | B72: =B42+48 -> 340 | C72: =B72-268 -> 72 | D72: Paracoccus | E72: IR | F72: NH4-HCO3 | G72: =30*(P72-0.0549)/0.0239 -> 190.71698 | H72: =(3.9165*Q72-0.5231)*30 -> -3.9435 | I72: =(11.007*R72-0.65)*20 -> 41.616734 | J72: =(1.584*U72 - 0.0774)*40 -> 8.239104 | K72: =H72+I72 -> 37.673234 | L72: =(S72*0.0433 - 0.0001)*30 -> 0.00063667989 | M72: =(0.3548*T72 + 0.0099)*30 -> 3.5971481 | P72: 0.20683786 | Q72: 0.1 | R72: =AVERAGE(V72:X72) -> 0.2481 | S72: 0.0027995996 | T72: 0.31004773 | U72: 0.1789 | V72: 0.2481
A73: P3 | B73: =B43+48 -> 340 | C73: =B73-268 -> 72 | D73: Paracoccus | E73: IR | F73: NH4-HCO3 | G73: =30*(P73-0.0549)/0.0239 -> 175.81672 | H73: =(3.9165*Q73-0.5231)*30 -> -4.3357217 | I73: =(11.007*R73-0.65)*20 -> 41.70479 | J73: =(1.584*U73 - 0.0774)*40 -> 12.642624 | K73: =H73+I73 -> 37.369068 | L73: =(S73*0.0433 - 0.0001)*30 -> -0.00039008745 | M73: =(0.3548*T73 + 0.0099)*30 -> 0.5774066 | P73: 0.19496732 | Q73: 0.096661801 | R73: =AVERAGE(V73:X73) -> 0.2485 | S73: 0.0020091706 | T73: 0.0263441 | U73: 0.2484 | V73: 0.2485
A74: A1 | B74: =B44+48 -> 340 | C74: =B74-268 -> 72 | D74: Aliidiomarina | E74: IR | F74: NH4-HCO3 | G74: =30*(P74-0.0549)/0.0239 -> 224.9524 | H74: =(3.9165*Q74-0.5231)*30 -> -3.9435 | I74: =(11.007*R74-0.65)*20 -> 41.220482 | J74: =(1.584*U74 - 0.0774)*40 -> 14.049216 | K74: =H74+I74 -> 37.276982 | L74: =(S74*0.0433 - 0.0001)*30 -> 0.00022443291 | M74: =(0.3548*T74 + 0.0099)*30 -> 2.9244586 | P74: 0.23411208 | Q74: 0.1 | R74: =AVERAGE(V74:X74) -> 0.2463 | S74: 0.0024822424 | T74: 0.2468488 | U74: 0.2706 | V74: 0.2463
...
