Workbook

Sheet r1
A1: Sample | B1: Time | C1: OD600 | D1: Group | E1: Substrate
A2: pd.1_Dark | B2: ='Round1.raw'!B3 -> 0 | C2: ='Round1.raw'!C3 -> 0.1345 | D2: pd_Dark | E2: Dark
A3: pd.1_Dark | B3: ='Round1.raw'!B4 -> 30 | C3: ='Round1.raw'!C4 -> 0.1318 | D3: pd_Dark | E3: Dark
A4: pd.1_Dark | B4: ='Round1.raw'!B5 -> 60 | C4: ='Round1.raw'!C5 -> 0.1319 | D4: pd_Dark | E4: Dark
A5: pd.1_Dark | B5: ='Round1.raw'!B6 -> 90 | C5: ='Round1.raw'!C6 -> 0.1318 | D5: pd_Dark | E5: Dark
A6: pd.1_Dark | B6: ='Round1.raw'!B7 -> 120 | C6: ='Round1.raw'!C7 -> 0.1314 | D6: pd_Dark | E6: Dark
A7: pd.1_Dark | B7: ='Round1.raw'!B8 -> 150 | C7: ='Round1.raw'!C8 -> 0.1314 | D7: pd_Dark | E7: Dark
A8: pd.1_Dark | B8: ='Round1.raw'!B9 -> 180 | C8: ='Round1.raw'!C9 -> 0.1311 | D8: pd_Dark | E8: Dark
A9: pd.1_Dark | B9: ='Round1.raw'!B10 -> 210 | C9: ='Round1.raw'!C10 -> 0.131 | D9: pd_Dark | E9: Dark
A10: pd.1_Dark | B10: ='Round1.raw'!B11 -> 240 | C10: ='Round1.raw'!C11 -> 0.1307 | D10: pd_Dark | E10: Dark
A11: pd.1_Dark | B11: ='Round1.raw'!B12 -> 270 | C11: ='Round1.raw'!C12 -> 0.1307 | D11: pd_Dark | E11: Dark
A12: pd.1_Dark | B12: ='Round1.raw'!B13 -> 300 | C12: ='Round1.raw'!C13 -> 0.1305 | D12: pd_Dark | E12: Dark
A13: pd.1_Dark | B13: ='Round1.raw'!B14 -> 330 | C13: ='Round1.raw'!C14 -> 0.1302 | D13: pd_Dark | E13: Dark
... A50: pd.1_Dark | B50: ='Round1.raw'!B51 -> 1440 | C50: ='Round1.raw'!C51 -> 0.1265 | D50: pd_Dark | E50: Dark
A51: pd.2_Dark | B51: ='Round1.raw'!B3 -> 0 | C51: ='Round1.raw'!D3 -> 0.1426 | D51: pd_Dark | E51: Dark
A52: pd.2_Dark | B52: ='Round1.raw'!B4 -> 30 | C52: ='Round1.raw'!D4 -> 0.1401 | D52: pd_Dark | E52: Dark
A53: pd.2_Dark | B53: ='Round1.raw'!B5 -> 60 | C53: ='Round1.raw'!D5 -> 0.139 | D53: pd_Dark | E53: Dark
A54: pd.2_Dark | B54: ='Round1.raw'!B6 -> 90 | C54: ='Round1.raw'!D6 -> 0.138 | D54: pd_Dark | E54: Dark
A55: pd.2_Dark | B55: ='Round1.raw'!B7 -> 120 | C55: ='Round1.raw'!D7 -> 0.138 | D55: pd_Dark | E55: Dark
A56: pd.2_Dark | B56: ='Round1.raw'!B8 -> 150 | C56: ='Round1.raw'!D8 -> 0.1378 | D56: pd_Dark | E56: Dark
A57: pd.2_Dark | B57: ='Round1.raw'!B9 -> 180 | C57: ='Round1.raw'!D9 -> 0.1382 | D57: pd_Dark | E57: Dark
A58: pd.2_Dark | B58: ='Round1.raw'!B10 -> 210 | C58: ='Round1.raw'!D10 -> 0.138 | D58: pd_Dark | E58: Dark
A59: pd.2_Dark | B59: ='Round1.raw'!B11 -> 240 | C59: ='Round1.raw'!D11 -> 0.1379 | D59: pd_Dark | E59: Dark
A60: pd.2_Dark | B60: ='Round1.raw'!B12 -> 270 | C60: ='Round1.raw'!D12 -> 0.138 | D60: pd_Dark | E60: Dark
A61: pd.2_Dark | B61: ='Round1.raw'!B13 -> 300 | C61: ='Round1.raw'!D13 -> 0.138 | D61: pd_Dark | E61: Dark
A62: pd.2_Dark | B62: ='Round1.raw'!B14 -> 330 | C62: ='Round1.raw'!D14 -> 0.1378 | D62: pd_Dark | E62: Dark
... A99: pd.2_Dark | B99: ='Round1.raw'!B51 -> 1440 | C99: ='Round1.raw'!D51 -> 0.1348 | D99: pd_Dark | E99: Dark
A100: pd.3_Dark | B100: ='Round1.raw'!B3 -> 0 | C100: ='Round1.raw'!E3 -> 0.1404 | D100: pd_Dark | E100: Dark
A101: pd.3_Dark | B101: ='Round1.raw'!B4 -> 30 | C101: ='Round1.raw'!E4 -> 0.1359 | D101: pd_Dark | E101: Dark
A102: pd.3_Dark | B102: ='Round1.raw'!B5 -> 60 | C102: ='Round1.raw'!E5 -> 0.1362 | D102: pd_Dark | E102: Dark
A103: pd.3_Dark | B103: ='Round1.raw'!B6 -> 90 | C103: ='Round1.raw'!E6 -> 0.1359 | D103: pd_Dark | E103: Dark
A104: pd.3_Dark | B104: ='Round1.raw'!B7 -> 120 | C104: ='Round1.raw'!E7 -> 0.1357 | D104: pd_Dark | E104: Dark
A105: pd.3_Dark | B105: ='Round1.raw'!B8 -> 150 | C105: ='Round1.raw'!E8 -> 0.1361 | D105: pd_Dark | E105: Dark
A106: pd.3_Dark | B106: ='Round1.raw'!B9 -> 180 | C106: ='Round1.raw'!E9 -> 0.136 | D106: pd_Dark | E106: Dark
A107: pd.3_Dark | B107: ='Round1.raw'!B10 -> 210 | C107: ='Round1.raw'!E10 -> 0.1361 | D107: pd_Dark | E107: Dark
A108: pd.3_Dark | B108: ='Round1.raw'!B11 -> 240 | C108: ='Round1.raw'!E11 -> 0.1363 | D108: pd_Dark | E108: Dark
A109: pd.3_Dark | B109: ='Round1.raw'!B12 -> 270 | C109: ='Round1.raw'!E12 -> 0.1362 | D109: pd_Dark | E109: Dark
A110: pd.3_Dark | B110: ='Round1.raw'!B13 -> 300 | C110: ='Round1.raw'!E13 -> 0.1365 | D110: pd_Dark | E110: Dark
A111: pd.3_Dark | B111: ='Round1.raw'!B14 -> 330 | C111: ='Round1.raw'!E14 -> 0.1363 | D111: pd_Dark | E111: Dark
... A148: pd.3_Dark | B148: ='Round1.raw'!B51 -> 1440 | C148: ='Round1.raw'!E51 -> 0.139 | D148: pd_Dark | E148: Dark
...

Sheet Round1.raw
A1: Data-Time | B1: Time | C1: Dark | O1: IR
A2: Data-Time | B2: Time 1 | C2: pd.NA1_Dark | D2: pd.NA2_Dark | E2: pd.NA3_Dark | F2: am.NA1_Dark | G2: am.NA2_Dark | H2: am.NA3_Dark | I2: pa.NA1_Dark | J2: pa.NA2_Dark | K2: pa.NA3_Dark | L2: Syn.1_Dark | M2: Syn.2_Dark | N2: Syn.3_Dark | O2: pd.NA1_IR | P2: pd.NA2_IR | Q2: pd.NA3_IR | R2: am.NA1_IR | S2: am.NA2_IR | T2: am.NA3_IR | U2: pa.NA1_IR | V2: pa.NA2_IR | W2: pa.NA3_IR | X2: Syn.1_IR | Y2: Syn.2_IR | Z2: Syn.3_IR | AA2: Tips
A3: 46057.812 | B3: 0 | C3: 0.1345 | D3: 0.1426 | E3: 0.1404 | F3: 0.1415 | G3: 0.1685 | H3: 0.1355 | I3: 0.1469 | J3: 0.1453 | K3: 0.1464 | L3: 0.1593 | M3: 0.1613 | N3: 0.1598 | O3: 0.1327 | P3: 0.1669 | Q3: 0.1622 | R3: 0.1928 | S3: 0.1785 | T3: 0.1833 | U3: 0.1819 | V3: 0.1822 | W3: 0.1862 | X3: 0.1614 | Y3: 0.1606 | Z3: 0.1699
B4: 30 | C4: 0.1318 | D4: 0.1401 | E4: 0.1359 | F4: 0.1387 | G4: 0.1639 | H4: 0.135 | I4: 0.146 | J4: 0.1437 | K4: 0.1469 | L4: 0.1561 | M4: 0.1599 | N4: 0.1575 | O4: 0.1316 | P4: 0.1426 | Q4: 0.1419 | R4: 0.1607 | S4: 0.1469 | T4: 0.1481 | U4: 0.1472 | V4: 0.1422 | W4: 0.1558 | X4: 0.159 | Y4: 0.158 | Z4: 0.1679
B5: =B4+30 -> 60 | C5: 0.1319 | D5: 0.139 | E5: 0.1362 | F5: 0.1412 | G5: 0.1754 | H5: 0.1373 | I5: 0.1424 | J5: 0.1455 | K5: 0.1476 | L5: 0.1555 | M5: 0.1579 | N5: 0.1563 | O5: 0.1296 | P5: 0.1312 | Q5: 0.1295 | R5: 0.1905 | S5: 0.1594 | T5: 0.1683 | U5: 0.1458 | V5: 0.1429 | W5: 0.1572 | X5: 0.1585 | Y5: 0.1582 | Z5: 0.1673
B6: =B5+30 -> 90 | C6: 0.1318 | D6: 0.138 | E6: 0.1359 | F6: 0.156 | G6: 0.1669 | H6: 0.1511 | I6: 0.1425 | J6: 0.1459 | K6: 0.1477 | L6: 0.1534 | M6: 0.1572 | N6: 0.1551 | O6: 0.1293 | P6: 0.1306 | Q6: 0.1295 | R6: 0.1633 | S6: 0.1607 | T6: 0.1534 | U6: 0.1454 | V6: 0.1418 | W6: 0.1568 | X6: 0.1586 | Y6: 0.1576 | Z6: 0.1659
B7: =B6+30 -> 120 | C7: 0.1314 | D7: 0.138 | E7: 0.1357 | F7: 0.1465 | G7: 0.1666 | H7: 0.1387 | I7: 0.1435 | J7: 0.1449 | K7: 0.147 | L7: 0.1536 | M7: 0.1563 | N7: 0.154 | O7: 0.1288 | P7: 0.1301 | Q7: 0.1291 | R7: 0.1642 | S7: 0.1613 | T7: 0.1524 | U7: 0.145 | V7: 0.1406 | W7: 0.1556 | X7: 0.1579 | Y7: 0.1565 | Z7: 0.1639
B8: =B7+30 -> 150 | C8: 0.1314 | D8: 0.1378 | E8: 0.1361 | F8: 0.1425 | G8: 0.1657 | H8: 0.1481 | I8: 0.1455 | J8: 0.1449 | K8: 0.1475 | L8: 0.1536 | M8: 0.1557 | N8: 0.1535 | O8: 0.1286 | P8: 0.1303 | Q8: 0.1293 | R8: 0.1658 | S8: 0.1565 | T8: 0.1567 | U8: 0.1447 | V8: 0.1397 | W8: 0.1547 | X8: 0.1572 | Y8: 0.1564 | Z8: 0.1647
B9: =B8+30 -> 180 | C9: 0.1311 | D9: 0.1382 | E9: 0.136 | F9: 0.1416 | G9: 0.1687 | H9: 0.1434 | I9: 0.144 | J9: 0.1453 | K9: 0.148 | L9: 0.1528 | M9: 0.1547 | N9: 0.1528 | O9: 0.1285 | P9: 0.1307 | Q9: 0.1293 | R9: 0.172 | S9: 0.1519 | T9: 0.152 | U9: 0.1449 | V9: 0.1397 | W9: 0.155 | X9: 0.156 | Y9: 0.1549 | Z9: 0.1637
B10: =B9+30 -> 210 | C10: 0.131 | D10: 0.138 | E10: 0.1361 | F10: 0.1406 | G10: 0.1738 | H10: 0.1379 | I10: 0.1433 | J10: 0.1445 | K10: 0.1473 | L10: 0.1512 | M10: 0.1532 | N10: 0.1515 | O10: 0.1285 | P10: 0.1307 | Q10: 0.1296 | R10: 0.1651 | S10: 0.16 | T10: 0.151 | U10: 0.1446 | V10: 0.1393 | W10: 0.1557 | X10: 0.1553 | Y10: 0.1539 | Z10: 0.1617
B11: =B10+30 -> 240 | C11: 0.1307 | D11: 0.1379 | E11: 0.1363 | F11: 0.1395 | G11: 0.1671 | H11: 0.1389 | I11: 0.1428 | J11: 0.1431 | K11: 0.1469 | L11: 0.1512 | M11: 0.1527 | N11: 0.151 | O11: 0.1283 | P11: 0.1307 | Q11: 0.1295 | R11: 0.1694 | S11: 0.16 | T11: 0.1509 | U11: 0.1443 | V11: 0.1393 | W11: 0.1558 | X11: 0.1551 | Y11: 0.1535 | Z11: 0.1615
B12: =B11+30 -> 270 | C12: 0.1307 | D12: 0.138 | E12: 0.1362 | F12: 0.1391 | G12: 0.1657 | H12: 0.1413 | I12: 0.1423 | J12: 0.143 | K12: 0.146 | L12: 0.1511 | M12: 0.152 | N12: 0.1502 | O12: 0.1281 | P12: 0.1306 | Q12: 0.1296 | R12: 0.1659 | S12: 0.1509 | T12: 0.1528 | U12: 0.144 | V12: 0.139 | W12: 0.1554 | X12: 0.1544 | Y12: 0.1531 | Z12: 0.161
B13: =B12+30 -> 300 | C13: 0.1305 | D13: 0.138 | E13: 0.1365 | F13: 0.1404 | G13: 0.1634 | H13: 0.1395 | I13: 0.1429 | J13: 0.1423 | K13: 0.1466 | L13: 0.1505 | M13: 0.1521 | N13: 0.1499 | O13: 0.1278 | P13: 0.1306 | Q13: 0.1297 | R13: 0.1613 | S13: 0.1496 | T13: 0.1512 | U13: 0.144 | V13: 0.1393 | W13: 0.156 | X13: 0.1538 | Y13: 0.1536 | Z13: 0.1601
B14: =B13+30 -> 330 | C14: 0.1302 | D14: 0.1378 | E14: 0.1363 | F14: 0.1398 | G14: 0.1632 | H14: 0.1408 | I14: 0.1426 | J14: 0.1427 | K14: 0.1463 | L14: 0.1493 | M14: 0.1517 | N14: 0.1492 | O14: 0.1275 | P14: 0.1305 | Q14: 0.1296 | R14: 0.1595 | S14: 0.1495 | T14: 0.1486 | U14: 0.1436 | V14: 0.1387 | W14: 0.1563 | X14: 0.1533 | Y14: 0.1531 | Z14: 0.1597
B15: =B14+30 -> 360 | C15: 0.1302 | D15: 0.1389 | E15: 0.1362 | F15: 0.1404 | G15: 0.1619 | H15: 0.1353 | I15: 0.1413 | J15: 0.1422 | K15: 0.1472 | L15: 0.1494 | M15: 0.1513 | N15: 0.1485 | O15: 0.1273 | P15: 0.1303 | Q15: 0.1293 | R15: 0.1578 | S15: 0.149 | T15: 0.149 | U15: 0.1437 | V15: 0.1383 | W15: 0.1561 | X15: 0.1528 | Y15: 0.1528 | Z15: 0.1584
B16: =B15+30 -> 390 | C16: 0.13 | D16: 0.138 | E16: 0.1354 | F16: 0.1412 | G16: 0.1623 | H16: 0.1367 | I16: 0.1404 | J16: 0.1422 | K16: 0.1468 | L16: 0.1487 | M16: 0.1507 | N16: 0.1484 | O16: 0.1271 | P16: 0.1306 | Q16: 0.1293 | R16: 0.1599 | S16: 0.1486 | T16: 0.1488 | U16: 0.1435 | V16: 0.139 | W16: 0.1569 | X16: 0.1521 | Y16: 0.1521 | Z16: 0.1584
... B49: =B48+30 -> 1380 | C49: 0.1253 | D49: 0.1336 | E49: 0.1374 | F49: 0.139 | G49: 0.1549 | H49: 0.1329 | I49: 0.1473 | J49: 0.1473 | K49: 0.1485 | L49: 0.1526 | M49: 0.1552 | N49: 0.1591 | O49: 0.1227 | P49: 0.1283 | Q49: 0.1269 | R49: 0.1638 | S49: 0.1507 | T49: 0.1466 | U49: 0.1474 | V49: 0.1425 | W49: 0.1566 | X49: 0.151 | Y49: 0.1576 | Z49: 0.1654
A50: 46058.792 | B50: =B49+30 -> 1410 | C50: 0.1254 | D50: 0.1339 | E50: 0.1377 | F50: 0.1418 | G50: 0.1548 | H50: 0.1331 | I50: 0.147 | J50: 0.1469 | K50: 0.1468 | L50: 0.1515 | M50: 0.1546 | N50: 0.1589 | O50: 0.1226 | P50: 0.1283 | Q50: 0.1333 | R50: 0.1643 | S50: 0.151 | T50: 0.1469 | U50: 0.1471 | V50: 0.1422 | W50: 0.1562 | X50: 0.1504 | Y50: 0.157 | Z50: 0.1649
A51: 46058.81 | B51: =B50+30 -> 1440 | C51: 0.1265 | D51: 0.1348 | E51: 0.139 | F51: 0.1361 | G51: 0.1527 | H51: 0.1322 | I51: 0.1465 | J51: 0.1462 | K51: 0.1464 | L51: 0.1518 | M51: 0.155 | N51: 0.158 | O51: 0.1229 | P51: 0.1443 | Q51: 0.1294 | R51: 0.1641 | S51: 0.1505 | T51: 0.1463 | U51: 0.1475 | V51: 0.1423 | W51: 0.157 | X51: 0.1504 | Y51: 0.1569 | Z51: 0.1645
B54: △ | C54: =C51-C3 -> -0.008 | D54: =D51-D3 -> -0.0078 | E54: =E51-E3 -> -0.0014 | F54: =F51-F3 -> -0.0054 | G54: =G51-G3 -> -0.0158 | H54: =H51-H3 -> -0.0033 | I54: =I51-I3 -> -0.0004 | J54: =J51-J3 -> 0.0009 | ... Z54: =Z51-Z3 -> -0.0054

Sheet r2
A1: Sample | B1: Time | C1: OD600 | D1: Group | E1: Substrate
A2: pd.1_Dark | B2: ='Round2.raw'!B3 -> 0 | C2: ='Round2.raw'!C3 -> 0.1338 | D2: pd_Dark | E2: Dark
A3: pd.1_Dark | B3: ='Round2.raw'!B4 -> 2 | C3: ='Round2.raw'!C4 -> 0.1349 | D3: pd_Dark | E3: Dark
A4: pd.1_Dark | B4: ='Round2.raw'!B5 -> 32 | C4: ='Round2.raw'!C5 -> 0.1469 | D4: pd_Dark | E4: Dark
A5: pd.1_Dark | B5: ='Round2.raw'!B6 -> 62 | C5: ='Round2.raw'!C6 -> 0.1486 | D5: pd_Dark | E5: Dark
A6: pd.1_Dark | B6: ='Round2.raw'!B7 -> 68 | C6: ='Round2.raw'!C7 -> 0.1473 | D6: pd_Dark | E6: Dark
A7: pd.1_Dark | B7: ='Round2.raw'!B8 -> 98 | C7: ='Round2.raw'!C8 -> 0.1332 | D7: pd_Dark | E7: Dark
A8: pd.1_Dark | B8: ='Round2.raw'!B9 -> 128 | C8: ='Round2.raw'!C9 -> 0.1321 | D8: pd_Dark | E8: Dark
A9: pd.1_Dark | B9: ='Round2.raw'!B10 -> 158 | C9: ='Round2.raw'!C10 -> 0.1323 | D9: pd_Dark | E9: Dark
A10: pd.1_Dark | B10: ='Round2.raw'!B11 -> 188 | C10: ='Round2.raw'!C11 -> 0.1321 | D10: pd_Dark | E10: Dark
A11: pd.1_Dark | B11: ='Round2.raw'!B12 -> 218 | C11: ='Round2.raw'!C12 -> 0.1311 | D11: pd_Dark | E11: Dark
A12: pd.1_Dark | B12: ='Round2.raw'!B13 -> 248 | C12: ='Round2.raw'!C13 -> 0.1312 | D12: pd_Dark | E12: Dark
A13: pd.1_Dark | B13: ='Round2.raw'!B14 -> 278 | C13: ='Round2.raw'!C14 -> 0.1304 | D13: pd_Dark | E13: Dark
... A50: pd.1_Dark | B50: ='Round2.raw'!B51 -> 1499 | C50: ='Round2.raw'!C51 -> 0.128 | D50: pd_Dark | E50: Dark
A51: pd.2_Dark | B51: ='Round2.raw'!B3 -> 0 | C51: ='Round2.raw'!D3 -> 0.1288 | D51: pd_Dark | E51: Dark
A52: pd.2_Dark | B52: ='Round2.raw'!B4 -> 2 | C52: ='Round2.raw'!D4 -> 0.1294 | D52: pd_Dark | E52: Dark
A53: pd.2_Dark | B53: ='Round2.raw'!B5 -> 32 | C53: ='Round2.raw'!D5 -> 0.127 | D53: pd_Dark | E53: Dark
A54: pd.2_Dark | B54: ='Round2.raw'!B6 -> 62 | C54: ='Round2.raw'!D6 -> 0.1321 | D54: pd_Dark | E54: Dark
A55: pd.2_Dark | B55: ='Round2.raw'!B7 -> 68 | C55: ='Round2.raw'!D7 -> 0.1535 | D55: pd_Dark | E55: Dark
A56: pd.2_Dark | B56: ='Round2.raw'!B8 -> 98 | C56: ='Round2.raw'!D8 -> 0.1342 | D56: pd_Dark | E56: Dark
A57: pd.2_Dark | B57: ='Round2.raw'!B9 -> 128 | C57: ='Round2.raw'!D9 -> 0.1343 | D57: pd_Dark | E57: Dark
A58: pd.2_Dark | B58: ='Round2.raw'!B10 -> 158 | C58: ='Round2.raw'!D10 -> 0.1371 | D58: pd_Dark | E58: Dark
A59: pd.2_Dark | B59: ='Round2.raw'!B11 -> 188 | C59: ='Round2.raw'!D11 -> 0.1384 | D59: pd_Dark | E59: Dark
A60: pd.2_Dark | B60: ='Round2.raw'!B12 -> 218 | C60: ='Round2.raw'!D12 -> 0.1333 | D60: pd_Dark | E60: Dark
A61: pd.2_Dark | B61: ='Round2.raw'!B13 -> 248 | C61: ='Round2.raw'!D13 -> 0.1336 | D61: pd_Dark | E61: Dark
A62: pd.2_Dark | B62: ='Round2.raw'!B14 -> 278 | C62: ='Round2.raw'!D14 -> 0.1336 | D62: pd_Dark | E62: Dark
... A99: pd.2_Dark | B99: ='Round2.raw'!B51 -> 1499 | C99: ='Round2.raw'!D51 -> 0.1309 | D99: pd_Dark | E99: Dark
A100: pd.3_Dark | B100: ='Round2.raw'!B3 -> 0 | C100: ='Round2.raw'!E3 -> 0.123 | D100: pd_Dark | E100: Dark
A101: pd.3_Dark | B101: ='Round2.raw'!B4 -> 2 | C101: ='Round2.raw'!E4 -> 0.1231 | D101: pd_Dark | E101: Dark
A102: pd.3_Dark | B102: ='Round2.raw'!B5 -> 32 | C102: ='Round2.raw'!E5 -> 0.1264 | D102: pd_Dark | E102: Dark
A103: pd.3_Dark | B103: ='Round2.raw'!B6 -> 62 | C103: ='Round2.raw'!E6 -> 0.1291 | D103: pd_Dark | E103: Dark
A104: pd.3_Dark | B104: ='Round2.raw'!B7 -> 68 | C104: ='Round2.raw'!E7 -> 0.1503 | D104: pd_Dark | E104: Dark
A105: pd.3_Dark | B105: ='Round2.raw'!B8 -> 98 | C105: ='Round2.raw'!E8 -> 0.1621 | D105: pd_Dark | E105: Dark
A106: pd.3_Dark | B106: ='Round2.raw'!B9 -> 128 | C106: ='Round2.raw'!E9 -> 0.1836 | D106: pd_Dark | E106: Dark
A107: pd.3_Dark | B107: ='Round2.raw'!B10 -> 158 | C107: ='Round2.raw'!E10 -> 0.2044 | D107: pd_Dark | E107: Dark
A108: pd.3_Dark | B108: ='Round2.raw'!B11 -> 188 | C108: ='Round2.raw'!E11 -> 0.208 | D108: pd_Dark | E108: Dark
A109: pd.3_Dark | B109: ='Round2.raw'!B12 -> 218 | C109: ='Round2.raw'!E12 -> 0.2229 | D109: pd_Dark | E109: Dark
A110: pd.3_Dark | B110: ='Round2.raw'!B13 -> 248 | C110: ='Round2.raw'!E13 -> 0.227 | D110: pd_Dark | E110: Dark
A111: pd.3_Dark | B111: ='Round2.raw'!B14 -> 278 | C111: ='Round2.raw'!E14 -> 0.2172 | D111: pd_Dark | E111: Dark
... A148: pd.3_Dark | B148: ='Round2.raw'!B51 -> 1499 | C148: ='Round2.raw'!E51 -> 0.1402 | D148: pd_Dark | E148: Dark
...

Sheet Round2.raw
A1: Data-Time | B1: Time | C1: Dark | O1: IR
A2: Data-Time | B2: Time 1 | C2: pd.NA1_Dark | D2: pd.NA2_Dark | E2: pd.NA3_Dark | F2: am.NA1_Dark | G2: am.NA2_Dark | H2: am.NA3_Dark | I2: pa.NA1_Dark | J2: pa.NA2_Dark | K2: pa.NA3_Dark | L2: Syn.1_Dark | M2: Syn.2_Dark | N2: Syn.3_Dark | O2: pd.NA1_IR | P2: pd.NA2_IR | Q2: pd.NA3_IR | R2: am.NA1_IR | S2: am.NA2_IR | T2: am.NA3_IR | U2: pa.NA1_IR | V2: pa.NA2_IR | W2: pa.NA3_IR | X2: Syn.1_IR | Y2: Syn.2_IR | Z2: Syn.3_IR | AA2: Tips
A3: 46058.826 | B3: 0 | C3: 0.1338 | D3: 0.1288 | E3: 0.123 | F3: 0.1333 | G3: 0.1266 | H3: 0.1309 | I3: 0.1336 | J3: 0.1324 | K3: 0.127 | L3: 0.1356 | M3: 0.1411 | N3: 0.1407 | O3: 0.1525 | P3: 0.1272 | Q3: 0.1202 | R3: 0.129 | S3: 0.1254 | T3: 0.1263 | U3: 0.1277 | V3: 0.1276 | W3: 0.1302 | X3: 0.1395 | Y3: 0.1369 | Z3: 0.1391
A4: 46058.827 | B4: 2 | C4: 0.1349 | D4: 0.1294 | E4: 0.1231 | F4: 0.1367 | G4: 0.1279 | H4: 0.1312 | I4: 0.1298 | J4: 0.1282 | K4: 0.123 | L4: 0.1345 | M4: 0.1427 | N4: 0.139 | O4: 0.138 | P4: 0.1251 | Q4: 0.1182 | R4: 0.1318 | S4: 0.1258 | T4: 0.1262 | U4: 0.1312 | V4: 0.1303 | W4: 0.1325 | X4: 0.1381 | Y4: 0.1395 | Z4: 0.1399
B5: =B4+30 -> 32 | C5: 0.1469 | D5: 0.127 | E5: 0.1264 | F5: 0.1351 | G5: 0.1276 | H5: 0.1309 | I5: 0.1296 | J5: 0.1261 | K5: 0.1218 | L5: 0.1358 | M5: 0.1433 | N5: 0.1388 | O5: 0.1374 | P5: 0.1225 | Q5: 0.1169 | R5: 0.1309 | S5: 0.1263 | T5: 0.1246 | U5: 0.1305 | V5: 0.1265 | W5: 0.1309 | X5: 0.1383 | Y5: 0.1407 | Z5: 0.1439
A6: 46058.869 | B6: =B5+30 -> 62 | C6: 0.1486 | D6: 0.1321 | E6: 0.1291 | F6: 0.1413 | G6: 0.1287 | H6: 0.131 | I6: 0.1317 | J6: 0.1256 | K6: 0.1208 | L6: 0.1361 | M6: 0.1438 | N6: 0.1412 | O6: 0.1724 | P6: 0.1335 | Q6: 0.1159 | R6: 0.134 | S6: 0.1276 | T6: 0.1239 | U6: 0.1306 | V6: 0.1272 | W6: 0.1317 | X6: 0.1389 | Y6: 0.1419 | Z6: 0.1476
A7: 46058.873 | B7: 68 | C7: 0.1473 | D7: 0.1535 | E7: 0.1503 | F7: 0.1546 | G7: 0.1451 | H7: 0.1537 | I7: 0.1541 | J7: 0.1482 | K7: 0.136 | L7: 0.1449 | M7: 0.1429 | N7: 0.1412 | O7: 0.1447 | P7: 0.1347 | Q7: 0.126 | R7: 0.1517 | S7: 0.1454 | T7: 0.1413 | U7: 0.1493 | V7: 0.1428 | W7: 0.1505 | X7: 0.1458 | Y7: 0.1411 | Z7: 0.1634
B8: =B7+30 -> 98 | C8: 0.1332 | D8: 0.1342 | E8: 0.1621 | F8: 0.1415 | G8: 0.1312 | H8: 0.1349 | I8: 0.134 | J8: 0.1306 | K8: 0.1221 | L8: 0.1352 | M8: 0.1435 | N8: 0.1425 | O8: 0.1359 | P8: 0.1313 | Q8: 0.1169 | R8: 0.1371 | S8: 0.1289 | T8: 0.1234 | U8: 0.132 | V8: 0.1291 | W8: 0.1319 | X8: 0.1397 | Y8: 0.1422 | Z8: 0.1867
B9: =B8+30 -> 128 | C9: 0.1321 | D9: 0.1343 | E9: 0.1836 | F9: 0.1332 | G9: 0.1373 | H9: 0.1371 | I9: 0.1349 | J9: 0.1323 | K9: 0.1223 | L9: 0.1354 | M9: 0.1439 | N9: 0.1429 | O9: 0.1357 | P9: 0.1266 | Q9: 0.1168 | R9: 0.1503 | S9: 0.1535 | T9: 0.1244 | U9: 0.1331 | V9: 0.1296 | W9: 0.1326 | X9: 0.1401 | Y9: 0.1429 | Z9: 0.1572
B10: =B9+30 -> 158 | C10: 0.1323 | D10: 0.1371 | E10: 0.2044 | F10: 0.134 | G10: 0.1331 | H10: 0.1378 | I10: 0.1357 | J10: 0.1319 | K10: 0.1229 | L10: 0.1383 | M10: 0.1443 | N10: 0.1437 | O10: 0.135 | P10: 0.1232 | Q10: 0.1171 | R10: 0.1361 | S10: 0.1313 | T10: 0.125 | U10: 0.1348 | V10: 0.1297 | W10: 0.1326 | X10: 0.14 | Y10: 0.1443 | Z10: 0.1811
B11: =B10+30 -> 188 | C11: 0.1321 | D11: 0.1384 | E11: 0.208 | F11: 0.1343 | G11: 0.134 | H11: 0.138 | I11: 0.1366 | J11: 0.1331 | K11: 0.1238 | L11: 0.1371 | M11: 0.1442 | N11: 0.1445 | O11: 0.1346 | P11: 0.1235 | Q11: 0.1177 | R11: 0.1403 | S11: 0.1367 | T11: 0.1263 | U11: 0.1398 | V11: 0.1311 | W11: 0.1337 | X11: 0.1403 | Y11: 0.1447 | Z11: 0.1857
B12: =B11+30 -> 218 | C12: 0.1311 | D12: 0.1333 | E12: 0.2229 | F12: 0.1374 | G12: 0.1371 | H12: 0.1384 | I12: 0.1378 | J12: 0.134 | K12: 0.1242 | L12: 0.1377 | M12: 0.144 | N12: 0.1449 | O12: 0.1344 | P12: 0.1243 | Q12: 0.1185 | R12: 0.1352 | S12: 0.1399 | T12: 0.1267 | U12: 0.1339 | V12: 0.1313 | W12: 0.133 | X12: 0.1406 | Y12: 0.1449 | Z12: 0.1872
B13: =B12+30 -> 248 | C13: 0.1312 | D13: 0.1336 | E13: 0.227 | F13: 0.1378 | G13: 0.1291 | H13: 0.1379 | I13: 0.1375 | J13: 0.1348 | K13: 0.1248 | L13: 0.1399 | M13: 0.1438 | N13: 0.1453 | O13: 0.1335 | P13: 0.1232 | Q13: 0.1186 | R13: 0.1355 | S13: 0.1339 | T13: 0.1273 | U13: 0.1353 | V13: 0.1332 | W13: 0.1336 | X13: 0.14 | Y13: 0.1451 | Z13: 0.1879
B14: =B13+30 -> 278 | C14: 0.1304 | D14: 0.1336 | E14: 0.2172 | F14: 0.1372 | G14: 0.1356 | H14: 0.1411 | I14: 0.1394 | J14: 0.136 | K14: 0.1347 | L14: 0.1378 | M14: 0.1436 | N14: 0.1457 | O14: 0.1334 | P14: 0.1234 | Q14: 0.1194 | R14: 0.1358 | S14: 0.1367 | T14: 0.1277 | U14: 0.1401 | V14: 0.1348 | W14: 0.1337 | X14: 0.1399 | Y14: 0.145 | Z14: 0.1782
B15: =B14+30 -> 308 | C15: 0.1306 | D15: 0.1318 | E15: 0.1949 | F15: 0.1371 | G15: 0.1363 | H15: 0.1404 | I15: 0.1388 | J15: 0.1359 | K15: 0.1274 | L15: 0.137 | M15: 0.1436 | N15: 0.1448 | O15: 0.1332 | P15: 0.1235 | Q15: 0.1194 | R15: 0.1357 | S15: 0.138 | T15: 0.1281 | U15: 0.1393 | V15: 0.1357 | W15: 0.1335 | X15: 0.1398 | Y15: 0.1439 | Z15: 0.1811
B16: =B15+30 -> 338 | C16: 0.1316 | D16: 0.1322 | E16: 0.184 | F16: 0.1351 | G16: 0.1313 | H16: 0.1402 | I16: 0.1398 | J16: 0.1363 | K16: 0.1242 | L16: 0.137 | M16: 0.1433 | N16: 0.1447 | O16: 0.1333 | P16: 0.123 | Q16: 0.1206 | R16: 0.1353 | S16: 0.1366 | T16: 0.1283 | U16: 0.1392 | V16: 0.1365 | W16: 0.1333 | X16: 0.1396 | Y16: 0.1437 | Z16: 0.1624
B17: =B16+30 -> 368 | C17: 0.1328 | D17: 0.132 | E17: 0.2007 | F17: 0.1359 | G17: 0.1317 | H17: 0.1407 | I17: 0.1393 | J17: 0.1369 | K17: 0.1362 | L17: 0.1377 | M17: 0.1431 | N17: 0.1451 | O17: 0.1337 | P17: 0.1229 | Q17: 0.1233 | R17: 0.1347 | S17: 0.1363 | T17: 0.1279 | U17: 0.1385 | V17: 0.1374 | W17: 0.1336 | X17: 0.1391 | Y17: 0.1438 | Z17: 0.1579
B18: =B17+30 -> 398 | C18: 0.1364 | D18: 0.1327 | E18: 0.176 | F18: 0.137 | G18: 0.133 | H18: 0.143 | I18: 0.1418 | J18: 0.1383 | K18: 0.1244 | L18: 0.1375 | M18: 0.1429 | N18: 0.1445 | O18: 0.1362 | P18: 0.1229 | Q18: 0.1306 | R18: 0.1352 | S18: 0.1371 | T18: 0.1285 | U18: 0.1419 | V18: 0.1393 | W18: 0.1344 | X18: 0.1387 | Y18: 0.1434 | Z18: 0.157
B19: =B18+30 -> 428 | C19: 0.1327 | D19: 0.1336 | E19: 0.1867 | F19: 0.1372 | G19: 0.1326 | H19: 0.1433 | I19: 0.144 | J19: 0.1402 | K19: 0.1245 | L19: 0.1374 | M19: 0.1427 | N19: 0.1444 | O19: 0.1352 | P19: 0.123 | Q19: 0.1245 | R19: 0.1351 | S19: 0.137 | T19: 0.1287 | U19: 0.1345 | V19: 0.1406 | W19: 0.1351 | X19: 0.1383 | Y19: 0.1436 | Z19: 0.1562
... B25: =B24+30 -> 608 | C25: 0.131 | D25: 0.1326 | E25: 0.1607 | F25: 0.1347 | G25: 0.1318 | H25: 0.149 | I25: 0.1471 | J25: 0.1502 | K25: 0.126 | L25: 0.1365 | M25: 0.142 | N25: 0.1428 | O25: 0.1345 | P25: 0.1234 | Q25: 0.1277 | R25: 0.1315 | S25: 0.14 | T25: 0.1289 | U25: 0.1374 | V25: 0.15 | W25: 0.1401 | X25: 0.1376 | Y25: 0.1419 | Z25: 0.1532
B26: =B25+58 -> 666 | C26: 0.1307 | D26: 0.1324 | E26: 0.1524 | F26: 0.1343 | G26: 0.1311 | H26: 0.1488 | I26: 0.1471 | J26: 0.1505 | K26: 0.1265 | L26: 0.1364 | M26: 0.1417 | N26: 0.1424 | O26: 0.1342 | P26: 0.1232 | Q26: 0.1269 | R26: 0.1311 | S26: 0.1395 | T26: 0.1287 | U26: 0.1374 | V26: 0.1512 | W26: 0.1407 | X26: 0.1371 | Y26: 0.1416 | Z26: 0.1504
B27: =B26+30 -> 696 | C27: 0.1303 | D27: 0.1325 | E27: 0.1383 | F27: 0.1338 | G27: 0.1313 | H27: 0.1495 | I27: 0.1485 | J27: 0.1521 | K27: 0.1282 | L27: 0.1368 | M27: 0.142 | N27: 0.1427 | O27: 0.1338 | P27: 0.1228 | Q27: 0.127 | R27: 0.1304 | S27: 0.1395 | T27: 0.129 | U27: 0.1382 | V27: 0.1546 | W27: 0.1419 | X27: 0.1373 | Y27: 0.1417 | Z27: 0.1509
B28: =B27+30 -> 726 | C28: 0.1306 | D28: 0.1322 | E28: 0.1368 | F28: 0.1344 | G28: 0.1312 | H28: 0.1531 | I28: 0.1494 | J28: 0.1559 | K28: 0.1287 | L28: 0.1364 | M28: 0.1416 | N28: 0.1424 | O28: 0.1334 | P28: 0.1229 | Q28: 0.1267 | R28: 0.1306 | S28: 0.1403 | T28: 0.1315 | U28: 0.1403 | V28: 0.1577 | W28: 0.1431 | X28: 0.1373 | Y28: 0.1412 | Z28: 0.1511
B29: =B28+30 -> 756 | C29: 0.1307 | D29: 0.1325 | E29: 0.1384 | F29: 0.1341 | G29: 0.1312 | H29: 0.1562 | I29: 0.1504 | J29: 0.1567 | K29: 0.1312 | L29: 0.1366 | M29: 0.1419 | N29: 0.1426 | O29: 0.134 | P29: 0.1229 | Q29: 0.1257 | R29: 0.1304 | S29: 0.1412 | T29: 0.1367 | U29: 0.1404 | V29: 0.1612 | W29: 0.145 | X29: 0.1375 | Y29: 0.1414 | Z29: 0.1505
B30: =B29+30 -> 786 | C30: 0.1304 | D30: 0.1319 | E30: 0.1373 | F30: 0.134 | G30: 0.1311 | H30: 0.1555 | I30: 0.1496 | J30: 0.1562 | K30: 0.13 | L30: 0.1359 | M30: 0.1416 | N30: 0.1424 | O30: 0.1335 | P30: 0.1227 | Q30: 0.1248 | R30: 0.1292 | S30: 0.1406 | T30: 0.1311 | U30: 0.1416 | V30: 0.1618 | W30: 0.1469 | X30: 0.137 | Y30: 0.141 | Z30: 0.1549
B31: =B30+30 -> 816 | C31: 0.1311 | D31: 0.1318 | E31: 0.1392 | F31: 0.1334 | G31: 0.1312 | H31: 0.1556 | I31: 0.1512 | J31: 0.1577 | K31: 0.1318 | L31: 0.136 | M31: 0.1413 | N31: 0.1429 | O31: 0.1337 | P31: 0.1226 | Q31: 0.1249 | R31: 0.1292 | S31: 0.1406 | T31: 0.1316 | U31: 0.1423 | V31: 0.1641 | W31: 0.149 | X31: 0.1371 | Y31: 0.1402 | Z31: 0.1519
B32: =B31+30 -> 846 | C32: 0.1305 | D32: 0.1314 | E32: 0.138 | F32: 0.1332 | G32: 0.1311 | H32: 0.1571 | I32: 0.153 | J32: 0.1585 | K32: 0.1348 | L32: 0.1358 | M32: 0.1415 | N32: 0.1423 | O32: 0.1333 | P32: 0.1223 | Q32: 0.1241 | R32: 0.1288 | S32: 0.1411 | T32: 0.133 | U32: 0.1428 | V32: 0.1646 | W32: 0.1521 | X32: 0.1369 | Y32: 0.1407 | Z32: 0.1557
A33: 46059.415 | B33: =B32+30 -> 876 | C33: 0.1299 | D33: 0.1317 | E33: 0.1364 | F33: 0.1322 | G33: 0.1311 | H33: 0.1586 | I33: 0.1528 | J33: 0.1578 | K33: 0.1341 | L33: 0.1352 | M33: 0.1411 | N33: 0.142 | O33: 0.1332 | P33: 0.1224 | Q33: 0.1238 | R33: 0.1282 | S33: 0.1394 | T33: 0.133 | U33: 0.1425 | V33: 0.1653 | W33: 0.1524 | X33: 0.1369 | Y33: 0.1405 | Z33: 0.1523
A34: 46059.444 | B34: =B33+41 -> 917 | C34: 0.1306 | D34: 0.1315 | E34: 0.1379 | F34: 0.1342 | G34: 0.1356 | H34: 0.163 | I34: 0.1573 | J34: 0.1593 | K34: 0.1396 | L34: 0.1354 | M34: 0.1412 | N34: 0.1423 | O34: 0.1361 | P34: 0.1241 | Q34: 0.1239 | R34: 0.129 | S34: 0.1477 | T34: 0.1417 | U34: 0.1466 | V34: 0.1662 | W34: 0.1553 | X34: 0.1372 | Y34: 0.1409 | Z34: 0.1529
B35: =B34+30 -> 947 | C35: 0.1295 | D35: 0.1313 | E35: 0.1394 | F35: 0.1342 | G35: 0.1348 | H35: 0.161 | I35: 0.1563 | J35: 0.1579 | K35: 0.138 | L35: 0.1352 | M35: 0.1409 | N35: 0.1424 | O35: 0.1342 | P35: 0.1226 | Q35: 0.124 | R35: 0.1284 | S35: 0.1449 | T35: 0.1424 | U35: 0.1459 | V35: 0.1649 | W35: 0.1561 | X35: 0.1373 | Y35: 0.1413 | Z35: 0.1524
B36: =B35+30 -> 977 | C36: 0.13 | D36: 0.131 | E36: 0.1371 | F36: 0.1337 | G36: 0.135 | H36: 0.1617 | I36: 0.1564 | J36: 0.1583 | K36: 0.1386 | L36: 0.1347 | M36: 0.1406 | N36: 0.1421 | O36: 0.1341 | P36: 0.1224 | Q36: 0.1235 | R36: 0.1283 | S36: 0.1448 | T36: 0.143 | U36: 0.1465 | V36: 0.1648 | W36: 0.1565 | X36: 0.1372 | Y36: 0.1407 | Z36: 0.1521
B37: =B36+30 -> 1007 | C37: 0.129 | D37: 0.1305 | E37: 0.1388 | F37: 0.1339 | G37: 0.136 | H37: 0.163 | I37: 0.1573 | J37: 0.1602 | K37: 0.1386 | L37: 0.1345 | M37: 0.1408 | N37: 0.1425 | O37: 0.1344 | P37: 0.1219 | Q37: 0.1234 | R37: 0.1282 | S37: 0.1453 | T37: 0.144 | U37: 0.1473 | V37: 0.1665 | W37: 0.1575 | X37: 0.137 | Y37: 0.1409 | Z37: 0.1553
B38: =B37+30 -> 1037 | C38: 0.1284 | D38: 0.1308 | E38: 0.1377 | F38: 0.134 | G38: 0.1366 | H38: 0.162 | I38: 0.1575 | J38: 0.1608 | K38: 0.1397 | L38: 0.1341 | M38: 0.1406 | N38: 0.1419 | O38: 0.1346 | P38: 0.1223 | Q38: 0.123 | R38: 0.128 | S38: 0.1445 | T38: 0.1457 | U38: 0.1472 | V38: 0.167 | W38: 0.1579 | X38: 0.1369 | Y38: 0.1405 | Z38: 0.1549
B39: =B38+30 -> 1067 | C39: 0.1286 | D39: 0.1303 | E39: 0.1364 | F39: 0.1343 | G39: 0.1377 | H39: 0.1625 | I39: 0.1581 | J39: 0.16 | K39: 0.1396 | L39: 0.1337 | M39: 0.1402 | N39: 0.1411 | O39: 0.1343 | P39: 0.1217 | Q39: 0.1227 | R39: 0.1276 | S39: 0.1448 | T39: 0.149 | U39: 0.1474 | V39: 0.1693 | W39: 0.1589 | X39: 0.1369 | Y39: 0.1401 | Z39: 0.1546
B40: =B39+30 -> 1097 | C40: 0.1293 | D40: 0.1301 | E40: 0.1364 | F40: 0.1346 | G40: 0.1374 | H40: 0.1627 | I40: 0.158 | J40: 0.1599 | K40: 0.1399 | L40: 0.1333 | M40: 0.1402 | N40: 0.1414 | O40: 0.1344 | P40: 0.1216 | Q40: 0.1223 | R40: 0.1273 | S40: 0.1443 | T40: 0.1496 | U40: 0.1479 | V40: 0.1688 | W40: 0.1598 | X40: 0.1368 | Y40: 0.1402 | Z40: 0.1558
B41: =B40+30 -> 1127 | C41: 0.1286 | D41: 0.1303 | E41: 0.1375 | F41: 0.1358 | G41: 0.1391 | H41: 0.1646 | I41: 0.1601 | J41: 0.1618 | K41: 0.1409 | L41: 0.1332 | M41: 0.1399 | N41: 0.141 | O41: 0.1342 | P41: 0.1216 | Q41: 0.1218 | R41: 0.1274 | S41: 0.1455 | T41: 0.1546 | U41: 0.1482 | V41: 0.1697 | W41: 0.1593 | X41: 0.1367 | Y41: 0.1398 | Z41: 0.16
B42: =B41+30 -> 1157 | C42: 0.1282 | D42: 0.1302 | E42: 0.1373 | F42: 0.1373 | G42: 0.1392 | H42: 0.1671 | I42: 0.1708 | J42: 0.1615 | K42: 0.1402 | L42: 0.1329 | M42: 0.1399 | N42: 0.1404 | O42: 0.1341 | P42: 0.1212 | Q42: 0.1217 | R42: 0.1271 | S42: 0.1454 | T42: 0.1582 | U42: 0.1489 | V42: 0.1692 | W42: 0.1594 | X42: 0.1368 | Y42: 0.1396 | Z42: 0.1573
B43: =B42+30 -> 1187 | C43: 0.1276 | D43: 0.1301 | E43: 0.1384 | F43: 0.1382 | G43: 0.1407 | H43: 0.1677 | I43: 0.1631 | J43: 0.1629 | K43: 0.142 | L43: 0.1328 | M43: 0.1407 | N43: 0.1405 | O43: 0.134 | P43: 0.1214 | Q43: 0.1215 | R43: 0.127 | S43: 0.147 | T43: 0.1627 | U43: 0.1494 | V43: 0.1692 | W43: 0.1621 | X43: 0.1366 | Y43: 0.1392 | Z43: 0.161
B44: =B43+30 -> 1217 | C44: 0.1275 | D44: 0.1302 | E44: 0.1368 | F44: 0.1386 | G44: 0.1409 | H44: 0.1663 | I44: 0.1626 | J44: 0.1617 | K44: 0.1423 | L44: 0.1324 | M44: 0.1396 | N44: 0.14 | O44: 0.1335 | P44: 0.1216 | Q44: 0.1216 | R44: 0.1267 | S44: 0.1476 | T44: 0.1666 | U44: 0.1489 | V44: 0.168 | W44: 0.1624 | X44: 0.1365 | Y44: 0.1393 | Z44: 0.1588
B45: =B44+30 -> 1247 | C45: 0.1278 | D45: 0.1304 | E45: 0.1375 | F45: 0.1392 | G45: 0.1409 | H45: 0.1694 | I45: 0.1646 | J45: 0.163 | K45: 0.1441 | L45: 0.1327 | M45: 0.1403 | N45: 0.1404 | O45: 0.1334 | P45: 0.1215 | Q45: 0.1215 | R45: 0.1266 | S45: 0.1484 | T45: 0.1695 | U45: 0.1501 | V45: 0.1682 | W45: 0.1609 | X45: 0.1365 | Y45: 0.1385 | Z45: 0.1645
...

Sheet r3
A1: Sample | B1: Time | C1: OD600 | D1: Group | E1: Substrate
A2: pd.1_Dark | B2: ='Round3.raw'!B3 -> 0 | C2: ='Round3.raw'!C3 -> 0.1741 | D2: pd_Dark | E2: Dark
A3: pd.1_Dark | B3: ='Round3.raw'!B4 -> 30 | C3: ='Round3.raw'!C4 -> 0.2244 | D3: pd_Dark | E3: Dark
A4: pd.1_Dark | B4: ='Round3.raw'!B5 -> 60 | C4: ='Round3.raw'!C5 -> 0.2306 | D4: pd_Dark | E4: Dark
A5: pd.1_Dark | B5: ='Round3.raw'!B6 -> 90 | C5: ='Round3.raw'!C6 -> 0.1583 | D5: pd_Dark | E5: Dark
A6: pd.1_Dark | B6: ='Round3.raw'!B7 -> 120 | C6: ='Round3.raw'!C7 -> 0.1603 | D6: pd_Dark | E6: Dark
A7: pd.1_Dark | B7: ='Round3.raw'!B8 -> 150 | C7: ='Round3.raw'!C8 -> 0.2073 | D7: pd_Dark | E7: Dark
A8: pd.1_Dark | B8: ='Round3.raw'!B9 -> 180 | C8: ='Round3.raw'!C9 -> 0.217 | D8: pd_Dark | E8: Dark
A9: pd.1_Dark | B9: ='Round3.raw'!B10 -> 210 | C9: ='Round3.raw'!C10 -> 0.1915 | D9: pd_Dark | E9: Dark
A10: pd.1_Dark | B10: ='Round3.raw'!B11 -> 240 | C10: ='Round3.raw'!C11 -> 0.1968 | D10: pd_Dark | E10: Dark
A11: pd.1_Dark | B11: ='Round3.raw'!B12 -> 270 | C11: ='Round3.raw'!C12 -> 0.1666 | D11: pd_Dark | E11: Dark
A12: pd.1_Dark | B12: ='Round3.raw'!B13 -> 300 | C12: ='Round3.raw'!C13 -> 0.1566 | D12: pd_Dark | E12: Dark
A13: pd.1_Dark | B13: ='Round3.raw'!B14 -> 330 | C13: ='Round3.raw'!C14 -> 0.1995 | D13: pd_Dark | E13: Dark
... A50: pd.1_Dark | B50: ='Round3.raw'!B51 -> 1450 | C50: ='Round3.raw'!C51 -> 0 | D50: pd_Dark | E50: Dark
A51: pd.2_Dark | B51: ='Round3.raw'!B3 -> 0 | C51: ='Round3.raw'!D3 -> 0.1205 | D51: pd_Dark | E51: Dark
A52: pd.2_Dark | B52: ='Round3.raw'!B4 -> 30 | C52: ='Round3.raw'!D4 -> 0.1208 | D52: pd_Dark | E52: Dark
A53: pd.2_Dark | B53: ='Round3.raw'!B5 -> 60 | C53: ='Round3.raw'!D5 -> 0.1458 | D53: pd_Dark | E53: Dark
A54: pd.2_Dark | B54: ='Round3.raw'!B6 -> 90 | C54: ='Round3.raw'!D6 -> 0.1219 | D54: pd_Dark | E54: Dark
A55: pd.2_Dark | B55: ='Round3.raw'!B7 -> 120 | C55: ='Round3.raw'!D7 -> 0.1223 | D55: pd_Dark | E55: Dark
A56: pd.2_Dark | B56: ='Round3.raw'!B8 -> 150 | C56: ='Round3.raw'!D8 -> 0.1255 | D56: pd_Dark | E56: Dark
A57: pd.2_Dark | B57: ='Round3.raw'!B9 -> 180 | C57: ='Round3.raw'!D9 -> 0.1369 | D57: pd_Dark | E57: Dark
A58: pd.2_Dark | B58: ='Round3.raw'!B10 -> 210 | C58: ='Round3.raw'!D10 -> 0.1509 | D58: pd_Dark | E58: Dark
A59: pd.2_Dark | B59: ='Round3.raw'!B11 -> 240 | C59: ='Round3.raw'!D11 -> 0.1381 | D59: pd_Dark | E59: Dark
A60: pd.2_Dark | B60: ='Round3.raw'!B12 -> 270 | C60: ='Round3.raw'!D12 -> 0.1574 | D60: pd_Dark | E60: Dark
A61: pd.2_Dark | B61: ='Round3.raw'!B13 -> 300 | C61: ='Round3.raw'!D13 -> 0.1667 | D61: pd_Dark | E61: Dark
A62: pd.2_Dark | B62: ='Round3.raw'!B14 -> 330 | C62: ='Round3.raw'!D14 -> 0.133 | D62: pd_Dark | E62: Dark
... A99: pd.2_Dark | B99: ='Round3.raw'!B51 -> 1450 | C99: ='Round3.raw'!D51 -> 0 | D99: pd_Dark | E99: Dark
A100: pd.3_Dark | B100: ='Round3.raw'!B3 -> 0 | C100: ='Round3.raw'!E3 -> 0.1255 | D100: pd_Dark | E100: Dark
A101: pd.3_Dark | B101: ='Round3.raw'!B4 -> 30 | C101: ='Round3.raw'!E4 -> 0.1245 | D101: pd_Dark | E101: Dark
A102: pd.3_Dark | B102: ='Round3.raw'!B5 -> 60 | C102: ='Round3.raw'!E5 -> 0.151 | D102: pd_Dark | E102: Dark
A103: pd.3_Dark | B103: ='Round3.raw'!B6 -> 90 | C103: ='Round3.raw'!E6 -> 0.127 | D103: pd_Dark | E103: Dark
A104: pd.3_Dark | B104: ='Round3.raw'!B7 -> 120 | C104: ='Round3.raw'!E7 -> 0.1281 | D104: pd_Dark | E104: Dark
A105: pd.3_Dark | B105: ='Round3.raw'!B8 -> 150 | C105: ='Round3.raw'!E8 -> 0.1279 | D105: pd_Dark | E105: Dark
A106: pd.3_Dark | B106: ='Round3.raw'!B9 -> 180 | C106: ='Round3.raw'!E9 -> 0.1272 | D106: pd_Dark | E106: Dark
A107: pd.3_Dark | B107: ='Round3.raw'!B10 -> 210 | C107: ='Round3.raw'!E10 -> 0.1319 | D107: pd_Dark | E107: Dark
A108: pd.3_Dark | B108: ='Round3.raw'!B11 -> 240 | C108: ='Round3.raw'!E11 -> 0.1322 | D108: pd_Dark | E108: Dark
A109: pd.3_Dark | B109: ='Round3.raw'!B12 -> 270 | C109: ='Round3.raw'!E12 -> 0.1408 | D109: pd_Dark | E109: Dark
A110: pd.3_Dark | B110: ='Round3.raw'!B13 -> 300 | C110: ='Round3.raw'!E13 -> 0.1372 | D110: pd_Dark | E110: Dark
A111: pd.3_Dark | B111: ='Round3.raw'!B14 -> 330 | C111: ='Round3.raw'!E14 -> 0.1386 | D111: pd_Dark | E111: Dark
... A148: pd.3_Dark | B148: ='Round3.raw'!B51 -> 1450 | C148: ='Round3.raw'!E51 -> 0 | D148: pd_Dark | E148: Dark
...

Sheet Round3.raw
A1: Data-Time | B1: Time | C1: Dark | O1: IR
A2: Data-Time | B2: Time 1 | C2: pd.1_Dark | D2: pd.2_Dark | E2: pd.3_Dark | F2: mz.1_Dark | G2: mz.2_Dark | H2: mz.3_Dark | I2: am.1_Dark | J2: am.2_Dark | K2: am.3_Dark | L2: Syn.1_Dark | M2: Syn.2_Dark | N2: Syn.3_Dark | O2: pd.1_IR | P2: pd.2_IR | Q2: pd.3_IR | R2: mz.1_IR | S2: mz.2_IR | T2: mz.3_IR | U2: am.1_Dark | V2: am.2_Dark | W2: am.3_Dark | X2: Syn.1_IR | Y2: Syn.2_IR | Z2: Syn.3_IR | AA2: Tips
A3: 46059.852 | B3: 0 | C3: 0.1741 | D3: 0.1205 | E3: 0.1255 | F3: 0.1259 | G3: 0.1244 | H3: 0.1342 | I3: 0.1206 | J3: 0.1204 | K3: 0.1198 | L3: 0.1352 | M3: 0.1457 | N3: 0.139 | O3: 0.1247 | P3: 0.1269 | Q3: 0.1197 | R3: 0.1317 | S3: 0.1275 | T3: 0.1309 | U3: 0.1236 | V3: 0.1222 | W3: 0.1297 | X3: 0.1353 | Y3: 0.1394 | Z3: 0.1417
B4: =B3+30 -> 30 | C4: 0.2244 | D4: 0.1208 | E4: 0.1245 | F4: 0.1242 | G4: 0.1244 | H4: 0.1334 | I4: 0.1202 | J4: 0.1205 | K4: 0.1199 | L4: 0.1367 | M4: 0.1454 | N4: 0.1386 | O4: 0.1323 | P4: 0.1246 | Q4: 0.1174 | R4: 0.1313 | S4: 0.1284 | T4: 0.1294 | U4: 0.1224 | V4: 0.121 | W4: 0.1287 | X4: 0.135 | Y4: 0.1408 | Z4: 0.1462
A5: 46059.893 | B5: =B4+30 -> 60 | C5: 0.2306 | D5: 0.1458 | E5: 0.151 | F5: 0.1459 | G5: 0.1469 | H5: 0.1551 | I5: 0.1419 | J5: 0.1482 | K5: 0.1473 | L5: 0.1508 | M5: 0.1596 | N5: 0.1392 | O5: 0.1287 | P5: 0.1274 | Q5: 0.1222 | R5: 0.1347 | S5: 0.1334 | T5: 0.1315 | U5: 0.1265 | V5: 0.1228 | W5: 0.1303 | X5: 0.1359 | Y5: 0.1413 | Z5: 0.187
B6: =B5+30 -> 90 | C6: 0.1583 | D6: 0.1219 | E6: 0.127 | F6: 0.1269 | G6: 0.1233 | H6: 0.1351 | I6: 0.1222 | J6: 0.1207 | K6: 0.1208 | L6: 0.1389 | M6: 0.1463 | N6: 0.1395 | O6: 0.1273 | P6: 0.1273 | Q6: 0.1189 | R6: 0.1321 | S6: 0.1445 | T6: 0.1293 | U6: 0.1243 | V6: 0.12 | W6: 0.129 | X6: 0.1359 | Y6: 0.1413 | Z6: 0.1877
B7: =B6+30 -> 120 | C7: 0.1603 | D7: 0.1223 | E7: 0.1281 | F7: 0.1272 | G7: 0.1248 | H7: 0.1391 | I7: 0.1225 | J7: 0.1207 | K7: 0.121 | L7: 0.1381 | M7: 0.1475 | N7: 0.1405 | O7: 0.1264 | P7: 0.1462 | Q7: 0.1191 | R7: 0.1331 | S7: 0.1479 | T7: 0.13 | U7: 0.1243 | V7: 0.1205 | W7: 0.1293 | X7: 0.1364 | Y7: 0.1417 | Z7: 0.1891
B8: =B7+30 -> 150 | C8: 0.2073 | D8: 0.1255 | E8: 0.1279 | F8: 0.1284 | G8: 0.1254 | H8: 0.1373 | I8: 0.1229 | J8: 0.121 | K8: 0.1215 | L8: 0.1383 | M8: 0.147 | N8: 0.1413 | O8: 0.1261 | P8: 0.1738 | Q8: 0.1188 | R8: 0.1331 | S8: 0.1497 | T8: 0.1301 | U8: 0.1244 | V8: 0.1204 | W8: 0.1295 | X8: 0.1368 | Y8: 0.1421 | Z8: 0.1852
B9: =B8+30 -> 180 | C9: 0.217 | D9: 0.1369 | E9: 0.1272 | F9: 0.1287 | G9: 0.133 | H9: 0.1372 | I9: 0.1226 | J9: 0.1216 | K9: 0.1213 | L9: 0.1386 | M9: 0.1491 | N9: 0.1418 | O9: 0.1258 | P9: 0.1328 | Q9: 0.119 | R9: 0.1337 | S9: 0.1553 | T9: 0.1314 | U9: 0.1254 | V9: 0.1205 | W9: 0.1301 | X9: 0.1373 | Y9: 0.1433 | Z9: 0.1602
B10: =B9+30 -> 210 | C10: 0.1915 | D10: 0.1509 | E10: 0.1319 | F10: 0.1341 | G10: 0.1374 | H10: 0.1369 | I10: 0.1237 | J10: 0.1213 | K10: 0.1221 | L10: 0.1389 | M10: 0.1487 | N10: 0.142 | O10: 0.1258 | P10: 0.1316 | Q10: 0.1194 | R10: 0.1386 | S10: 0.1502 | T10: 0.1322 | U10: 0.1263 | V10: 0.1211 | W10: 0.1307 | X10: 0.1377 | Y10: 0.1427 | Z10: 0.1675
B11: =B10+30 -> 240 | C11: 0.1968 | D11: 0.1381 | E11: 0.1322 | F11: 0.1348 | G11: 0.1384 | H11: 0.1373 | I11: 0.1243 | J11: 0.1217 | K11: 0.122 | L11: 0.1382 | M11: 0.1491 | N11: 0.1415 | O11: 0.1258 | P11: 0.131 | Q11: 0.1199 | R11: 0.1373 | S11: 0.1423 | T11: 0.1432 | U11: 0.1263 | V11: 0.1214 | W11: 0.131 | X11: 0.1373 | Y11: 0.1426 | Z11: 0.152
B12: =B11+30 -> 270 | C12: 0.1666 | D12: 0.1574 | E12: 0.1408 | F12: 0.1461 | G12: 0.135 | H12: 0.1405 | I12: 0.1246 | J12: 0.1218 | K12: 0.1226 | L12: 0.1379 | M12: 0.149 | N12: 0.1427 | O12: 0.1259 | P12: 0.1326 | Q12: 0.1202 | R12: 0.1403 | S12: 0.1478 | T12: 0.1505 | U12: 0.1277 | V12: 0.1218 | W12: 0.1321 | X12: 0.1371 | Y12: 0.1431 | Z12: 0.1548
B13: =B12+30 -> 300 | C13: 0.1566 | D13: 0.1667 | E13: 0.1372 | F13: 0.1327 | G13: 0.1327 | H13: 0.1385 | I13: 0.1246 | J13: 0.1241 | K13: 0.1223 | L13: 0.1373 | M13: 0.1493 | N13: 0.1425 | O13: 0.1259 | P13: 0.1324 | Q13: 0.1211 | R13: 0.1461 | S13: 0.1446 | T13: 0.1474 | U13: 0.1273 | V13: 0.122 | W13: 0.1317 | X13: 0.1371 | Y13: 0.1428 | Z13: 0.162
B14: =B13+30 -> 330 | C14: 0.1995 | D14: 0.133 | E14: 0.1386 | F14: 0.1335 | G14: 0.1249 | H14: 0.1507 | I14: 0.1247 | J14: 0.1222 | K14: 0.1226 | L14: 0.1367 | M14: 0.1493 | N14: 0.1436 | O14: 0.126 | P14: 0.1323 | Q14: 0.1212 | R14: 0.1516 | S14: 0.145 | T14: 0.1308 | U14: 0.128 | V14: 0.1222 | W14: 0.1318 | X14: 0.1373 | Y14: 0.1434 | Z14: 0.1665
B15: =B14+30 -> 360 | C15: 0.171 | D15: 0.1375 | E15: 0.1357 | F15: 0.1318 | G15: 0.1322 | H15: 0.1351 | I15: 0.1262 | J15: 0.1227 | K15: 0.1234 | L15: 0.136 | M15: 0.1497 | N15: 0.1433 | O15: 0.1261 | P15: 0.1326 | Q15: 0.1234 | R15: 0.1432 | S15: 0.1463 | T15: 0.1329 | U15: 0.1289 | V15: 0.1227 | W15: 0.1317 | X15: 0.1375 | Y15: 0.144 | Z15: 0.1524
B16: =B15+30 -> 390 | C16: 0.1531 | D16: 0.1301 | E16: 0.1358 | F16: 0.1298 | G16: 0.1288 | H16: 0.1416 | I16: 0.1255 | J16: 0.1224 | K16: 0.1237 | L16: 0.136 | M16: 0.1498 | N16: 0.1436 | O16: 0.1262 | P16: 0.1318 | Q16: 0.1225 | R16: 0.1443 | S16: 0.1449 | T16: 0.135 | U16: 0.1309 | V16: 0.1227 | W16: 0.1315 | X16: 0.1368 | Y16: 0.1435 | Z16: 0.1585
B17: =B16+30 -> 420 | C17: 0.1419 | D17: 0.14 | E17: 0.1359 | F17: 0.1281 | G17: 0.1288 | H17: 0.1374 | I17: 0.1285 | J17: 0.1223 | K17: 0.1239 | L17: 0.1358 | M17: 0.15 | N17: 0.1431 | O17: 0.1266 | P17: 0.1317 | Q17: 0.1342 | R17: 0.1411 | S17: 0.1457 | T17: 0.1331 | U17: 0.1316 | V17: 0.1229 | W17: 0.1316 | X17: 0.1376 | Y17: 0.1436 | Z17: 0.1586
... B29: =B28+30 -> 780 | C29: 0.132 | D29: 0.1276 | E29: 0.1296 | F29: 0.1255 | G29: 0.1272 | H29: 0.135 | I29: 0.1398 | J29: 0.1231 | K29: 0.1261 | L29: 0.1336 | M29: 0.1499 | N29: 0.142 | O29: 0.1273 | P29: 0.1295 | Q29: 0.1327 | R29: 0.1493 | S29: 0.1329 | T29: 0.1281 | U29: 0.1315 | V29: 0.1243 | W29: 0.1314 | X29: 0.1363 | Y29: 0.1408 | Z29: 0.1467
B30: =B29+40 -> 820 | C30: 0.1302 | D30: 0.1301 | E30: 0.1307 | F30: 0.1267 | G30: 0.1258 | H30: 0.1355 | I30: 0.1281 | J30: 0.1242 | K30: 0.1273 | L30: 0.1335 | M30: 0.1499 | N30: 0.1415 | O30: 0.1271 | P30: 0.1294 | Q30: 0.1364 | R30: 0.1476 | S30: 0.1325 | T30: 0.1282 | U30: 0.1316 | V30: 0.1248 | W30: 0.1311 | X30: 0.1361 | Y30: 0.1406 | Z30: 0.1479
B31: =B30+30 -> 850 | C31: 0.1302 | D31: 0.1315 | E31: 0.132 | F31: 0.127 | G31: 0.1274 | H31: 0.1356 | I31: 0.1435 | J31: 0.137 | K31: 0.1281 | L31: 0.1334 | M31: 0.1496 | N31: 0.1411 | O31: 0.1269 | P31: 0.1292 | Q31: 0.1358 | R31: 0.1478 | S31: 0.1326 | T31: 0.1277 | U31: 0.132 | V31: 0.1247 | W31: 0.131 | X31: 0.1362 | Y31: 0.1405 | Z31: 0.1485
B32: =B31+30 -> 880 | C32: 0.1298 | D32: 0.1333 | E32: 0.1325 | F32: 0.1275 | G32: 0.126 | H32: 0.1356 | I32: 0.1294 | J32: 0.1319 | K32: 0.1289 | L32: 0.1332 | M32: 0.1496 | N32: 0.141 | O32: 0.1268 | P32: 0.1292 | Q32: 0.1371 | R32: 0.1482 | S32: 0.1328 | T32: 0.1276 | U32: 0.1317 | V32: 0.1246 | W32: 0.131 | X32: 0.1362 | Y32: 0.1403 | Z32: 0.1481
B33: =B32+30 -> 910 | C33: 0.1303 | D33: 0.1366 | E33: 0.1327 | F33: 0.1266 | G33: 0.1257 | H33: 0.1354 | I33: 0.124 | J33: 0.1233 | K33: 0.1277 | L33: 0.1326 | M33: 0.1496 | N33: 0.1403 | O33: 0.1266 | P33: 0.1294 | Q33: 0.1379 | R33: 0.1451 | S33: 0.1317 | T33: 0.1278 | U33: 0.1309 | V33: 0.1247 | W33: 0.1304 | X33: 0.136 | Y33: 0.1399 | Z33: 0.1495
B34: =B33+30 -> 940 | C34: 0.1294 | D34: 0.1324 | E34: 0.1326 | F34: 0.1285 | G34: 0.1241 | H34: 0.1342 | I34: 0.1272 | J34: 0.1352 | K34: 0.1291 | L34: 0.1326 | M34: 0.149 | N34: 0.1401 | O34: 0.1267 | P34: 0.1293 | Q34: 0.1362 | R34: 0.1418 | S34: 0.1316 | T34: 0.1275 | U34: 0.1305 | V34: 0.1248 | W34: 0.1301 | X34: 0.1356 | Y34: 0.1395 | Z34: 0.1478
B35: =B34+30 -> 970 | C35: 0.1298 | D35: 0.1317 | E35: 0.132 | F35: 0.1266 | G35: 0.1239 | H35: 0.1341 | I35: 0.1249 | J35: 0.1226 | K35: 0.1284 | L35: 0.1321 | M35: 0.1488 | N35: 0.1396 | O35: 0.1265 | P35: 0.1291 | Q35: 0.1366 | R35: 0.1385 | S35: 0.1315 | T35: 0.1273 | U35: 0.1306 | V35: 0.1247 | W35: 0.1297 | X35: 0.1356 | Y35: 0.1393 | Z35: 0.1516
A36: 46060.539 | B36: =B35+30 -> 1000 | C36: 0.1295 | D36: 0.1304 | E36: 0.132 | F36: 0.1292 | G36: 0.1239 | H36: 0.1338 | I36: 0.1246 | J36: 0.1229 | K36: 0.1282 | L36: 0.1322 | M36: 0.149 | N36: 0.14 | O36: 0.1264 | P36: 0.1288 | Q36: 0.1348 | R36: 0.1363 | S36: 0.1312 | T36: 0.1268 | U36: 0.1309 | V36: 0.1249 | W36: 0.1297 | X36: 0.1359 | Y36: 0.1389 | Z36: 0.1481
A37: 46060.546 | B37: =B36+10 -> 1010 | C37: 0.1286 | D37: 0.1384 | E37: 0.1387 | F37: 0.1325 | G37: 0.1273 | H37: 0.1364 | I37: 0.1245 | J37: 0.1287 | K37: 0.1326 | L37: 0.1333 | M37: 0.1553 | N37: 0.1458 | O37: 0.1269 | P37: 0.1293 | Q37: 0.1356 | R37: 0.1459 | S37: 0.1289 | T37: 0.1274 | U37: 0.1351 | V37: 0.1262 | W37: 0.1313 | X37: 0.1389 | Y37: 0.1397 | Z37: 0.1453
B38: =B37+30 -> 1040 | C38: 0.1277 | D38: 0.1314 | E38: 0.1341 | F38: 0.1297 | G38: 0.1253 | H38: 0.135 | I38: 0.1249 | J38: 0.1279 | K38: 0.1313 | L38: 0.1326 | M38: 0.152 | N38: 0.1431 | O38: 0.1263 | P38: 0.1285 | Q38: 0.1338 | R38: 0.1379 | S38: 0.128 | T38: 0.1261 | U38: 0.1331 | V38: 0.1257 | W38: 0.1293 | X38: 0.1362 | Y38: 0.139 | Z38: 0.147
B39: =B38+30 -> 1070 | C39: 0.1273 | D39: 0.1309 | E39: 0.1317 | F39: 0.1274 | G39: 0.1234 | H39: 0.1333 | I39: 0.1233 | J39: 0.1284 | K39: 0.1307 | L39: 0.1321 | M39: 0.1506 | N39: 0.1395 | O39: 0.1267 | P39: 0.1284 | Q39: 0.1312 | R39: 0.1352 | S39: 0.1275 | T39: 0.1258 | U39: 0.1315 | V39: 0.1256 | W39: 0.129 | X39: 0.1357 | Y39: 0.1384 | Z39: 0.1481
B40: =B39+30 -> 1100 | C40: 0.1274 | D40: 0.1294 | E40: 0.1311 | F40: 0.1262 | G40: 0.1228 | H40: 0.1327 | I40: 0.1234 | J40: 0.125 | K40: 0.1296 | L40: 0.1317 | M40: 0.1499 | N40: 0.1413 | O40: 0.1255 | P40: 0.1282 | Q40: 0.1294 | R40: 0.1337 | S40: 0.1273 | T40: 0.1255 | U40: 0.1307 | V40: 0.1254 | W40: 0.1292 | X40: 0.1352 | Y40: 0.1385 | Z40: 0.1455
B41: =B40+30 -> 1130 | C41: 0.1273 | D41: 0.1276 | E41: 0.1308 | F41: 0.126 | G41: 0.1225 | H41: 0.1321 | I41: 0.1231 | J41: 0.1227 | K41: 0.1286 | L41: 0.1317 | M41: 0.1498 | N41: 0.1401 | O41: 0.1257 | P41: 0.1281 | Q41: 0.1273 | R41: 0.1325 | S41: 0.127 | T41: 0.1255 | U41: 0.1305 | V41: 0.1259 | W41: 0.1289 | X41: 0.135 | Y41: 0.1384 | Z41: 0.1594
A42: 46060.65 | B42: =B41+30 -> 1160 | C42: 0.1269 | D42: 0.1279 | E42: 0.1313 | F42: 0.1255 | G42: 0.1221 | H42: 0.132 | I42: 0.1238 | J42: 0.1223 | K42: 0.1285 | L42: 0.1314 | M42: 0.1489 | N42: 0.1398 | O42: 0.1254 | P42: 0.128 | Q42: 0.1266 | R42: 0.1317 | S42: 0.1267 | T42: 0.1252 | U42: 0.1298 | V42: 0.1258 | W42: 0.1288 | X42: 0.1349 | Y42: 0.1382 | Z42: 0.1485
A43: 46060.669 | B43: =B42+30 -> 1190
A44: 46060.69 | B44: =B43+30 -> 1220 | C44: 0.1263 | D44: 0.129 | E44: 0.1317 | F44: 0.1269 | G44: 0.1227 | H44: 0.1325 | I44: 0.1237 | J44: 0.1241 | K44: 0.1286 | L44: 0.1314 | M44: 0.1508 | N44: 0.1457 | O44: 0.1266 | P44: 0.1281 | Q44: 0.1255 | R44: 0.1315 | S44: 0.1265 | T44: 0.1251 | U44: 0.1297 | V44: 0.1285 | W44: 0.1291 | X44: 0.135 | Y44: 0.138 | Z44: 0.146
A45: 46060.724 | B45: =B44+50 -> 1270
B46: =B45+30 -> 1300 | C46: 0.1262 | D46: 0.1273 | L46: 0.1312 | M46: 0.1509 | N46: 0.1399 | O46: 0.1277 | P46: 0.1303 | Q46: 0.1254 | R46: 0.1345 | S46: 0.128 | T46: 0.1243 | U46: 0.13 | V46: 0.1309 | W46: 0.1299 | X46: 0.1368 | Y46: 0.1378 | Z46: 0.1443
B47: =B46+30 -> 1330 | C47: 0.1256 | D47: 0.1267 | E47: 0.1289 | F47: 0.1235 | G47: 0.122 | H47: 0.1319 | I47: 0.1232 | J47: 0.1246 | K47: 0.1271 | L47: 0.1315 | M47: 0.1552 | N47: 0.1422 | O47: 0.1262 | P47: 0.1296 | Q47: 0.1246 | R47: 0.1333 | S47: 0.1268 | T47: 0.1243 | U47: 0.1298 | V47: 0.1324 | W47: 0.1297 | X47: 0.1365 | Y47: 0.1378 | Z47: 0.1447
B48: =B47+30 -> 1360 | C48: 0.1256 | D48: 0.127 | E48: 0.129 | F48: 0.1228 | G48: 0.1221 | H48: 0.1314 | I48: 0.1229 | J48: 0.1238 | K48: 0.1267 | L48: 0.1318 | M48: 0.1538 | N48: 0.1413 | O48: 0.1259 | P48: 0.1289 | Q48: 0.1244 | R48: 0.1317 | S48: 0.1261 | T48: 0.1242 | U48: 0.1286 | V48: 0.137 | W48: 0.1292 | X48: 0.1359 | Y48: 0.1373 | Z48: 0.1442
A49: 46060.807 | B49: =B48+30 -> 1390 | C49: 0.1298 | D49: 0.1271 | E49: 0.1289 | F49: 0.1224 | G49: 0.1222 | H49: 0.1324 | I49: 0.1229 | J49: 0.124 | K49: 0.1263 | L49: 0.1311 | M49: 0.1526 | N49: 0.1383 | O49: 0.1255 | P49: 0.1284 | Q49: 0.1242 | R49: 0.1306 | S49: 0.1259 | T49: 0.1243 | U49: 0.1285 | V49: 0.1322 | W49: 0.1289 | X49: 0.1353 | Y49: 0.1372 | Z49: 0.145
B50: =B49+30 -> 1420
B51: =B50+30 -> 1450
...

Sheet r4
A1: Sample | B1: Time | C1: OD600 | D1: Group | E1: Substrate
A2: pd.1_Dark | B2: ='Round4.raw'!B3 -> 0 | C2: ='Round4.raw'!C3 -> 0.1155 | D2: pd_Dark | E2: Dark
A3: pd.1_Dark | B3: ='Round4.raw'!B4 -> 30 | C3: ='Round4.raw'!C4 -> 0.114 | D3: pd_Dark | E3: Dark
A4: pd.1_Dark | B4: ='Round4.raw'!B5 -> 60 | C4: ='Round4.raw'!C5 -> 0.1316 | D4: pd_Dark | E4: Dark
A5: pd.1_Dark | B5: ='Round4.raw'!B6 -> 90 | C5: ='Round4.raw'!C6 -> 0.1134 | D5: pd_Dark | E5: Dark
A6: pd.1_Dark | B6: ='Round4.raw'!B7 -> 120 | C6: ='Round4.raw'!C7 -> 0.1139 | D6: pd_Dark | E6: Dark
A7: pd.1_Dark | B7: ='Round4.raw'!B8 -> 150 | C7: ='Round4.raw'!C8 -> 0.1139 | D7: pd_Dark | E7: Dark
A8: pd.1_Dark | B8: ='Round4.raw'!B9 -> 180 | C8: ='Round4.raw'!C9 -> 0.1139 | D8: pd_Dark | E8: Dark
A9: pd.1_Dark | B9: ='Round4.raw'!B10 -> 210 | C9: ='Round4.raw'!C10 -> 0.1144 | D9: pd_Dark | E9: Dark
A10: pd.1_Dark | B10: ='Round4.raw'!B11 -> 240 | C10: ='Round4.raw'!C11 -> 0.1151 | D10: pd_Dark | E10: Dark
A11: pd.1_Dark | B11: ='Round4.raw'!B12 -> 270 | C11: ='Round4.raw'!C12 -> 0.115 | D11: pd_Dark | E11: Dark
A12: pd.1_Dark | B12: ='Round4.raw'!B13 -> 300 | C12: ='Round4.raw'!C13 -> 0.1158 | D12: pd_Dark | E12: Dark
A13: pd.1_Dark | B13: ='Round4.raw'!B14 -> 330 | C13: ='Round4.raw'!C14 -> 0.1167 | D13: pd_Dark | E13: Dark
... A44: pd.1_Dark | B44: ='Round4.raw'!B45 -> 1260 | C44: ='Round4.raw'!C45 -> 0.1162 | D44: pd_Dark | E44: Dark
A45: pd.2_Dark | B45: ='Round4.raw'!B3 -> 0 | C45: ='Round4.raw'!D3 -> 0.1178 | D45: pd_Dark | E45: Dark
A46: pd.2_Dark | B46: ='Round4.raw'!B4 -> 30 | C46: ='Round4.raw'!D4 -> 0.1145 | D46: pd_Dark | E46: Dark
A47: pd.2_Dark | B47: ='Round4.raw'!B5 -> 60 | C47: ='Round4.raw'!D5 -> 0.1534 | D47: pd_Dark | E47: Dark
A48: pd.2_Dark | B48: ='Round4.raw'!B6 -> 90 | C48: ='Round4.raw'!D6 -> 0.117 | D48: pd_Dark | E48: Dark
A49: pd.2_Dark | B49: ='Round4.raw'!B7 -> 120 | C49: ='Round4.raw'!D7 -> 0.1178 | D49: pd_Dark | E49: Dark
A50: pd.2_Dark | B50: ='Round4.raw'!B8 -> 150 | C50: ='Round4.raw'!D8 -> 0.1183 | D50: pd_Dark | E50: Dark
A51: pd.2_Dark | B51: ='Round4.raw'!B9 -> 180 | C51: ='Round4.raw'!D9 -> 0.1194 | D51: pd_Dark | E51: Dark
A52: pd.2_Dark | B52: ='Round4.raw'!B10 -> 210 | C52: ='Round4.raw'!D10 -> 0.1206 | D52: pd_Dark | E52: Dark
A53: pd.2_Dark | B53: ='Round4.raw'!B11 -> 240 | C53: ='Round4.raw'!D11 -> 0.1208 | D53: pd_Dark | E53: Dark
A54: pd.2_Dark | B54: ='Round4.raw'!B12 -> 270 | C54: ='Round4.raw'!D12 -> 0.1215 | D54: pd_Dark | E54: Dark
A55: pd.2_Dark | B55: ='Round4.raw'!B13 -> 300 | C55: ='Round4.raw'!D13 -> 0.1243 | D55: pd_Dark | E55: Dark
A56: pd.2_Dark | B56: ='Round4.raw'!B14 -> 330 | C56: ='Round4.raw'!D14 -> 0.1263 | D56: pd_Dark | E56: Dark
... A87: pd.2_Dark | B87: ='Round4.raw'!B45 -> 1260 | C87: ='Round4.raw'!D45 -> 0.1203 | D87: pd_Dark | E87: Dark
A88: pd.3_Dark | B88: ='Round4.raw'!B3 -> 0 | C88: ='Round4.raw'!E3 -> 0.1203 | D88: pd_Dark | E88: Dark
A89: pd.3_Dark | B89: ='Round4.raw'!B4 -> 30 | C89: ='Round4.raw'!E4 -> 0.1163 | D89: pd_Dark | E89: Dark
A90: pd.3_Dark | B90: ='Round4.raw'!B5 -> 60 | C90: ='Round4.raw'!E5 -> 0.1543 | D90: pd_Dark | E90: Dark
A91: pd.3_Dark | B91: ='Round4.raw'!B6 -> 90 | C91: ='Round4.raw'!E6 -> 0.1193 | D91: pd_Dark | E91: Dark
A92: pd.3_Dark | B92: ='Round4.raw'!B7 -> 120 | C92: ='Round4.raw'!E7 -> 0.1194 | D92: pd_Dark | E92: Dark
A93: pd.3_Dark | B93: ='Round4.raw'!B8 -> 150 | C93: ='Round4.raw'!E8 -> 0.1199 | D93: pd_Dark | E93: Dark
A94: pd.3_Dark | B94: ='Round4.raw'!B9 -> 180 | C94: ='Round4.raw'!E9 -> 0.1199 | D94: pd_Dark | E94: Dark
A95: pd.3_Dark | B95: ='Round4.raw'!B10 -> 210 | C95: ='Round4.raw'!E10 -> 0.1204 | D95: pd_Dark | E95: Dark
A96: pd.3_Dark | B96: ='Round4.raw'!B11 -> 240 | C96: ='Round4.raw'!E11 -> 0.1209 | D96: pd_Dark | E96: Dark
A97: pd.3_Dark | B97: ='Round4.raw'!B12 -> 270 | C97: ='Round4.raw'!E12 -> 0.1211 | D97: pd_Dark | E97: Dark
A98: pd.3_Dark | B98: ='Round4.raw'!B13 -> 300 | C98: ='Round4.raw'!E13 -> 0.1215 | D98: pd_Dark | E98: Dark
A99: pd.3_Dark | B99: ='Round4.raw'!B14 -> 330 | C99: ='Round4.raw'!E14 -> 0.122 | D99: pd_Dark | E99: Dark
... A130: pd.3_Dark | B130: ='Round4.raw'!B45 -> 1260 | C130: ='Round4.raw'!E45 -> 0.1349 | D130: pd_Dark | E130: Dark
...

Sheet Round4.raw
A1: Data-Time | B1: Time | C1: Dark | O1: IR
A2: Data-Time | B2: Time 1 | C2: pd.1_Dark | D2: pd.2_Dark | E2: pd.3_Dark | F2: mz.1_Dark | G2: mz.2_Dark | H2: mz.3_Dark | I2: am.1_Dark | J2: am.2_Dark | K2: am.3_Dark | L2: Syn.1_Dark | M2: Syn.2_Dark | N2: Syn.3_Dark | O2: pd.1_IR | P2: pd.2_IR | Q2: pd.3_IR | R2: mz.1_IR | S2: mz.2_IR | T2: mz.3_IR | U2: am.1_Dark | V2: am.2_Dark | W2: am.3_Dark | X2: Syn.1_IR | Y2: Syn.2_IR | Z2: Syn.3_IR | AA2: Tips
A3: 46060.825 | B3: 0 | C3: 0.1155 | D3: 0.1178 | E3: 0.1203 | F3: 0.1243 | G3: 0.1168 | H3: 0.1216 | I3: 0.1069 | J3: 0.114 | K3: 0.114 | L3: 0.136 | M3: 0.1357 | N3: 0.1327 | O3: 0.1193 | P3: 0.1188 | Q3: 0.1189 | R3: 0.1214 | S3: 0.1195 | T3: 0.1156 | U3: 0.1173 | V3: 0.1176 | W3: 0.1241 | X3: 0.1289 | Y3: 0.1325 | Z3: 0.1306
A4: 46060.846 | B4: =B3+30 -> 30 | C4: 0.114 | D4: 0.1145 | E4: 0.1163 | F4: 0.1195 | G4: 0.1155 | H4: 0.1189 | I4: 0.1061 | J4: 0.1126 | K4: 0.1126 | L4: 0.1353 | M4: 0.1375 | N4: 0.1316 | O4: 0.1158 | P4: 0.1163 | Q4: 0.1166 | R4: 0.1205 | S4: 0.118 | T4: 0.1158 | U4: 0.1166 | V4: 0.1144 | W4: 0.1216 | X4: 0.1299 | Y4: 0.132 | Z4: 0.1301
A5: 46060.868 | B5: =B4+30 -> 60 | C5: 0.1316 | D5: 0.1534 | E5: 0.1543 | F5: 0.1542 | G5: 0.1503 | H5: 0.1435 | I5: 0.132 | J5: 0.1313 | K5: 0.1291 | L5: 0.1466 | M5: 0.1418 | N5: 0.1336 | O5: 0.1253 | P5: 0.135 | Q5: 0.1587 | R5: 0.1552 | S5: 0.1526 | T5: 0.1484 | U5: 0.1518 | V5: 0.1404 | W5: 0.1506 | X5: 0.1421 | Y5: 0.1452 | Z5: 0.1331
B6: =B5+30 -> 90 | C6: 0.1134 | D6: 0.117 | E6: 0.1193 | F6: 0.1239 | G6: 0.1169 | H6: 0.123 | I6: 0.1078 | J6: 0.1141 | K6: 0.1127 | L6: 0.1381 | M6: 0.1399 | N6: 0.1347 | O6: 0.1163 | P6: 0.1153 | Q6: 0.1184 | R6: 0.1221 | S6: 0.1197 | T6: 0.1161 | U6: 0.1167 | V6: 0.1152 | W6: 0.1227 | X6: 0.1314 | Y6: 0.1366 | Z6: 0.1344
B7: =B6+30 -> 120 | C7: 0.1139 | D7: 0.1178 | E7: 0.1194 | F7: 0.1246 | G7: 0.1172 | H7: 0.1236 | I7: 0.1078 | J7: 0.1142 | K7: 0.113 | L7: 0.1381 | M7: 0.1406 | N7: 0.1358 | O7: 0.1161 | P7: 0.1154 | Q7: 0.1183 | R7: 0.1215 | S7: 0.1209 | T7: 0.1164 | U7: 0.1167 | V7: 0.1164 | W7: 0.1233 | X7: 0.1327 | Y7: 0.1375 | Z7: 0.1349
B8: =B7+30 -> 150 | C8: 0.1139 | D8: 0.1183 | E8: 0.1199 | F8: 0.1266 | G8: 0.1179 | H8: 0.1242 | I8: 0.108 | J8: 0.1145 | K8: 0.1128 | L8: 0.1378 | M8: 0.1407 | N8: 0.1365 | O8: 0.1168 | P8: 0.1163 | Q8: 0.1197 | R8: 0.1216 | S8: 0.1217 | T8: 0.117 | U8: 0.1173 | V8: 0.1169 | W8: 0.1236 | X8: 0.1321 | Y8: 0.1376 | Z8: 0.1356
B9: =B8+30 -> 180 | C9: 0.1139 | D9: 0.1194 | E9: 0.1199 | F9: 0.1275 | G9: 0.1182 | H9: 0.125 | I9: 0.1083 | J9: 0.1148 | K9: 0.1128 | L9: 0.1381 | M9: 0.1411 | N9: 0.1367 | O9: 0.1171 | P9: 0.1174 | Q9: 0.1204 | R9: 0.1221 | S9: 0.1227 | T9: 0.1181 | U9: 0.1184 | V9: 0.1176 | W9: 0.1247 | X9: 0.1336 | Y9: 0.1385 | Z9: 0.1395
B10: =B9+30 -> 210 | C10: 0.1144 | D10: 0.1206 | E10: 0.1204 | F10: 0.1277 | G10: 0.1185 | H10: 0.1256 | I10: 0.109 | J10: 0.1158 | K10: 0.1133 | L10: 0.1392 | M10: 0.1409 | N10: 0.1378 | O10: 0.1173 | P10: 0.1174 | Q10: 0.1209 | R10: 0.125 | S10: 0.1235 | T10: 0.1188 | U10: 0.1189 | V10: 0.1178 | W10: 0.1249 | X10: 0.1335 | Y10: 0.1394 | Z10: 0.1385
B11: =B10+30 -> 240 | C11: 0.1151 | D11: 0.1208 | E11: 0.1209 | F11: 0.1283 | G11: 0.1195 | H11: 0.1263 | I11: 0.1095 | J11: 0.1164 | K11: 0.1136 | L11: 0.1395 | M11: 0.1404 | N11: 0.1391 | O11: 0.1182 | P11: 0.1181 | Q11: 0.1211 | R11: 0.1257 | S11: 0.1257 | T11: 0.1191 | U11: 0.1197 | V11: 0.1181 | W11: 0.1257 | X11: 0.1344 | Y11: 0.1397 | Z11: 0.14
B12: =B11+30 -> 270 | C12: 0.115 | D12: 0.1215 | E12: 0.1211 | F12: 0.1285 | G12: 0.1197 | H12: 0.1266 | I12: 0.1099 | J12: 0.117 | K12: 0.1141 | L12: 0.1398 | M12: 0.1405 | N12: 0.1388 | O12: 0.1214 | P12: 0.1185 | Q12: 0.1218 | R12: 0.125 | S12: 0.1261 | T12: 0.1193 | U12: 0.1202 | V12: 0.1178 | W12: 0.1259 | X12: 0.1349 | Y12: 0.1403 | Z12: 0.1589
B13: =B12+30 -> 300 | C13: 0.1158 | D13: 0.1243 | E13: 0.1215 | F13: 0.128 | G13: 0.1198 | H13: 0.1267 | I13: 0.1099 | J13: 0.1167 | K13: 0.1141 | L13: 0.1392 | M13: 0.1403 | N13: 0.1394 | O13: 0.1232 | P13: 0.1209 | Q13: 0.128 | R13: 0.1259 | S13: 0.1265 | T13: 0.1191 | U13: 0.1207 | V13: 0.1179 | W13: 0.1268 | X13: 0.1346 | Y13: 0.1403 | Z13: 0.1808
B14: =B13+30 -> 330 | C14: 0.1167 | D14: 0.1263 | E14: 0.122 | F14: 0.129 | G14: 0.1202 | H14: 0.1278 | I14: 0.1099 | J14: 0.1169 | K14: 0.1144 | L14: 0.1381 | M14: 0.1409 | N14: 0.1391 | O14: 0.1218 | P14: 0.1277 | Q14: 0.1442 | R14: 0.1482 | S14: 0.1514 | T14: 0.1198 | U14: 0.1208 | V14: 0.1187 | W14: 0.1278 | X14: 0.1347 | Y14: 0.1397 | Z14: 0.1837
B15: =B14+30 -> 360 | C15: 0.1216 | D15: 0.1297 | E15: 0.1228 | F15: 0.129 | G15: 0.1209 | H15: 0.1324 | I15: 0.1103 | J15: 0.1173 | K15: 0.1151 | L15: 0.1379 | M15: 0.1415 | N15: 0.141 | O15: 0.1218 | P15: 0.1315 | Q15: 0.1281 | R15: 0.1295 | S15: 0.1309 | T15: 0.12 | U15: 0.1207 | V15: 0.1185 | W15: 0.1285 | X15: 0.1342 | Y15: 0.1405 | Z15: 0.1686
B16: =B15+30 -> 390 | C16: 0.1182 | D16: 0.1345 | E16: 0.1251 | F16: 0.1284 | G16: 0.1209 | H16: 0.1307 | I16: 0.1102 | J16: 0.1173 | K16: 0.1152 | L16: 0.1377 | M16: 0.1407 | N16: 0.141 | O16: 0.1214 | P16: 0.1303 | Q16: 0.138 | R16: 0.1389 | S16: 0.1607 | T16: 0.1204 | U16: 0.1208 | V16: 0.1187 | W16: 0.1281 | X16: 0.1342 | Y16: 0.1411 | Z16: 0.1669
B17: =B16+30 -> 420 | C17: 0.1197 | D17: 0.1311 | E17: 0.1254 | F17: 0.1276 | G17: 0.1207 | H17: 0.1329 | I17: 0.1106 | J17: 0.1175 | K17: 0.1156 | L17: 0.1373 | M17: 0.141 | N17: 0.1417 | O17: 0.1213 | P17: 0.1241 | Q17: 0.1248 | R17: 0.1539 | S17: 0.1433 | T17: 0.1207 | U17: 0.1209 | V17: 0.1187 | W17: 0.1285 | X17: 0.1334 | Y17: 0.1404 | Z17: 0.1867
... B45: =B44+30 -> 1260 | C45: 0.1162 | D45: 0.1203 | E45: 0.1349 | F45: 0.1235 | G45: 0.1455 | H45: 0.1263 | I45: 0.1134 | J45: 0.1189 | K45: 0.1167 | L45: 0.1362 | M45: 0.1398 | N45: 0.1361 | O45: 0.1186 | P45: 0.1221 | Q45: 0.1266 | R45: 0.1314 | S45: 0.1249 | T45: 0.1212 | U45: 0.1227 | V45: 0.1204 | W45: 0.1286 | X45: 0.133 | Y45: 0.142 | Z45: 0.1519
A46: 46061.722 | B46: =B45+30 -> 1290 | C46: 0.1162 | D46: 0.1203 | E46: 0.1321 | F46: 0.1235 | G46: 0.1463 | H46: 0.1258 | I46: 0.1134 | J46: 0.1187 | K46: 0.1164 | L46: 0.1359 | M46: 0.1397 | N46: 0.1356 | O46: 0.1185 | P46: 0.1211 | Q46: 0.1267 | R46: 0.1312 | S46: 0.1245 | T46: 0.1186 | U46: 0.1222 | V46: 0.1194 | W46: 0.1282 | X46: 0.1329 | Y46: 0.1408 | Z46: 0.1677
B48: △ | C48: =C46-C3 -> 0.0007 | D48: =D46-D3 -> 0.0025 | E48: =E46-E3 -> 0.0118 | F48: =F46-F3 -> -0.0008 | G48: =G46-G3 -> 0.0295 | H48: =H46-H3 -> 0.0042 | I48: =I46-I3 -> 0.0065 | J48: =J46-J3 -> 0.0047 | ... Z48: =Z46-Z3 -> 0.0371

Sheet r3-all
A1: Sample | B1: Time | C1: OD600 | D1: Group | E1: Substrate
A2: pd.1_Dark | B2: ='Round3.raw'!B3 -> 0 | C2: ='Round3.raw'!#REF! -> #REF! | D2: pd_Dark | E2: Dark
A3: pd.1_Dark | B3: ='Round3.raw'!B4 -> 30 | C3: ='Round3.raw'!#REF! -> #REF! | D3: pd_Dark | E3: Dark
A4: pd.1_Dark | B4: ='Round3.raw'!B5 -> 60 | C4: ='Round3.raw'!C5 -> 0.2306 | D4: pd_Dark | E4: Dark
A5: pd.1_Dark | B5: ='Round3.raw'!B6 -> 90 | C5: ='Round3.raw'!C6 -> 0.1583 | D5: pd_Dark | E5: Dark
A6: pd.1_Dark | B6: ='Round3.raw'!B7 -> 120 | C6: ='Round3.raw'!C7 -> 0.1603 | D6: pd_Dark | E6: Dark
A7: pd.1_Dark | B7: ='Round3.raw'!B8 -> 150 | C7: ='Round3.raw'!C8 -> 0.2073 | D7: pd_Dark | E7: Dark
A8: pd.1_Dark | B8: ='Round3.raw'!B9 -> 180 | C8: ='Round3.raw'!C9 -> 0.217 | D8: pd_Dark | E8: Dark
A9: pd.1_Dark | B9: ='Round3.raw'!B10 -> 210 | C9: ='Round3.raw'!C10 -> 0.1915 | D9: pd_Dark | E9: Dark
A10: pd.1_Dark | B10: ='Round3.raw'!B11 -> 240 | C10: ='Round3.raw'!C11 -> 0.1968 | D10: pd_Dark | E10: Dark
A11: pd.1_Dark | B11: ='Round3.raw'!B12 -> 270 | C11: ='Round3.raw'!C12 -> 0.1666 | D11: pd_Dark | E11: Dark
A12: pd.1_Dark | B12: ='Round3.raw'!B13 -> 300 | C12: ='Round3.raw'!C13 -> 0.1566 | D12: pd_Dark | E12: Dark
A13: pd.1_Dark | B13: ='Round3.raw'!B14 -> 330 | C13: ='Round3.raw'!C14 -> 0.1995 | D13: pd_Dark | E13: Dark
A14: pd.1_Dark | B14: ='Round3.raw'!B15 -> 360 | C14: ='Round3.raw'!C15 -> 0.171 | D14: pd_Dark | E14: Dark
A15: pd.1_Dark | B15: ='Round3.raw'!B16 -> 390 | C15: ='Round3.raw'!C16 -> 0.1531 | D15: pd_Dark | E15: Dark
... A50: pd.1_Dark | B50: ='Round3.raw'!B51 -> 1450 | C50: ='Round3.raw'!C51 -> 0 | D50: pd_Dark | E50: Dark
A51: pd.2_Dark | B51: ='Round3.raw'!B3 -> 0 | C51: ='Round3.raw'!#REF! -> #REF! | D51: pd_Dark | E51: Dark
A52: pd.2_Dark | B52: ='Round3.raw'!B4 -> 30 | C52: ='Round3.raw'!#REF! -> #REF! | D52: pd_Dark | E52: Dark
A53: pd.2_Dark | B53: ='Round3.raw'!B5 -> 60 | C53: ='Round3.raw'!D5 -> 0.1458 | D53: pd_Dark | E53: Dark
A54: pd.2_Dark | B54: ='Round3.raw'!B6 -> 90 | C54: ='Round3.raw'!D6 -> 0.1219 | D54: pd_Dark | E54: Dark
A55: pd.2_Dark | B55: ='Round3.raw'!B7 -> 120 | C55: ='Round3.raw'!D7 -> 0.1223 | D55: pd_Dark | E55: Dark
A56: pd.2_Dark | B56: ='Round3.raw'!B8 -> 150 | C56: ='Round3.raw'!D8 -> 0.1255 | D56: pd_Dark | E56: Dark
A57: pd.2_Dark | B57: ='Round3.raw'!B9 -> 180 | C57: ='Round3.raw'!D9 -> 0.1369 | D57: pd_Dark | E57: Dark
A58: pd.2_Dark | B58: ='Round3.raw'!B10 -> 210 | C58: ='Round3.raw'!D10 -> 0.1509 | D58: pd_Dark | E58: Dark
A59: pd.2_Dark | B59: ='Round3.raw'!B11 -> 240 | C59: ='Round3.raw'!D11 -> 0.1381 | D59: pd_Dark | E59: Dark
A60: pd.2_Dark | B60: ='Round3.raw'!B12 -> 270 | C60: ='Round3.raw'!D12 -> 0.1574 | D60: pd_Dark | E60: Dark
A61: pd.2_Dark | B61: ='Round3.raw'!B13 -> 300 | C61: ='Round3.raw'!D13 -> 0.1667 | D61: pd_Dark | E61: Dark
A62: pd.2_Dark | B62: ='Round3.raw'!B14 -> 330 | C62: ='Round3.raw'!D14 -> 0.133 | D62: pd_Dark | E62: Dark
A63: pd.2_Dark | B63: ='Round3.raw'!B15 -> 360 | C63: ='Round3.raw'!D15 -> 0.1375 | D63: pd_Dark | E63: Dark
A64: pd.2_Dark | B64: ='Round3.raw'!B16 -> 390 | C64: ='Round3.raw'!D16 -> 0.1301 | D64: pd_Dark | E64: Dark
... A99: pd.2_Dark | B99: ='Round3.raw'!B51 -> 1450 | C99: ='Round3.raw'!D51 -> 0 | D99: pd_Dark | E99: Dark
A100: pd.3_Dark | B100: ='Round3.raw'!B3 -> 0 | C100: ='Round3.raw'!#REF! -> #REF! | D100: pd_Dark | E100: Dark
