Workbook

Sheet r2
A1: Sample | B1: Time | C1: OD600 | D1: Group | E1: Substrate
A2: pd.1_CN | B2: 0 | C2: 0.0939 | D2: pd_CN_Control | E2: Inorganic
A3: pd.1_CN | B3: =B2+60 -> 60 | C3: 0.0931 | D3: pd_CN_Control | E3: Inorganic
A4: pd.1_CN | B4: =B3+60 -> 120 | C4: 0.0936 | D4: pd_CN_Control | E4: Inorganic
A5: pd.1_CN | B5: =B4+60 -> 180 | C5: 0.0938 | D5: pd_CN_Control | E5: Inorganic
A6: pd.1_CN | B6: =B5+60 -> 240 | C6: 0.0941 | D6: pd_CN_Control | E6: Inorganic
A7: pd.1_CN | B7: =B6+60 -> 300 | C7: 0.0945 | D7: pd_CN_Control | E7: Inorganic
A8: pd.1_CN | B8: =B7+60 -> 360 | C8: 0.0947 | D8: pd_CN_Control | E8: Inorganic
A9: pd.1_CN | B9: =B8+60 -> 420 | C9: 0.0947 | D9: pd_CN_Control | E9: Inorganic
A10: pd.1_CN | B10: =B9+60 -> 480 | C10: 0.0951 | D10: pd_CN_Control | E10: Inorganic
A11: pd.1_CN | B11: =B10+60 -> 540 | C11: 0.095 | D11: pd_CN_Control | E11: Inorganic
A12: pd.1_CN | B12: =B11+60 -> 600 | C12: 0.0951 | D12: pd_CN_Control | E12: Inorganic
A13: pd.1_CN | B13: =B12+60 -> 660 | C13: 0.0951 | D13: pd_CN_Control | E13: Inorganic
A14: pd.1_CN | B14: =B13+60 -> 720 | C14: 0.0951 | D14: pd_CN_Control | E14: Inorganic
... A18: pd.1_CN | B18: =B17+60 -> 960 | C18: 0.098 | D18: pd_CN_Control | E18: Inorganic
A19: pd.1_CN | B19: =B18+30 -> 990 | C19: 0.2485 | D19: pd_CN_Control | E19: Inorganic
A20: pd.1_CN | B20: =B19+30 -> 1020 | C20: 0.1441 | D20: pd_CN_Control | E20: Inorganic
A21: pd.1_CN | B21: =B20+30 -> 1050 | C21: 0.1385 | D21: pd_CN_Control | E21: Inorganic
A22: pd.1_CN | B22: =B21+30 -> 1080 | C22: 0.1459 | D22: pd_CN_Control | E22: Inorganic
A23: pd.1_CN | B23: =B22+30 -> 1110 | C23: 0.159 | D23: pd_CN_Control | E23: Inorganic
A24: pd.1_CN | B24: =B23+30 -> 1140 | C24: 0.1547 | D24: pd_CN_Control | E24: Inorganic
A25: pd.1_CN | B25: =B24+30 -> 1170 | C25: 0.1471 | D25: pd_CN_Control | E25: Inorganic
A26: pd.1_CN | B26: =B25+30 -> 1200 | C26: 0.1612 | D26: pd_CN_Control | E26: Inorganic
A27: pd.1_CN | B27: =B26+30 -> 1230 | C27: 0.1534 | D27: pd_CN_Control | E27: Inorganic
A28: pd.1_CN | B28: =B27+30 -> 1260 | C28: 0.2467 | D28: pd_CN_Control | E28: Inorganic
A29: pd.1_CN | B29: =B28+30 -> 1290 | C29: 0.139 | D29: pd_CN_Control | E29: Inorganic
A30: pd.1_CN | B30: =B27+90 -> 1320 | C30: 0.1792 | D30: pd_CN_Control | E30: Inorganic
A31: pd.1_CN | B31: =B30+20 -> 1340 | C31: 0.2707 | D31: pd_CN_Control | E31: Inorganic
A32: pd.1_CN | B32: =B31+30 -> 1370 | C32: 0.1562 | D32: pd_CN_Control | E32: Inorganic
A33: pd.1_CN | B33: =B30+60 -> 1380 | C33: 0.2151 | D33: pd_CN_Control | E33: Inorganic
A34: pd.1_CN | B34: =B33+30 -> 1410 | C34: 0.1283 | D34: pd_CN_Control | E34: Inorganic
A35: pd.1_CN | B35: =B34+30 -> 1440 | C35: 0.1451 | D35: pd_CN_Control | E35: Inorganic
A36: pd.1_CN | B36: =B35+30 -> 1470 | C36: 0.1567 | D36: pd_CN_Control | E36: Inorganic
A37: pd.1_CN | B37: =B36+30 -> 1500 | C37: 0.1371 | D37: pd_CN_Control | E37: Inorganic
A38: pd.1_CN | B38: =B37+30 -> 1530 | C38: 0.1473 | D38: pd_CN_Control | E38: Inorganic
A39: pd.1_CN | B39: =B38+30 -> 1560 | C39: 0.1328 | D39: pd_CN_Control | E39: Inorganic
A40: pd.1_CN | B40: =B39+30 -> 1590 | C40: 0.1342 | D40: pd_CN_Control | E40: Inorganic
A41: pd.1_CN | B41: =B40+30 -> 1620 | C41: 0.1648 | D41: pd_CN_Control | E41: Inorganic
A42: pd.1_CN | B42: =B41+30 -> 1650 | C42: 0.1438 | D42: pd_CN_Control | E42: Inorganic
A43: pd.1_CN | B43: =B42+30 -> 1680 | C43: 0.1439 | D43: pd_CN_Control | E43: Inorganic
...

Sheet Round2.raw
A1: Data-Time | B1: Time (min) | D1: CN | M1: Mean_CN | P1: TSB | Y1: Mean_TSB
A2: Data-Time | B2: Time 1 | C2: Time 2 | D2: pd.1_CN | E2: pd.2_CN | F2: pd.3_CN | G2: am.1_CN | H2: am.2_CN | I2: am.3_CN | J2: mz.1_CN | K2: mz.2_CN | L2: mz.3_CN | M2: pd | N2: am | O2: mz | P2: pd.1_TSB | Q2: pd.2_TSB | R2: pd.3_TSB | S2: am.1_TSB | T2: am.2_TSB | U2: am.3_TSB | V2: mz.1_TSB | W2: mz.2_TSB | X2: mz.3_TSB | Y2: pd | Z2: am | AA2: mz | AB2: Tips
A3: 46038.819 | C3: 0 | D3: 0.0939 | E3: 0.1968 | F3: 0.1719 | G3: 0.1234 | H3: 0.1298 | I3: 0.2215 | J3: 0.1613 | K3: 0.226 | L3: 0.2241 | M3: =AVERAGE(D3:F3) -> 0.1542 | N3: =AVERAGE(G3:I3) -> 0.15823333 | O3: =AVERAGE(J3:L3) -> 0.2038 | P3: 0.1989 | Q3: 0.209 | R3: 0.2114 | S3: 0.1439 | T3: 0.1382 | U3: 0.156 | V3: 0.2499 | W3: 0.2673 | X3: 0.2765 | Y3: =AVERAGE(P3:R3) -> 0.20643333 | Z3: =AVERAGE(S3:U3) -> 0.14603333 | AA3: =AVERAGE(V3:X3) -> 0.26456667 | AB3: pd_cn有个菌液（pd1）没加进去，加到Am中了（Am3）
C4: =C3+60 -> 60 | D4: 0.0931 | E4: 0.2093 | F4: 0.1907 | G4: 0.1287 | H4: 0.1563 | I4: 0.2434 | J4: 0.1589 | K4: 0.2484 | L4: 0.2409 | M4: =AVERAGE(D4:F4) -> 0.16436667 | N4: =AVERAGE(G4:I4) -> 0.17613333 | O4: =AVERAGE(J4:L4) -> 0.21606667 | P4: 0.2152 | Q4: 0.23 | R4: 0.2323 | S4: 0.172 | T4: 0.1576 | U4: 0.1922 | V4: 0.3237 | W4: 0.3368 | X4: 0.3454 | Y4: =AVERAGE(P4:R4) -> 0.22583333 | Z4: =AVERAGE(S4:U4) -> 0.17393333 | AA4: =AVERAGE(V4:X4) -> 0.3353
C5: =C4+60 -> 120 | D5: 0.0936 | E5: 0.2309 | F5: 0.2131 | G5: 0.1469 | H5: 0.1487 | I5: 0.2633 | J5: 0.1513 | K5: 0.2683 | L5: 0.2659 | M5: =AVERAGE(D5:F5) -> 0.1792 | N5: =AVERAGE(G5:I5) -> 0.1863 | O5: =AVERAGE(J5:L5) -> 0.2285 | P5: 0.2275 | Q5: 0.2442 | R5: 0.2519 | S5: 0.1817 | T5: 0.192 | U5: 0.2268 | V5: 0.4049 | W5: 0.439 | X5: 0.4421 | Y5: =AVERAGE(P5:R5) -> 0.2412 | Z5: =AVERAGE(S5:U5) -> 0.20016667 | AA5: =AVERAGE(V5:X5) -> 0.42866667
C6: =C5+60 -> 180 | D6: 0.0938 | E6: 0.2541 | F6: 0.2348 | G6: 0.156 | H6: 0.154 | I6: 0.3096 | J6: 0.1516 | K6: 0.2849 | L6: 0.2823 | M6: =AVERAGE(D6:F6) -> 0.19423333 | N6: =AVERAGE(G6:I6) -> 0.20653333 | O6: =AVERAGE(J6:L6) -> 0.2396 | P6: 0.2524 | Q6: 0.2574 | R6: 0.2754 | S6: 0.2049 | T6: 0.2184 | U6: 0.2591 | V6: 0.5157 | W6: 0.5603 | X6: 0.5707 | Y6: =AVERAGE(P6:R6) -> 0.26173333 | Z6: =AVERAGE(S6:U6) -> 0.22746667 | AA6: =AVERAGE(V6:X6) -> 0.5489
C7: =C6+60 -> 240 | D7: 0.0941 | E7: 0.2763 | F7: 0.2583 | G7: 0.1645 | H7: 0.1605 | I7: 0.3539 | J7: 0.1619 | K7: 0.3045 | L7: 0.2997 | M7: =AVERAGE(D7:F7) -> 0.20956667 | N7: =AVERAGE(G7:I7) -> 0.2263 | O7: =AVERAGE(J7:L7) -> 0.25536667 | P7: 0.2638 | Q7: 0.2706 | R7: 0.2894 | S7: 0.2363 | T7: 0.233 | U7: 0.3055 | V7: 0.6577 | W7: 0.6844 | X7: 0.7025 | Y7: =AVERAGE(P7:R7) -> 0.2746 | Z7: =AVERAGE(S7:U7) -> 0.25826667 | AA7: =AVERAGE(V7:X7) -> 0.68153333
C8: =C7+60 -> 300 | D8: 0.0945 | E8: 0.3103 | F8: 0.2861 | G8: 0.1647 | H8: 0.1619 | I8: 0.4045 | J8: 0.1478 | K8: 0.317 | L8: 0.3071 | M8: =AVERAGE(D8:F8) -> 0.2303 | N8: =AVERAGE(G8:I8) -> 0.2437 | O8: =AVERAGE(J8:L8) -> 0.2573 | P8: 0.283 | Q8: 0.2857 | R8: 0.3068 | S8: 0.2743 | T8: 0.2763 | U8: 0.3542 | V8: 0.7965 | W8: 0.8006 | X8: 0.8254 | Y8: =AVERAGE(P8:R8) -> 0.29183333 | Z8: =AVERAGE(S8:U8) -> 0.3016 | AA8: =AVERAGE(V8:X8) -> 0.8075
C9: =C8+60 -> 360 | D9: 0.0947 | E9: 0.332 | F9: 0.3094 | G9: 0.182 | H9: 0.1865 | I9: 0.4296 | J9: 0.1477 | K9: 0.3294 | L9: 0.3219 | M9: =AVERAGE(D9:F9) -> 0.24536667 | N9: =AVERAGE(G9:I9) -> 0.26603333 | O9: =AVERAGE(J9:L9) -> 0.26633333 | P9: 0.2989 | Q9: 0.3017 | R9: 0.3241 | S9: 0.3097 | T9: 0.3299 | U9: 0.3836 | V9: 0.9168 | W9: 0.8993 | X9: 0.9081 | Y9: =AVERAGE(P9:R9) -> 0.30823333 | Z9: =AVERAGE(S9:U9) -> 0.34106667 | AA9: =AVERAGE(V9:X9) -> 0.90806667
C10: =C9+60 -> 420 | D10: 0.0947 | E10: 0.3434 | F10: 0.3258 | G10: 0.1748 | H10: 0.1881 | I10: 0.4632 | J10: 0.1589 | K10: 0.3374 | L10: 0.3441 | M10: =AVERAGE(D10:F10) -> 0.25463333 | N10: =AVERAGE(G10:I10) -> 0.27536667 | O10: =AVERAGE(J10:L10) -> 0.28013333 | P10: 0.3171 | Q10: 0.3172 | R10: 0.3427 | S10: 0.3585 | T10: 0.3692 | U10: 0.4561 | V10: 0.9882 | W10: 0.9669 | X10: 0.962 | Y10: =AVERAGE(P10:R10) -> 0.32566667 | Z10: =AVERAGE(S10:U10) -> 0.3946 | AA10: =AVERAGE(V10:X10) -> 0.97236667
C11: =C10+60 -> 480 | D11: 0.0951 | E11: 0.3568 | F11: 0.3446 | G11: 0.185 | H11: 0.1861 | I11: 0.4758 | J11: 0.1632 | K11: 0.3449 | L11: 0.3567 | M11: =AVERAGE(D11:F11) -> 0.2655 | N11: =AVERAGE(G11:I11) -> 0.2823 | O11: =AVERAGE(J11:L11) -> 0.28826667 | P11: 0.3362 | Q11: 0.3329 | R11: 0.3617 | S11: 0.4003 | T11: 0.4309 | U11: 0.5155 | V11: 1.0464 | W11: 1.0272 | X11: 1.0114 | Y11: =AVERAGE(P11:R11) -> 0.3436 | Z11: =AVERAGE(S11:U11) -> 0.4489 | AA11: =AVERAGE(V11:X11) -> 1.0283333
C12: =C11+60 -> 540 | D12: 0.095 | E12: 0.3652 | F12: 0.3468 | G12: 0.1905 | H12: 0.1994 | I12: 0.5262 | J12: 0.1604 | K12: 0.3494 | L12: 0.3678 | M12: =AVERAGE(D12:F12) -> 0.269 | N12: =AVERAGE(G12:I12) -> 0.30536667 | O12: =AVERAGE(J12:L12) -> 0.29253333 | P12: 0.349 | Q12: 0.3517 | R12: 0.3827 | S12: 0.4534 | T12: 0.4933 | U12: 0.5712 | V12: 1.0972 | W12: 1.0689 | X12: 1.0563 | Y12: =AVERAGE(P12:R12) -> 0.36113333 | Z12: =AVERAGE(S12:U12) -> 0.50596667 | AA12: =AVERAGE(V12:X12) -> 1.0741333
C13: =C12+60 -> 600 | D13: 0.0951 | E13: 0.3681 | F13: 0.3454 | G13: 0.1995 | H13: 0.2068 | I13: 0.5524 | J13: 0.1656 | K13: 0.3531 | L13: 0.3841 | M13: =AVERAGE(D13:F13) -> 0.26953333 | N13: =AVERAGE(G13:I13) -> 0.31956667 | O13: =AVERAGE(J13:L13) -> 0.30093333 | P13: 0.3685 | Q13: 0.3734 | R13: 0.406 | S13: 0.4859 | T13: 0.5286 | U13: 0.6391 | V13: 1.125 | W13: 1.1047 | X13: 1.088 | Y13: =AVERAGE(P13:R13) -> 0.38263333 | Z13: =AVERAGE(S13:U13) -> 0.5512 | AA13: =AVERAGE(V13:X13) -> 1.1059
C14: =C13+60 -> 660 | D14: 0.0951 | E14: 0.3741 | F14: 0.3412 | G14: 0.207 | H14: 0.2119 | I14: 0.5806 | J14: 0.1682 | K14: 0.3568 | L14: 0.3945 | M14: =AVERAGE(D14:F14) -> 0.27013333 | N14: =AVERAGE(G14:I14) -> 0.33316667 | O14: =AVERAGE(J14:L14) -> 0.3065 | P14: 0.3877 | Q14: 0.389 | R14: 0.4262 | S14: 0.5404 | T14: 0.5581 | U14: 0.6936 | V14: 1.1174 | W14: 1.1365 | X14: 1.113 | Y14: =AVERAGE(P14:R14) -> 0.40096667 | Z14: =AVERAGE(S14:U14) -> 0.59736667 | AA14: =AVERAGE(V14:X14) -> 1.1223
C15: =C14+60 -> 720 | D15: 0.0951 | E15: 0.3741 | F15: 0.3383 | G15: 0.2066 | H15: 0.2088 | I15: 0.5865 | J15: 0.1811 | K15: 0.3593 | L15: 0.4027 | M15: =AVERAGE(D15:F15) -> 0.26916667 | N15: =AVERAGE(G15:I15) -> 0.33396667 | O15: =AVERAGE(J15:L15) -> 0.31436667 | P15: 0.4068 | Q15: 0.4113 | R15: 0.4484 | S15: 0.5734 | T15: 0.5957 | U15: 0.7315 | V15: 1.1244 | W15: 1.1611 | X15: 1.1163 | Y15: =AVERAGE(P15:R15) -> 0.42216667 | Z15: =AVERAGE(S15:U15) -> 0.63353333 | AA15: =AVERAGE(V15:X15) -> 1.1339333
... C19: =C18+60 -> 960 | D19: 0.098 | E19: 0.3819 | F19: 0.3336 | G19: 0.2325 | H19: 0.2076 | I19: 0.6088 | J19: 0.2009 | K19: 0.3755 | L19: 0.4233 | M19: =AVERAGE(D19:F19) -> 0.27116667 | N19: =AVERAGE(G19:I19) -> 0.34963333 | O19: =AVERAGE(J19:L19) -> 0.33323333 | P19: 0.4986 | Q19: 0.5309 | R19: 0.5612 | S19: 0.7429 | T19: 0.7578 | U19: 0.9142 | V19: 1.1176 | W19: 1.179 | X19: 1.1528 | Y19: =AVERAGE(P19:R19) -> 0.53023333 | Z19: =AVERAGE(S19:U19) -> 0.80496667 | AA19: =AVERAGE(V19:X19) -> 1.1498
A20: 46039.496 | C20: =C19+30 -> 990 | D20: 0.2485 | E20: 0.4714 | F20: 0.3546 | G20: 0.3267 | H20: 0.2764 | I20: 0.6582 | J20: 0.2888 | K20: 0.4897 | L20: 0.5347 | M20: =AVERAGE(D20:F20) -> 0.35816667 | N20: =AVERAGE(G20:I20) -> 0.42043333 | O20: =AVERAGE(J20:L20) -> 0.43773333 | P20: 0.5204 | Q20: 0.6457 | R20: 0.6996 | S20: 0.8095 | T20: 0.8183 | U20: 0.9013 | V20: 1.1053 | W20: 1.2591 | X20: 1.2285 | Y20: =AVERAGE(P20:R20) -> 0.6219 | Z20: =AVERAGE(S20:U20) -> 0.84303333 | AA20: =AVERAGE(V20:X20) -> 1.1976333
C21: =C20+30 -> 1020 | D21: 0.1441 | E21: 0.3897 | F21: 0.3208 | G21: 0.2459 | H21: 0.2116 | I21: 0.6051 | J21: 0.2001 | K21: 0.3879 | L21: 0.4356 | M21: =AVERAGE(D21:F21) -> 0.28486667 | N21: =AVERAGE(G21:I21) -> 0.3542 | O21: =AVERAGE(J21:L21) -> 0.3412 | P21: 0.537 | Q21: 0.5606 | R21: 0.6096 | S21: 0.7481 | T21: 0.7642 | U21: 0.9244 | V21: 1.044 | W21: 1.1618 | X21: 1.1287 | Y21: =AVERAGE(P21:R21) -> 0.56906667 | Z21: =AVERAGE(S21:U21) -> 0.81223333 | AA21: =AVERAGE(V21:X21) -> 1.1115
A22: 0.5375 | C22: =C21+30 -> 1050 | D22: 0.1385 | E22: 0.3954 | F22: 0.3444 | G22: 0.2616 | H22: 0.2121 | I22: 0.6142 | J22: 0.201 | K22: 0.3921 | L22: 0.4323 | M22: =AVERAGE(D22:F22) -> 0.29276667 | N22: =AVERAGE(G22:I22) -> 0.36263333 | O22: =AVERAGE(J22:L22) -> 0.3418 | P22: 0.5586 | Q22: 0.5835 | R22: 0.6245 | S22: 0.7746 | T22: 0.8133 | U22: 0.9513 | V22: 1.0519 | W22: 1.1872 | X22: 1.1521 | Y22: =AVERAGE(P22:R22) -> 0.58886667 | Z22: =AVERAGE(S22:U22) -> 0.8464 | AA22: =AVERAGE(V22:X22) -> 1.1304
C23: =C22+30 -> 1080 | D23: 0.1459 | E23: 0.4051 | F23: 0.3697 | G23: 0.2658 | H23: 0.2144 | I23: 0.6322 | J23: 0.205 | K23: 0.3961 | L23: 0.4337 | M23: =AVERAGE(D23:F23) -> 0.3069 | N23: =AVERAGE(G23:I23) -> 0.3708 | O23: =AVERAGE(J23:L23) -> 0.34493333 | P23: 0.5913 | Q23: 0.5999 | R23: 0.6543 | S23: 0.7843 | T23: 0.8058 | U23: 0.9692 | V23: 1.0977 | W23: 1.1864 | X23: 1.1585 | Y23: =AVERAGE(P23:R23) -> 0.61516667 | Z23: =AVERAGE(S23:U23) -> 0.8531 | AA23: =AVERAGE(V23:X23) -> 1.1475333
A24: 0.57916667 | C24: =C23+30 -> 1110 | D24: 0.159 | E24: 0.4149 | F24: 0.3869 | G24: 0.2715 | H24: 0.2165 | I24: 0.6412 | J24: 0.2072 | K24: 0.4015 | L24: 0.4373 | M24: =AVERAGE(D24:F24) -> 0.32026667 | N24: =AVERAGE(G24:I24) -> 0.3764 | O24: =AVERAGE(J24:L24) -> 0.34866667 | P24: 0.6114 | Q24: 0.6169 | R24: 0.6774 | S24: 0.796 | T24: 0.8449 | U24: 0.9963 | V24: 1.113 | W24: 1.1917 | X24: 1.1636 | Y24: =AVERAGE(P24:R24) -> 0.63523333 | Z24: =AVERAGE(S24:U24) -> 0.87906667 | AA24: =AVERAGE(V24:X24) -> 1.1561
C25: =C24+30 -> 1140 | D25: 0.1547 | E25: 0.4253 | F25: 0.3913 | G25: 0.2837 | H25: 0.2198 | I25: 0.6584 | J25: 0.2094 | K25: 0.4075 | L25: 0.4389 | M25: =AVERAGE(D25:F25) -> 0.32376667 | N25: =AVERAGE(G25:I25) -> 0.3873 | O25: =AVERAGE(J25:L25) -> 0.35193333 | P25: 0.6445 | Q25: 0.6381 | R25: 0.6966 | S25: 0.8125 | T25: 0.8344 | U25: 1.0147 | V25: 1.1183 | W25: 1.1957 | X25: 1.166 | Y25: =AVERAGE(P25:R25) -> 0.65973333 | Z25: =AVERAGE(S25:U25) -> 0.8872 | AA25: =AVERAGE(V25:X25) -> 1.16
A26: 0.62083333 | C26: =C25+30 -> 1170 | D26: 0.1471 | E26: 0.4393 | F26: 0.386 | G26: 0.2919 | H26: 0.2223 | I26: 0.6601 | J26: 0.211 | K26: 0.4128 | L26: 0.4409 | M26: =AVERAGE(D26:F26) -> 0.32413333 | N26: =AVERAGE(G26:I26) -> 0.39143333 | O26: =AVERAGE(J26:L26) -> 0.3549 | P26: 0.668 | Q26: 0.6545 | R26: 0.717 | S26: 0.836 | T26: 0.8732 | U26: 1.0378 | V26: 1.1273 | W26: 1.1889 | X26: 1.1784 | Y26: =AVERAGE(P26:R26) -> 0.67983333 | Z26: =AVERAGE(S26:U26) -> 0.91566667 | AA26: =AVERAGE(V26:X26) -> 1.1648667
C27: =C26+30 -> 1200 | D27: 0.1612 | E27: 0.4441 | F27: 0.3794 | G27: 0.3046 | H27: 0.2249 | I27: 0.6595 | J27: 0.2114 | K27: 0.4195 | L27: 0.4431 | M27: =AVERAGE(D27:F27) -> 0.32823333 | N27: =AVERAGE(G27:I27) -> 0.39633333 | O27: =AVERAGE(J27:L27) -> 0.358 | P27: 0.6963 | Q27: 0.673 | R27: 0.7364 | S27: 0.8607 | T27: 0.8852 | U27: 1.044 | V27: 1.1227 | W27: 1.1841 | X27: 1.1782 | Y27: =AVERAGE(P27:R27) -> 0.7019 | Z27: =AVERAGE(S27:U27) -> 0.92996667 | AA27: =AVERAGE(V27:X27) -> 1.1616667
A28: 0.6625 | C28: =C27+30 -> 1230 | D28: 0.1534 | E28: 0.4515 | F28: 0.3752 | G28: 0.3097 | H28: 0.2296 | I28: 0.6679 | J28: 0.2124 | K28: 0.4255 | L28: 0.4446 | M28: =AVERAGE(D28:F28) -> 0.3267 | N28: =AVERAGE(G28:I28) -> 0.4024 | O28: =AVERAGE(J28:L28) -> 0.36083333 | P28: 0.7256 | Q28: 0.6912 | R28: 0.7593 | S28: 0.8824 | T28: 0.9002 | U28: 1.0679 | V28: 1.1247 | W28: 1.1925 | X28: 1.1775 | Y28: =AVERAGE(P28:R28) -> 0.72536667 | Z28: =AVERAGE(S28:U28) -> 0.95016667 | AA28: =AVERAGE(V28:X28) -> 1.1649
A29: 46039.686 | C29: =C28+30 -> 1260 | D29: 0.2467 | E29: 0.5346 | F29: 0.4118 | G29: 0.3977 | H29: 0.3015 | I29: 0.6936 | J29: 0.2741 | K29: 0.5226 | L29: 0.5231 | M29: =AVERAGE(D29:F29) -> 0.3977 | N29: =AVERAGE(G29:I29) -> 0.46426667 | O29: =AVERAGE(J29:L29) -> 0.43993333 | P29: 0.766 | Q29: 0.832 | R29: 0.9016 | S29: 0.995 | T29: 1.0041 | U29: 1.0772 | V29: 1.1738 | W29: 1.2672 | X29: 1.2373 | Y29: =AVERAGE(P29:R29) -> 0.8332 | Z29: =AVERAGE(S29:U29) -> 1.0254333 | AA29: =AVERAGE(V29:X29) -> 1.2261
C30: =C29+30 -> 1290 | D30: 0.139 | E30: 0.436 | F30: 0.386 | G30: 0.3271 | H30: 0.2405 | I30: 0.6551 | J30: 0.2201 | K30: 0.4298 | L30: 0.4493 | M30: =AVERAGE(D30:F30) -> 0.32033333 | N30: =AVERAGE(G30:I30) -> 0.40756667 | O30: =AVERAGE(J30:L30) -> 0.3664 | P30: 0.7807 | Q30: 0.7384 | R30: 0.8008 | S30: 0.9352 | T30: 0.9398 | U30: 1.0941 | V30: 1.1202 | W30: 1.1803 | X30: 1.1668 | Y30: =AVERAGE(P30:R30) -> 0.7733 | Z30: =AVERAGE(S30:U30) -> 0.9897 | AA30: =AVERAGE(V30:X30) -> 1.1557667
A31: 46039.727 | C31: =C28+90 -> 1320 | D31: 0.1792 | E31: 0.4622 | F31: 0.4089 | G31: 0.3547 | H31: 0.2501 | I31: 0.6799 | J31: 0.227 | K31: 0.4375 | L31: 0.4764 | M31: =AVERAGE(D31:F31) -> 0.3501 | N31: =AVERAGE(G31:I31) -> 0.42823333 | O31: =AVERAGE(J31:L31) -> 0.3803 | P31: 0.8189 | Q31: 0.8005 | R31: 0.8711 | S31: 0.969 | T31: 0.9705 | U31: 1.0981 | V31: 1.1613 | W31: 1.2244 | X31: 1.1834 | Y31: =AVERAGE(P31:R31) -> 0.83016667 | Z31: =AVERAGE(S31:U31) -> 1.0125333 | AA31: =AVERAGE(V31:X31) -> 1.1897
A32: 46039.741 | C32: =C31+20 -> 1340 | D32: 0.2707 | E32: 0.5536 | F32: 0.4877 | G32: 0.4335 | H32: 0.3457 | I32: 0.6969 | J32: 0.2804 | K32: 0.5082 | L32: 0.5749 | M32: =AVERAGE(D32:F32) -> 0.43733333 | N32: =AVERAGE(G32:I32) -> 0.49203333 | O32: =AVERAGE(J32:L32) -> 0.4545 | P32: 0.8392 | Q32: 0.9183 | R32: 0.9967 | S32: 1.0605 | T32: 1.0478 | U32: 1.1103 | V32: 1.1405 | W32: 1.2786 | X32: 1.2531 | Y32: =AVERAGE(P32:R32) -> 0.91806667 | Z32: =AVERAGE(S32:U32) -> 1.0728667 | AA32: =AVERAGE(V32:X32) -> 1.2240667
A33: 46039.76 | C33: =C32+30 -> 1370 | D33: 0.1562 | E33: 0.4407 | F33: 0.4104 | G33: 0.3527 | H33: 0.2871 | I33: 0.686 | J33: 0.242 | K33: 0.4463 | L33: 0.481 | M33: =AVERAGE(D33:F33) -> 0.33576667 | N33: =AVERAGE(G33:I33) -> 0.44193333 | O33: =AVERAGE(J33:L33) -> 0.38976667 | P33: 0.879 | Q33: 0.8121 | R33: 0.8989 | S33: 0.9872 | T33: 0.9714 | U33: 1.1099 | V33: 1.1632 | W33: 1.2143 | X33: 1.2047 | Y33: =AVERAGE(P33:R33) -> 0.86333333 | Z33: =AVERAGE(S33:U33) -> 1.0228333 | AA33: =AVERAGE(V33:X33) -> 1.1940667
A34: 46039.77 | C34: =C31+60 -> 1380 | D34: 0.2151 | E34: 0.4491 | F34: 0.4206 | G34: 0.3732 | H34: 0.2986 | I34: 0.6761 | J34: 0.2415 | K34: 0.4519 | L34: 0.5014 | M34: =AVERAGE(D34:F34) -> 0.3616 | N34: =AVERAGE(G34:I34) -> 0.4493 | O34: =AVERAGE(J34:L34) -> 0.39826667 | P34: 0.8998 | Q34: 0.8731 | R34: 0.9514 | S34: 1.0417 | T34: 1.0381 | U34: 1.1324 | V34: 1.1293 | W34: 1.1952 | X34: 1.1709 | Y34: =AVERAGE(P34:R34) -> 0.9081 | Z34: =AVERAGE(S34:U34) -> 1.0707333 | AA34: =AVERAGE(V34:X34) -> 1.1651333
C35: =C34+30 -> 1410 | D35: 0.1283 | E35: 0.4311 | F35: 0.3999 | G35: 0.329 | H35: 0.272 | I35: 0.6702 | J35: 0.2379 | K35: 0.4381 | L35: 0.4595 | M35: =AVERAGE(D35:F35) -> 0.31976667 | N35: =AVERAGE(G35:I35) -> 0.42373333 | O35: =AVERAGE(J35:L35) -> 0.3785 | P35: 0.8962 | Q35: 0.8241 | R35: 0.8901 | S35: 1.035 | T35: 1.0253 | U35: 1.1637 | V35: 1.1376 | W35: 1.1805 | X35: 1.1502 | Y35: =AVERAGE(P35:R35) -> 0.87013333 | Z35: =AVERAGE(S35:U35) -> 1.0746667 | AA35: =AVERAGE(V35:X35) -> 1.1561
C36: =C35+30 -> 1440 | D36: 0.1451 | E36: 0.4478 | F36: 0.4133 | G36: 0.334 | H36: 0.2818 | I36: 0.6719 | J36: 0.2388 | K36: 0.4455 | L36: 0.4647 | M36: =AVERAGE(D36:F36) -> 0.3354 | N36: =AVERAGE(G36:I36) -> 0.42923333 | O36: =AVERAGE(J36:L36) -> 0.383 | P36: 0.9316 | Q36: 0.8412 | R36: 0.9099 | S36: 1.0589 | T36: 1.0528 | U36: 1.1771 | V36: 1.1508 | W36: 1.2005 | X36: 1.1739 | Y36: =AVERAGE(P36:R36) -> 0.89423333 | Z36: =AVERAGE(S36:U36) -> 1.0962667 | AA36: =AVERAGE(V36:X36) -> 1.1750667
C37: =C36+30 -> 1470 | D37: 0.1567 | E37: 0.4556 | F37: 0.4217 | G37: 0.3291 | H37: 0.2922 | I37: 0.6875 | J37: 0.2373 | K37: 0.4519 | L37: 0.4694 | M37: =AVERAGE(D37:F37) -> 0.34466667 | N37: =AVERAGE(G37:I37) -> 0.43626667 | O37: =AVERAGE(J37:L37) -> 0.3862 | P37: 0.9778 | Q37: 0.8616 | R37: 0.9319 | S37: 1.0762 | T37: 1.0533 | U37: 1.1906 | V37: 1.1505 | W37: 1.1893 | X37: 1.1828 | Y37: =AVERAGE(P37:R37) -> 0.92376667 | Z37: =AVERAGE(S37:U37) -> 1.1067 | AA37: =AVERAGE(V37:X37) -> 1.1742
C38: =C37+30 -> 1500 | D38: 0.1371 | E38: 0.4601 | F38: 0.4033 | G38: 0.3365 | H38: 0.2972 | I38: 0.6942 | J38: 0.236 | K38: 0.4531 | L38: 0.4686 | M38: =AVERAGE(D38:F38) -> 0.3335 | N38: =AVERAGE(G38:I38) -> 0.44263333 | O38: =AVERAGE(J38:L38) -> 0.3859 | P38: 1.0165 | Q38: 0.8794 | R38: 0.9519 | S38: 1.1063 | T38: 1.0623 | U38: 1.207 | V38: 1.1376 | W38: 1.1779 | X38: 1.1838 | Y38: =AVERAGE(P38:R38) -> 0.94926667 | Z38: =AVERAGE(S38:U38) -> 1.1252 | AA38: =AVERAGE(V38:X38) -> 1.1664333
C39: =C38+30 -> 1530 | D39: 0.1473 | E39: 0.4676 | F39: 0.3993 | G39: 0.3416 | H39: 0.3066 | I39: 0.7072 | J39: 0.2358 | K39: 0.4564 | L39: 0.4681 | M39: =AVERAGE(D39:F39) -> 0.33806667 | N39: =AVERAGE(G39:I39) -> 0.4518 | O39: =AVERAGE(J39:L39) -> 0.38676667 | P39: 1.0453 | Q39: 0.8968 | R39: 0.973 | S39: 1.1359 | T39: 1.0762 | U39: 1.2198 | V39: 1.1384 | W39: 1.1834 | X39: 1.1871 | Y39: =AVERAGE(P39:R39) -> 0.9717 | Z39: =AVERAGE(S39:U39) -> 1.1439667 | AA39: =AVERAGE(V39:X39) -> 1.1696333
C40: =C39+30 -> 1560 | D40: 0.1328 | E40: 0.4739 | F40: 0.4281 | G40: 0.3463 | H40: 0.3189 | I40: 0.7046 | J40: 0.2356 | K40: 0.4582 | L40: 0.4688 | M40: =AVERAGE(D40:F40) -> 0.34493333 | N40: =AVERAGE(G40:I40) -> 0.4566 | O40: =AVERAGE(J40:L40) -> 0.38753333 | P40: 1.0857 | Q40: 0.9175 | R40: 0.9913 | S40: 1.172 | T40: 1.1051 | U40: 1.2281 | V40: 1.1373 | W40: 1.1837 | X40: 1.1845 | Y40: =AVERAGE(P40:R40) -> 0.99816667 | Z40: =AVERAGE(S40:U40) -> 1.1684 | AA40: =AVERAGE(V40:X40) -> 1.1685
C41: =C40+30 -> 1590 | D41: 0.1342 | E41: 0.4753 | F41: 0.4313 | G41: 0.3496 | H41: 0.337 | I41: 0.7036 | J41: 0.2348 | K41: 0.458 | L41: 0.4705 | M41: =AVERAGE(D41:F41) -> 0.34693333 | N41: =AVERAGE(G41:I41) -> 0.4634 | O41: =AVERAGE(J41:L41) -> 0.38776667 | P41: 1.1179 | Q41: 0.9378 | R41: 1.0076 | S41: 1.2059 | T41: 1.1271 | U41: 1.2459 | V41: 1.1341 | W41: 1.1831 | X41: 1.1803 | Y41: =AVERAGE(P41:R41) -> 1.0211 | Z41: =AVERAGE(S41:U41) -> 1.1929667 | AA41: =AVERAGE(V41:X41) -> 1.1658333
C42: =C41+30 -> 1620 | D42: 0.1648 | E42: 0.4761 | F42: 0.4324 | G42: 0.3533 | H42: 0.3468 | I42: 0.708 | J42: 0.2336 | K42: 0.4574 | L42: 0.4732 | M42: =AVERAGE(D42:F42) -> 0.35776667 | N42: =AVERAGE(G42:I42) -> 0.46936667 | O42: =AVERAGE(J42:L42) -> 0.38806667 | P42: 1.1549 | Q42: 0.9575 | R42: 1.0289 | S42: 1.2311 | T42: 1.1409 | U42: 1.2621 | V42: 1.1401 | W42: 1.1733 | X42: 1.1848 | Y42: =AVERAGE(P42:R42) -> 1.0471 | Z42: =AVERAGE(S42:U42) -> 1.2113667 | AA42: =AVERAGE(V42:X42) -> 1.1660667
C43: =C42+30 -> 1650 | D43: 0.1438 | E43: 0.4768 | F43: 0.4348 | G43: 0.3553 | H43: 0.349 | I43: 0.7042 | J43: 0.2335 | K43: 0.4565 | L43: 0.4763 | M43: =AVERAGE(D43:F43) -> 0.3518 | N43: =AVERAGE(G43:I43) -> 0.4695 | O43: =AVERAGE(J43:L43) -> 0.38876667 | P43: 1.1773 | Q43: 0.9782 | R43: 1.0476 | S43: 1.2549 | T43: 1.168 | U43: 1.2856 | V43: 1.1329 | W43: 1.1694 | X43: 1.1655 | Y43: =AVERAGE(P43:R43) -> 1.0677 | Z43: =AVERAGE(S43:U43) -> 1.2361667 | AA43: =AVERAGE(V43:X43) -> 1.1559333
...

Sheet r1
A1: Sample | B1: Time | C1: OD600 | D1: Group | E1: Substrate
A2: pd.1_CN | B2: 0 | C2: 0.3373 | D2: pd_CN | E2: Inorganic
A3: pd.1_CN | B3: 30 | C3: 0.3492 | D3: pd_CN | E3: Inorganic
A4: pd.1_CN | B4: 60 | C4: 0.3613 | D4: pd_CN | E4: Inorganic
A5: pd.1_CN | B5: 70 | C5: 0.3672 | D5: pd_CN | E5: Inorganic
A6: pd.1_CN | B6: 100 | C6: 0.3808 | D6: pd_CN | E6: Inorganic
A7: pd.1_CN | B7: 130 | C7: 0.3918 | D7: pd_CN | E7: Inorganic
A8: pd.1_CN | B8: 160 | C8: 0.4066 | D8: pd_CN | E8: Inorganic
A9: pd.1_CN | B9: 190 | C9: 0.4157 | D9: pd_CN | E9: Inorganic
A10: pd.1_CN | B10: 200 | C10: 0.424 | D10: pd_CN | E10: Inorganic
A11: pd.1_CN | B11: 230 | C11: 0.4352 | D11: pd_CN | E11: Inorganic
A12: pd.1_CN | B12: 240 | C12: 0.4458 | D12: pd_CN | E12: Inorganic
A13: pd.1_CN | B13: 240 | C13: 0.4515 | D13: pd_CN | E13: Inorganic
... A493: so.3_TSB | B493: 1110 | C493: 0.8435 | D493: so_TSB | E493: Organic

Sheet Round1.raw
A1: Data-Time | B1: Time | D1: CN | J1: TSB
A2: Data-Time | B2: Time 1 | C2: Time 2 | D2: pd.1_CN | E2: pd.2_CN | F2: pd.3_CN | G2: so.1_CN | H2: so.2_CN | I2: so.3_CN | J2: pd.1_TSB | K2: pd.2_TSB | L2: pd.3_TSB | M2: so.1_TSB | N2: so.2_TSB | O2: so.3_TSB
A3: 46036.551 | C3: 0 | D3: 0.3373 | E3: 0.3444 | F3: 0.3712 | G3: 0.36 | H3: 0.3722 | I3: 0.2439 | J3: 1.0121 | K3: 0.9992 | L3: 1.0079 | M3: 0.6834 | N3: 0.5812 | O3: 0.704
C4: 30 | D4: 0.3492 | E4: 0.3611 | F4: 0.3877 | G4: 0.3614 | H4: 0.3657 | I4: 0.2667 | J4: 1.0181 | K4: 0.9922 | L4: 0.998 | M4: 0.6961 | N4: 0.617 | O4: 0.7147
C5: 60 | D5: 0.3613 | E5: 0.366 | F5: 0.3989 | G5: 0.3505 | H5: 0.3555 | I5: 0.2743 | J5: 1.0372 | K5: 1.0118 | L5: 1.0103 | M5: 0.672 | N5: 0.6108 | O5: 0.6962
A7: 46036.602 | C7: =C5+10 -> 70 | D7: 0.3672 | E7: 0.3962 | F7: 0.4414 | G7: 0.376 | H7: 0.3908 | I7: 0.2959 | J7: 1.0408 | K7: 1.0451 | L7: 1.0442 | M7: 0.7101 | N7: 0.6601 | O7: 0.7153
C8: =C7+30 -> 100 | D8: 0.3808 | E8: 0.3798 | F8: 0.4165 | G8: 0.3544 | H8: 0.3647 | I8: 0.2839 | J8: 1.0576 | K8: 1.0315 | L8: 1.0264 | M8: 0.6756 | N8: 0.6307 | O8: 0.7078
C9: =C8+30 -> 130 | D9: 0.3918 | E9: 0.3882 | F9: 0.4323 | G9: 0.3463 | H9: 0.3594 | I9: 0.2871 | J9: 1.0714 | K9: 1.046 | L9: 1.0393 | M9: 0.677 | N9: 0.6346 | O9: 0.6919
C10: =C9+30 -> 160 | D10: 0.4066 | E10: 0.396 | F10: 0.447 | G10: 0.3511 | H10: 0.363 | I10: 0.295 | J10: 1.0871 | K10: 1.0613 | L10: 1.0518 | M10: 0.6807 | N10: 0.6419 | O10: 0.6908
C11: =C10+30 -> 190 | D11: 0.4157 | E11: 0.4032 | F11: 0.4651 | G11: 0.3582 | H11: 0.3699 | I11: 0.2953 | J11: 1.1044 | K11: 1.0735 | L11: 1.067 | M11: 0.6834 | N11: 0.6522 | O11: 0.7016
A13: 46036.699 | C13: =C11+10 -> 200 | D13: 0.424 | E13: 0.4184 | F13: 0.4832 | G13: 0.3484 | H13: 0.3598 | I13: 0.2802 | J13: 1.1139 | K13: 1.0772 | L13: 1.0784 | M13: 0.6904 | N13: 0.6514 | O13: 0.6893
C14: =C13+30 -> 230 | D14: 0.4352 | E14: 0.4236 | F14: 0.4906 | G14: 0.3673 | H14: 0.3746 | I14: 0.2926 | J14: 1.1243 | K14: 1.1011 | L14: 1.0912 | M14: 0.7057 | N14: 0.6723 | O14: 0.7178
A16: 46036.731 | C16: 240 | D16: 0.4458 | E16: 0.4539 | F16: 0.5346 | G16: 0.3802 | H16: 0.3829 | I16: 0.2898 | J16: 1.1398 | K16: 1.1321 | L16: 1.1006 | M16: 0.7368 | N16: 0.6767 | O16: 0.6921
C17: 240 | D17: 0.4515 | E17: 0.4402 | F17: 0.5146 | G17: 0.3689 | H17: 0.3748 | I17: 0.2904 | J17: 1.1479 | K17: 1.1224 | L17: 1.1198 | M17: 0.7162 | N17: 0.685 | O17: 0.7176
A19: 46036.771 | C19: =C17+30 -> 270 | D19: 0.4703 | E19: 0.4685 | F19: 0.5594 | G19: 0.3774 | H19: 0.3802 | I19: 0.2926 | J19: 1.1675 | K19: 1.1564 | L19: 1.1298 | M19: 0.7439 | N19: 0.6893 | O19: 0.7096
C20: =C19+30 -> 300 | D20: 0.4692 | E20: 0.4581 | F20: 0.5425 | G20: 0.3806 | H20: 0.3799 | I20: 0.3022 | J20: 1.1717 | K20: 1.1447 | L20: 1.1426 | M20: 0.7271 | N20: 0.6964 | O20: 0.7103
C21: =C20+30 -> 330 | D21: 0.4786 | E21: 0.4636 | F21: 0.5538 | G21: 0.3801 | H21: 0.3781 | I21: 0.3075 | J21: 1.1726 | K21: 1.1573 | L21: 1.1579 | M21: 0.7363 | N21: 0.7066 | O21: 0.7163
C22: =C21+30 -> 360 | D22: 0.4865 | E22: 0.4701 | F22: 0.5653 | G22: 0.3833 | H22: 0.3792 | I22: 0.3061 | J22: 1.1859 | K22: 1.1648 | L22: 1.1712 | M22: 0.7429 | N22: 0.7063 | O22: 0.7203
A24: 46036.842 | C24: =C22+30 -> 390 | D24: 0.4999 | E24: 0.4829 | F24: 0.5877 | G24: 0.3882 | H24: 0.3808 | I24: 0.3136 | J24: 1.1946 | K24: 1.1813 | L24: 1.1724 | M24: 0.7668 | N24: 0.7064 | O24: 0.7083
A26: 46036.851 | C26: =C24+30 -> 420 | D26: 0.5035 | E26: 0.4962 | F26: 0.591 | G26: 0.3832 | H26: 0.3751 | I26: 0.2965 | J26: 1.1959 | K26: 1.1839 | L26: 1.1769 | M26: 0.7608 | N26: 0.6933 | O26: 0.7054
C27: =C26+30 -> 450 | D27: 0.5077 | E27: 0.5009 | F27: 0.5899 | G27: 0.3884 | H27: 0.3796 | I27: 0.3132 | J27: 1.1972 | K27: 1.1798 | L27: 1.1867 | M27: 0.7594 | N27: 0.7241 | O27: 0.7259
C28: =C27+30 -> 480 | D28: 0.5162 | E28: 0.5129 | F28: 0.5996 | G28: 0.3891 | H28: 0.3808 | I28: 0.3225 | J28: 1.2024 | K28: 1.189 | L28: 1.2026 | M28: 0.7583 | N28: 0.7288 | O28: 0.7251
A30: 46036.901 | C30: =C28+30 -> 510 | D30: 0.5288 | E30: 0.5399 | F30: 0.6363 | G30: 0.3984 | H30: 0.3821 | I30: 0.323 | J30: 1.214 | K30: 1.2197 | L30: 1.2114 | M30: 0.7955 | N30: 0.7231 | O30: 0.724
C31: =C30+30 -> 540 | D31: 0.53 | E31: 0.5261 | F31: 0.6174 | G31: 0.3871 | H31: 0.3721 | I31: 0.3206 | J31: 1.2134 | K31: 1.1931 | L31: 1.2132 | M31: 0.761 | N31: 0.7198 | O31: 0.7291
C32: =C31+30 -> 570 | D32: 0.5327 | E32: 0.5465 | F32: 0.6285 | G32: 0.3799 | H32: 0.3653 | I32: 0.3294 | J32: 1.2167 | K32: 1.2004 | L32: 1.215 | M32: 0.7713 | N32: 0.7356 | O32: 0.7222
C33: =C32+30 -> 600 | D33: 0.5448 | E33: 0.5636 | F33: 0.6364 | G33: 0.3742 | H33: 0.3613 | I33: 0.3319 | J33: 1.2204 | K33: 1.2077 | L33: 1.2212 | M33: 0.7709 | N33: 0.7414 | O33: 0.7333
C34: =C33+30 -> 630 | D34: 0.556 | E34: 0.5774 | F34: 0.6446 | G34: 0.37 | H34: 0.3602 | I34: 0.3396 | J34: 1.2276 | K34: 1.2095 | L34: 1.2351 | M34: 0.7724 | N34: 0.7462 | O34: 0.7356
C35: =C34+30 -> 660 | D35: 0.5732 | E35: 0.5909 | F35: 0.6463 | G35: 0.3648 | H35: 0.3586 | I35: 0.345 | J35: 1.2329 | K35: 1.2148 | L35: 1.2402 | M35: 0.775 | N35: 0.7451 | O35: 0.7307
C36: =C35+30 -> 690 | D36: 0.5957 | E36: 0.6041 | F36: 0.6581 | G36: 0.3561 | H36: 0.3537 | I36: 0.3472 | J36: 1.2438 | K36: 1.2191 | L36: 1.2505 | M36: 0.7736 | N36: 0.7528 | O36: 0.719
C37: =C36+30 -> 720 | D37: 0.6163 | E37: 0.6139 | F37: 0.666 | G37: 0.3446 | H37: 0.3496 | I37: 0.3453 | J37: 1.251 | K37: 1.2294 | L37: 1.2555 | M37: 0.7781 | N37: 0.7494 | O37: 0.7188
C38: =C37+30 -> 750 | D38: 0.63 | E38: 0.621 | F38: 0.6702 | G38: 0.3326 | H38: 0.3458 | I38: 0.3474 | J38: 1.2592 | K38: 1.2379 | L38: 1.269 | M38: 0.7828 | N38: 0.75 | O38: 0.7171
C39: =C38+30 -> 780 | D39: 0.6515 | E39: 0.6288 | F39: 0.677 | G39: 0.3238 | H39: 0.3423 | I39: 0.3488 | J39: 1.263 | K39: 1.2481 | L39: 1.2791 | M39: 0.7837 | N39: 0.7544 | O39: 0.7097
C40: =C39+30 -> 810 | D40: 0.6682 | E40: 0.6391 | F40: 0.6842 | G40: 0.3141 | H40: 0.3362 | I40: 0.3507 | J40: 1.2692 | K40: 1.2578 | L40: 1.2827 | M40: 0.7891 | N40: 0.7616 | O40: 0.7199
C41: =C40+30 -> 840 | D41: 0.6775 | E41: 0.6536 | F41: 0.692 | G41: 0.3042 | H41: 0.3289 | I41: 0.3488 | J41: 1.2825 | K41: 1.2685 | L41: 1.2957 | M41: 0.7989 | N41: 0.7637 | O41: 0.7012
C42: =C41+30 -> 870 | D42: 0.6859 | E42: 0.6692 | F42: 0.6991 | G42: 0.2977 | H42: 0.3259 | I42: 0.3496 | J42: 1.2891 | K42: 1.2789 | L42: 1.3028 | M42: 0.8229 | N42: 0.7637 | O42: 0.6922
... C50: =C49+30 -> 1110 | D50: 0.7533 | E50: 0.7596 | F50: 0.777 | G50: 0.2755 | H50: 0.3056 | I50: 0.3429 | J50: 1.3781 | K50: 1.3701 | L50: 1.3877 | M50: 0.9883 | N50: 0.8358 | O50: 0.8435
