Workbook

Sheet r1
A1: Sample | B1: Time | C1: OD600 | D1: Group | E1: Substrate
A2: pd.1_Dark | B2: ='r1.raw.P'!B3 -> 0 | C2: ='r1.raw.P'!C3 -> 0.1255 | D2: pd_Dark | E2: Dark
A3: pd.1_Dark | B3: ='r1.raw.P'!B4 -> 30 | C3: ='r1.raw.P'!C4 -> 0.1248 | D3: pd_Dark | E3: Dark
A4: pd.1_Dark | B4: ='r1.raw.P'!B5 -> 60 | C4: ='r1.raw.P'!C5 -> 0.1248 | D4: pd_Dark | E4: Dark
A5: pd.1_Dark | B5: ='r1.raw.P'!B6 -> 90 | C5: ='r1.raw.P'!C6 -> 0.1247 | D5: pd_Dark | E5: Dark
A6: pd.1_Dark | B6: ='r1.raw.P'!B7 -> 120 | C6: ='r1.raw.P'!C7 -> 0.1237 | D6: pd_Dark | E6: Dark
A7: pd.1_Dark | B7: ='r1.raw.P'!B8 -> 150 | C7: ='r1.raw.P'!C8 -> 0.1232 | D7: pd_Dark | E7: Dark
A8: pd.1_Dark | B8: ='r1.raw.P'!B9 -> 180 | C8: ='r1.raw.P'!C9 -> 0.1215 | D8: pd_Dark | E8: Dark
A9: pd.1_Dark | B9: ='r1.raw.P'!B10 -> 210 | C9: ='r1.raw.P'!C10 -> 0.1212 | D9: pd_Dark | E9: Dark
A10: pd.1_Dark | B10: ='r1.raw.P'!B11 -> 240 | C10: ='r1.raw.P'!C11 -> 0.1204 | D10: pd_Dark | E10: Dark
A11: pd.1_Dark | B11: ='r1.raw.P'!B12 -> 270 | C11: ='r1.raw.P'!C12 -> 0.1201 | D11: pd_Dark | E11: Dark
A12: pd.1_Dark | B12: ='r1.raw.P'!B13 -> 300 | C12: ='r1.raw.P'!C13 -> 0.1195 | D12: pd_Dark | E12: Dark
A13: pd.1_Dark | B13: ='r1.raw.P'!B14 -> 330 | C13: ='r1.raw.P'!C14 -> 0.1189 | D13: pd_Dark | E13: Dark
... A50: pd.1_Dark | B50: ='r1.raw.P'!B51 -> 1430 | C50: ='r1.raw.P'!C51 -> 0.1113 | D50: pd_Dark | E50: Dark
A51: pd.2_Dark | B51: ='r1.raw.P'!B3 -> 0 | C51: ='r1.raw.P'!D3 -> 0.1264 | D51: pd_Dark | E51: Dark
A52: pd.2_Dark | B52: ='r1.raw.P'!B4 -> 30 | C52: ='r1.raw.P'!D4 -> 0.1289 | D52: pd_Dark | E52: Dark
A53: pd.2_Dark | B53: ='r1.raw.P'!B5 -> 60 | C53: ='r1.raw.P'!D5 -> 0.1252 | D53: pd_Dark | E53: Dark
A54: pd.2_Dark | B54: ='r1.raw.P'!B6 -> 90 | C54: ='r1.raw.P'!D6 -> 0.1249 | D54: pd_Dark | E54: Dark
A55: pd.2_Dark | B55: ='r1.raw.P'!B7 -> 120 | C55: ='r1.raw.P'!D7 -> 0.124 | D55: pd_Dark | E55: Dark
A56: pd.2_Dark | B56: ='r1.raw.P'!B8 -> 150 | C56: ='r1.raw.P'!D8 -> 0.1235 | D56: pd_Dark | E56: Dark
A57: pd.2_Dark | B57: ='r1.raw.P'!B9 -> 180 | C57: ='r1.raw.P'!D9 -> 0.1227 | D57: pd_Dark | E57: Dark
A58: pd.2_Dark | B58: ='r1.raw.P'!B10 -> 210 | C58: ='r1.raw.P'!D10 -> 0.1213 | D58: pd_Dark | E58: Dark
A59: pd.2_Dark | B59: ='r1.raw.P'!B11 -> 240 | C59: ='r1.raw.P'!D11 -> 0.1209 | D59: pd_Dark | E59: Dark
A60: pd.2_Dark | B60: ='r1.raw.P'!B12 -> 270 | C60: ='r1.raw.P'!D12 -> 0.1209 | D60: pd_Dark | E60: Dark
A61: pd.2_Dark | B61: ='r1.raw.P'!B13 -> 300 | C61: ='r1.raw.P'!D13 -> 0.1205 | D61: pd_Dark | E61: Dark
A62: pd.2_Dark | B62: ='r1.raw.P'!B14 -> 330 | C62: ='r1.raw.P'!D14 -> 0.1194 | D62: pd_Dark | E62: Dark
... A99: pd.2_Dark | B99: ='r1.raw.P'!B51 -> 1430 | C99: ='r1.raw.P'!D51 -> 0.1087 | D99: pd_Dark | E99: Dark
A100: pd.3_Dark | B100: ='r1.raw.P'!B3 -> 0 | C100: ='r1.raw.P'!E3 -> 0.124 | D100: pd_Dark | E100: Dark
A101: pd.3_Dark | B101: ='r1.raw.P'!B4 -> 30 | C101: ='r1.raw.P'!E4 -> 0.1258 | D101: pd_Dark | E101: Dark
A102: pd.3_Dark | B102: ='r1.raw.P'!B5 -> 60 | C102: ='r1.raw.P'!E5 -> 0.1259 | D102: pd_Dark | E102: Dark
A103: pd.3_Dark | B103: ='r1.raw.P'!B6 -> 90 | C103: ='r1.raw.P'!E6 -> 0.1244 | D103: pd_Dark | E103: Dark
A104: pd.3_Dark | B104: ='r1.raw.P'!B7 -> 120 | C104: ='r1.raw.P'!E7 -> 0.1229 | D104: pd_Dark | E104: Dark
A105: pd.3_Dark | B105: ='r1.raw.P'!B8 -> 150 | C105: ='r1.raw.P'!E8 -> 0.122 | D105: pd_Dark | E105: Dark
A106: pd.3_Dark | B106: ='r1.raw.P'!B9 -> 180 | C106: ='r1.raw.P'!E9 -> 0.1215 | D106: pd_Dark | E106: Dark
A107: pd.3_Dark | B107: ='r1.raw.P'!B10 -> 210 | C107: ='r1.raw.P'!E10 -> 0.1206 | D107: pd_Dark | E107: Dark
A108: pd.3_Dark | B108: ='r1.raw.P'!B11 -> 240 | C108: ='r1.raw.P'!E11 -> 0.1202 | D108: pd_Dark | E108: Dark
A109: pd.3_Dark | B109: ='r1.raw.P'!B12 -> 270 | C109: ='r1.raw.P'!E12 -> 0.1195 | D109: pd_Dark | E109: Dark
A110: pd.3_Dark | B110: ='r1.raw.P'!B13 -> 300 | C110: ='r1.raw.P'!E13 -> 0.1191 | D110: pd_Dark | E110: Dark
A111: pd.3_Dark | B111: ='r1.raw.P'!B14 -> 330 | C111: ='r1.raw.P'!E14 -> 0.1185 | D111: pd_Dark | E111: Dark
... A148: pd.3_Dark | B148: ='r1.raw.P'!B51 -> 1430 | C148: ='r1.raw.P'!E51 -> 0.1071 | D148: pd_Dark | E148: Dark
...

Sheet r1.raw.P
A1: Data-Time | B1: Time | C1: Dark | L1: IR | V1: RAW
A2: Data-Time | B2: Time 1 | C2: Dark-P-C1 | D2: Dark-P-C2 | E2: Dark-P-C3 | F2: Dark-P-Ac1 | G2: Dark-P-Ac2 | H2: Dark-P-Ac3 | I2: Dark-P-S1 | J2: Dark-P-S2 | K2: Dark-P-S3 | L2: IR-P-C1 | M2: IR-P-C2 | N2: IR-P-C3 | O2: IR-P-Ac1 | P2: IR-P-Ac2 | Q2: IR-P-Ac3 | R2: IR-P-S1 | S2: IR-P-S2 | T2: IR-P-S3 | U2: Tips | V2: C-D | Y2: C-I | AB2: Ac-D | AE2: Ac-I | AH2: S-D | AK2: S-I
A3: 46074.929 | B3: 0 | C3: 0.1255 | D3: 0.1264 | E3: 0.124 | F3: 0.1996 | G3: 0.1338 | H3: 0.14 | I3: 0.1712 | J3: 0.1247 | K3: 0.1271 | L3: 0.1525 | M3: 0.1378 | N3: 0.1595 | O3: 0.1273 | P3: 0.1376 | Q3: 0.1222 | R3: 0.1274 | S3: 0.1308 | T3: 0.1251 | V3: 0.1255 | W3: 0.1264 | X3: 0.124 | Y3: 0.1525 | Z3: 0.1378 | AA3: 0.1595 | AB3: 0.1996 | AC3: 0.1338 | AD3: 0.14 | AE3: 0.1273 | AF3: 0.1376 | AG3: 0.1222 | AH3: 0.1712 | AI3: 0.1247 | AJ3: 0.1271 | AK3: 0.1274 | AL3: 0.1308 | AM3: 0.1251
B4: 30 | C4: 0.1248 | D4: 0.1289 | E4: 0.1258 | F4: 0.1763 | G4: 0.1336 | H4: 0.1437 | I4: 0.1653 | J4: 0.1227 | K4: 0.1289 | L4: 0.1451 | M4: 0.1408 | N4: 0.1634 | O4: 0.1265 | P4: 0.1307 | Q4: 0.1255 | R4: 0.1281 | S4: 0.1285 | T4: 0.1341 | V4: 0.1248 | W4: 0.1289 | X4: 0.1258 | Y4: 0.1451 | Z4: 0.1408 | AA4: 0.1634 | AB4: 0.1763 | AC4: 0.1336 | AD4: 0.1437 | AE4: 0.1265 | AF4: 0.1307 | AG4: 0.1255 | AH4: 0.1653 | AI4: 0.1227 | AJ4: 0.1289 | AK4: 0.1281 | AL4: 0.1285 | AM4: 0.1341
B5: =B4+30 -> 60 | C5: 0.1248 | D5: 0.1252 | E5: 0.1259 | F5: 0.1477 | G5: 0.1313 | H5: 0.1371 | I5: 0.1451 | J5: 0.1234 | K5: 0.1275 | L5: 0.1466 | M5: 0.1384 | N5: 0.1591 | O5: 0.1242 | P5: 0.1314 | Q5: 0.128 | R5: 0.1265 | S5: 0.1262 | T5: 0.1312 | V5: 0.1248 | W5: 0.1252 | X5: 0.1259 | Y5: 0.1466 | Z5: 0.1384 | AA5: 0.1591 | AB5: 0.1477 | AC5: 0.1313 | AD5: 0.1371 | AE5: 0.1242 | AF5: 0.1314 | AG5: 0.128 | AH5: 0.1451 | AI5: 0.1234 | AJ5: 0.1275 | AK5: 0.1265 | AL5: 0.1262 | AM5: 0.1312
B6: =B5+30 -> 90 | C6: 0.1247 | D6: 0.1249 | E6: 0.1244 | F6: 0.1402 | G6: 0.131 | H6: 0.1364 | I6: 0.1517 | J6: 0.1219 | K6: 0.1251 | L6: 0.1429 | M6: 0.1383 | N6: 0.1546 | O6: 0.1243 | P6: 0.1282 | Q6: 0.1251 | R6: 0.1263 | S6: 0.1258 | T6: 0.128 | V6: 0.1247 | W6: 0.1249 | X6: 0.1244 | Y6: 0.1429 | Z6: 0.1383 | AA6: 0.1546 | AB6: 0.1402 | AC6: 0.131 | AD6: 0.1364 | AE6: 0.1243 | AF6: 0.1282 | AG6: 0.1251 | AH6: 0.1517 | AI6: 0.1219 | AJ6: 0.1251 | AK6: 0.1263 | AL6: 0.1258 | AM6: 0.128
B7: =B6+30 -> 120 | C7: 0.1237 | D7: 0.124 | E7: 0.1229 | F7: 0.1371 | G7: 0.1308 | H7: 0.1369 | I7: 0.1562 | J7: 0.1217 | K7: 0.1245 | L7: 0.141 | M7: 0.1361 | N7: 0.1518 | O7: 0.1239 | P7: 0.1277 | Q7: 0.1254 | R7: 0.1262 | S7: 0.1257 | T7: 0.1265 | V7: 0.1237 | W7: 0.124 | X7: 0.1229 | Y7: 0.141 | Z7: 0.1361 | AA7: 0.1518 | AB7: 0.1371 | AC7: 0.1308 | AD7: 0.1369 | AE7: 0.1239 | AF7: 0.1277 | AG7: 0.1254 | AH7: 0.1562 | AI7: 0.1217 | AJ7: 0.1245 | AK7: 0.1262 | AL7: 0.1257 | AM7: 0.1265
B8: =B7+30 -> 150 | C8: 0.1232 | D8: 0.1235 | E8: 0.122 | F8: 0.1357 | G8: 0.1292 | H8: 0.1333 | I8: 0.1362 | J8: 0.1201 | K8: 0.1242 | L8: 0.1394 | M8: 0.1356 | N8: 0.1494 | O8: 0.1225 | P8: 0.1257 | Q8: 0.1233 | R8: 0.125 | S8: 0.1244 | T8: 0.1252 | V8: 0.1232 | W8: 0.1235 | X8: 0.122 | Y8: 0.1394 | Z8: 0.1356 | AA8: 0.1494 | AB8: 0.1357 | AC8: 0.1292 | AD8: 0.1333 | AE8: 0.1225 | AF8: 0.1257 | AG8: 0.1233 | AH8: 0.1362 | AI8: 0.1201 | AJ8: 0.1242 | AK8: 0.125 | AL8: 0.1244 | AM8: 0.1252
B9: =B8+30 -> 180 | C9: 0.1215 | D9: 0.1227 | E9: 0.1215 | F9: 0.1357 | G9: 0.1289 | H9: 0.1302 | I9: 0.1423 | J9: 0.1207 | K9: 0.1231 | L9: 0.138 | M9: 0.1334 | N9: 0.1474 | O9: 0.1218 | P9: 0.125 | Q9: 0.1228 | R9: 0.1242 | S9: 0.1259 | T9: 0.1253 | V9: 0.1215 | W9: 0.1227 | X9: 0.1215 | Y9: 0.138 | Z9: 0.1334 | AA9: 0.1474 | AB9: 0.1357 | AC9: 0.1289 | AD9: 0.1302 | AE9: 0.1218 | AF9: 0.125 | AG9: 0.1228 | AH9: 0.1423 | AI9: 0.1207 | AJ9: 0.1231 | AK9: 0.1242 | AL9: 0.1259 | AM9: 0.1253
B10: =B9+30 -> 210 | C10: 0.1212 | D10: 0.1213 | E10: 0.1206 | F10: 0.134 | G10: 0.1277 | H10: 0.1284 | I10: 0.147 | J10: 0.1193 | K10: 0.1224 | L10: 0.1377 | M10: 0.1317 | N10: 0.1457 | O10: 0.121 | P10: 0.1247 | Q10: 0.1224 | R10: 0.1233 | S10: 0.1236 | T10: 0.1256 | V10: 0.1212 | W10: 0.1213 | X10: 0.1206 | Y10: 0.1377 | Z10: 0.1317 | AA10: 0.1457 | AB10: 0.134 | AC10: 0.1277 | AD10: 0.1284 | AE10: 0.121 | AF10: 0.1247 | AG10: 0.1224 | AH10: 0.147 | AI10: 0.1193 | AJ10: 0.1224 | AK10: 0.1233 | AL10: 0.1236 | AM10: 0.1256
B11: =B10+30 -> 240 | C11: 0.1204 | D11: 0.1209 | E11: 0.1202 | F11: 0.1324 | G11: 0.126 | H11: 0.1252 | I11: 0.1484 | J11: 0.1233 | K11: 0.1216 | L11: 0.1358 | M11: 0.1305 | N11: 0.1437 | O11: 0.1199 | P11: 0.1233 | Q11: 0.1212 | R11: 0.1227 | S11: 0.1228 | T11: 0.126 | V11: 0.1204 | W11: 0.1209 | X11: 0.1202 | Y11: 0.1358 | Z11: 0.1305 | AA11: 0.1437 | AB11: 0.1324 | AC11: 0.126 | AD11: 0.1252 | AE11: 0.1199 | AF11: 0.1233 | AG11: 0.1212 | AH11: 0.1484 | AI11: 0.1233 | AJ11: 0.1216 | AK11: 0.1227 | AL11: 0.1228 | AM11: 0.126
B12: =B11+30 -> 270 | C12: 0.1201 | D12: 0.1209 | E12: 0.1195 | F12: 0.1306 | G12: 0.1247 | H12: 0.1243 | I12: 0.145 | J12: 0.1213 | K12: 0.1213 | L12: 0.135 | M12: 0.1294 | N12: 0.1415 | O12: 0.1196 | P12: 0.1222 | Q12: 0.12 | R12: 0.1219 | S12: 0.1222 | T12: 0.1244 | V12: 0.1201 | W12: 0.1209 | X12: 0.1195 | Y12: 0.135 | Z12: 0.1294 | AA12: 0.1415 | AB12: 0.1306 | AC12: 0.1247 | AD12: 0.1243 | AE12: 0.1196 | AF12: 0.1222 | AG12: 0.12 | AH12: 0.145 | AI12: 0.1213 | AJ12: 0.1213 | AK12: 0.1219 | AL12: 0.1222 | AM12: 0.1244
B13: =B12+30 -> 300 | C13: 0.1195 | D13: 0.1205 | E13: 0.1191 | F13: 0.1306 | G13: 0.1239 | H13: 0.1235 | I13: 0.1395 | J13: 0.1176 | K13: 0.1207 | L13: 0.1401 | M13: 0.1291 | N13: 0.1397 | O13: 0.1188 | P13: 0.1213 | Q13: 0.1196 | R13: 0.1217 | S13: 0.1219 | T13: 0.125 | V13: 0.1195 | W13: 0.1205 | X13: 0.1191 | Y13: 0.1401 | Z13: 0.1291 | AA13: 0.1397 | AB13: 0.1306 | AC13: 0.1239 | AD13: 0.1235 | AE13: 0.1188 | AF13: 0.1213 | AG13: 0.1196 | AH13: 0.1395 | AI13: 0.1176 | AJ13: 0.1207 | AK13: 0.1217 | AL13: 0.1219 | AM13: 0.125
B14: =B13+30 -> 330 | C14: 0.1189 | D14: 0.1194 | E14: 0.1185 | F14: 0.1291 | G14: 0.1233 | H14: 0.1232 | I14: 0.1418 | J14: 0.1173 | K14: 0.1203 | L14: 0.144 | M14: 0.1284 | N14: 0.1376 | O14: 0.1184 | P14: 0.1205 | Q14: 0.119 | R14: 0.1212 | S14: 0.1208 | T14: 0.1244 | V14: 0.1189 | W14: 0.1194 | X14: 0.1185 | Y14: 0.144 | Z14: 0.1284 | AA14: 0.1376 | AB14: 0.1291 | AC14: 0.1233 | AD14: 0.1232 | AE14: 0.1184 | AF14: 0.1205 | AG14: 0.119 | AH14: 0.1418 | AI14: 0.1173 | AJ14: 0.1203 | AK14: 0.1212 | AL14: 0.1208 | AM14: 0.1244
B15: =B14+30 -> 360 | C15: 0.1185 | D15: 0.119 | E15: 0.1186 | F15: 0.1282 | G15: 0.1229 | H15: 0.1227 | I15: 0.1454 | J15: 0.1167 | K15: 0.1197 | L15: 0.1454 | M15: 0.1281 | N15: 0.1368 | O15: 0.1181 | P15: 0.12 | Q15: 0.1183 | R15: 0.1219 | S15: 0.12 | T15: 0.1242 | V15: 0.1185 | W15: 0.119 | X15: 0.1186 | Y15: 0.1454 | Z15: 0.1281 | AA15: 0.1368 | AB15: 0.1282 | AC15: 0.1229 | AD15: 0.1227 | AE15: 0.1181 | AF15: 0.12 | AG15: 0.1183 | AH15: 0.1454 | AI15: 0.1167 | AJ15: 0.1197 | AK15: 0.1219 | AL15: 0.12 | AM15: 0.1242
B16: =B15+30 -> 390 | C16: 0.1183 | D16: 0.1187 | E16: 0.118 | F16: 0.1283 | G16: 0.1219 | H16: 0.1224 | I16: 0.1436 | J16: 0.1195 | K16: 0.119 | L16: 0.1456 | M16: 0.1291 | N16: 0.1361 | O16: 0.1178 | P16: 0.1196 | Q16: 0.1179 | R16: 0.1221 | S16: 0.1194 | T16: 0.126 | V16: 0.1183 | W16: 0.1187 | X16: 0.118 | Y16: 0.1456 | Z16: 0.1291 | AA16: 0.1361 | AB16: 0.1283 | AC16: 0.1219 | AD16: 0.1224 | AE16: 0.1178 | AF16: 0.1196 | AG16: 0.1179 | AH16: 0.1436 | AI16: 0.1195 | AJ16: 0.119 | AK16: 0.1221 | AL16: 0.1194 | AM16: 0.126
... B42: =B41+30 -> 1170 | C42: 0.1112 | D42: 0.1102 | E42: 0.1086 | F42: 0.1595 | G42: 0.1176 | H42: 0.1261 | I42: 0.1773 | J42: 0.1114 | K42: 0.1141 | L42: 0.1203 | M42: 0.1216 | N42: 0.1254 | O42: 0.1171 | P42: 0.1161 | Q42: 0.1141 | R42: 0.1126 | S42: 0.1126 | T42: 0.1153 | V42: 0.1112 | W42: 0.1102 | X42: 0.1086 | Y42: 0.1203 | Z42: 0.1216 | AA42: 0.1254 | AB42: 0.1595 | AC42: 0.1176 | AD42: 0.1261 | AE42: 0.1171 | AF42: 0.1161 | AG42: 0.1141 | AH42: 0.1773 | AI42: 0.1114 | AJ42: 0.1141 | AK42: 0.1126 | AL42: 0.1126 | AM42: 0.1153
A43: 46075.762 | B43: =B42+30 -> 1200 | C43: 0.1111 | D43: 0.1099 | E43: 0.1083 | F43: 0.1645 | G43: 0.1177 | H43: 0.1191 | I43: 0.189 | J43: 0.11 | K43: 0.1199 | L43: 0.1203 | M43: 0.121 | N43: 0.1366 | O43: 0.1168 | P43: 0.1164 | Q43: 0.1138 | R43: 0.112 | S43: 0.1127 | T43: 0.1129 | V43: 0.1111 | W43: 0.1099 | X43: 0.1083 | Y43: 0.1203 | Z43: 0.121 | AA43: 0.1366 | AB43: 0.1645 | AC43: 0.1177 | AD43: 0.1191 | AE43: 0.1168 | AF43: 0.1164 | AG43: 0.1138 | AH43: 0.189 | AI43: 0.11 | AJ43: 0.1199 | AK43: 0.112 | AL43: 0.1127 | AM43: 0.1129
A44: 46075.767 | B44: =B43+10 -> 1210 | C44: 0.1143 | D44: 0.1181 | E44: 0.1149 | F44: 0.1416 | G44: 0.1381 | H44: 0.1278 | I44: 0.169 | J44: 0.1156 | K44: 0.1228 | L44: 0.1247 | M44: 0.1314 | N44: 0.1347 | O44: 0.1204 | P44: 0.1375 | Q44: 0.1208 | R44: 0.1117 | S44: 0.1171 | T44: 0.1165 | V44: 0.1143 | W44: 0.1181 | X44: 0.1149 | Y44: 0.1247 | Z44: 0.1314 | AA44: 0.1347 | AB44: 0.1416 | AC44: 0.1381 | AD44: 0.1278 | AE44: 0.1204 | AF44: 0.1375 | AG44: 0.1208 | AH44: 0.169 | AI44: 0.1156 | AJ44: 0.1228 | AK44: 0.1117 | AL44: 0.1171 | AM44: 0.1165
A45: 46075.794 | B45: =B44+40 -> 1250 | C45: 0.1154 | D45: 0.1154 | E45: 0.1156 | F45: 0.1387 | G45: 0.1197 | H45: 0.1211 | I45: 0.1451 | J45: 0.119 | K45: 0.1167 | L45: 0.122 | M45: 0.1229 | N45: 0.1266 | O45: 0.114 | P45: 0.1198 | Q45: 0.1171 | R45: 0.1138 | S45: 0.121 | T45: 0.1135 | V45: 0.1154 | W45: 0.1154 | X45: 0.1156 | Y45: 0.122 | Z45: 0.1229 | AA45: 0.1266 | AB45: 0.1387 | AC45: 0.1197 | AD45: 0.1211 | AE45: 0.114 | AF45: 0.1198 | AG45: 0.1171 | AH45: 0.1451 | AI45: 0.119 | AJ45: 0.1167 | AK45: 0.1138 | AL45: 0.121 | AM45: 0.1135
B46: =B45+30 -> 1280 | C46: 0.1121 | D46: 0.1096 | E46: 0.1077 | F46: 0.1656 | G46: 0.12 | H46: 0.129 | I46: 0.2164 | J46: 0.1102 | K46: 0.1147 | L46: 0.1215 | M46: 0.1252 | N46: 0.1256 | O46: 0.1171 | P46: 0.1178 | Q46: 0.1153 | R46: 0.1154 | S46: 0.1119 | T46: 0.1118 | V46: 0.1121 | W46: 0.1096 | X46: 0.1077 | Y46: 0.1215 | Z46: 0.1252 | AA46: 0.1256 | AB46: 0.1656 | AC46: 0.12 | AD46: 0.129 | AE46: 0.1171 | AF46: 0.1178 | AG46: 0.1153 | AH46: 0.2164 | AI46: 0.1102 | AJ46: 0.1147 | AK46: 0.1154 | AL46: 0.1119 | AM46: 0.1118
B47: =B46+30 -> 1310 | C47: 0.1119 | D47: 0.1094 | E47: 0.1077 | F47: 0.165 | G47: 0.1191 | H47: 0.1214 | I47: 0.1853 | J47: 0.1121 | K47: 0.1178 | L47: 0.123 | M47: 0.1264 | N47: 0.1286 | O47: 0.1152 | P47: 0.1179 | Q47: 0.116 | R47: 0.1131 | S47: 0.1117 | T47: 0.1115 | V47: 0.1119 | W47: 0.1094 | X47: 0.1077 | Y47: 0.123 | Z47: 0.1264 | AA47: 0.1286 | AB47: 0.165 | AC47: 0.1191 | AD47: 0.1214 | AE47: 0.1152 | AF47: 0.1179 | AG47: 0.116 | AH47: 0.1853 | AI47: 0.1121 | AJ47: 0.1178 | AK47: 0.1131 | AL47: 0.1117 | AM47: 0.1115
B48: =B47+30 -> 1340 | C48: 0.1117 | D48: 0.109 | E48: 0.107 | F48: 0.1604 | G48: 0.1191 | H48: 0.1223 | I48: 0.1698 | J48: 0.1102 | K48: 0.1161 | L48: 0.1205 | M48: 0.1252 | N48: 0.14 | O48: 0.117 | P48: 0.1185 | Q48: 0.1193 | R48: 0.1158 | S48: 0.1118 | T48: 0.1124 | V48: 0.1117 | W48: 0.109 | X48: 0.107 | Y48: 0.1205 | Z48: 0.1252 | AA48: 0.14 | AB48: 0.1604 | AC48: 0.1191 | AD48: 0.1223 | AE48: 0.117 | AF48: 0.1185 | AG48: 0.1193 | AH48: 0.1698 | AI48: 0.1102 | AJ48: 0.1161 | AK48: 0.1158 | AL48: 0.1118 | AM48: 0.1124
B49: =B48+30 -> 1370 | C49: 0.1118 | D49: 0.109 | E49: 0.1071 | F49: 0.1678 | G49: 0.1187 | H49: 0.1216 | I49: 0.1698 | J49: 0.1117 | K49: 0.1234 | L49: 0.1229 | M49: 0.1252 | N49: 0.1405 | O49: 0.116 | P49: 0.119 | Q49: 0.1159 | R49: 0.1149 | S49: 0.1191 | T49: 0.1184 | V49: 0.1118 | W49: 0.109 | X49: 0.1071 | Y49: 0.1229 | Z49: 0.1252 | AA49: 0.1405 | AB49: 0.1678 | AC49: 0.1187 | AD49: 0.1216 | AE49: 0.116 | AF49: 0.119 | AG49: 0.1159 | AH49: 0.1698 | AI49: 0.1117 | AJ49: 0.1234 | AK49: 0.1149 | AL49: 0.1191 | AM49: 0.1184
B50: =B49+30 -> 1400 | C50: 0.1117 | D50: 0.1089 | E50: 0.1071 | F50: 0.1622 | G50: 0.1186 | H50: 0.1222 | I50: 0.1856 | J50: 0.1101 | K50: 0.1161 | L50: 0.12 | M50: 0.1249 | N50: 0.1251 | O50: 0.1143 | P50: 0.1194 | Q50: 0.1161 | R50: 0.1179 | S50: 0.1189 | T50: 0.117 | V50: 0.1117 | W50: 0.1089 | X50: 0.1071 | Y50: 0.12 | Z50: 0.1249 | AA50: 0.1251 | AB50: 0.1622 | AC50: 0.1186 | AD50: 0.1222 | AE50: 0.1143 | AF50: 0.1194 | AG50: 0.1161 | AH50: 0.1856 | AI50: 0.1101 | AJ50: 0.1161 | AK50: 0.1179 | AL50: 0.1189 | AM50: 0.117
B51: =B50+30 -> 1430 | C51: 0.1113 | D51: 0.1087 | E51: 0.1071 | F51: 0.1537 | G51: 0.1184 | H51: 0.1333 | I51: 0.1864 | J51: 0.1137 | K51: 0.1194 | L51: 0.1207 | M51: 0.1243 | N51: 0.1399 | O51: 0.1155 | P51: 0.1189 | Q51: 0.1163 | R51: 0.1162 | S51: 0.1197 | T51: 0.1128 | V51: 0.1113 | W51: 0.1087 | X51: 0.1071 | Y51: 0.1207 | Z51: 0.1243 | AA51: 0.1399 | AB51: 0.1537 | AC51: 0.1184 | AD51: 0.1333 | AE51: 0.1155 | AF51: 0.1189 | AG51: 0.1163 | AH51: 0.1864 | AI51: 0.1137 | AJ51: 0.1194 | AK51: 0.1162 | AL51: 0.1197 | AM51: 0.1128
B52: =B51+30 -> 1460 | C52: 0.1118 | D52: 0.1085 | E52: 0.107 | F52: 0.1709 | G52: 0.1187 | H52: 0.1278 | I52: 0.1984 | J52: 0.1104 | K52: 0.116 | L52: 0.1215 | M52: 0.1239 | N52: 0.1283 | O52: 0.1155 | P52: 0.1186 | Q52: 0.1154 | R52: 0.1133 | S52: 0.1189 | T52: 0.1137 | V52: 0.1118 | W52: 0.1085 | X52: 0.107 | Y52: 0.1215 | Z52: 0.1239 | AA52: 0.1283 | AB52: 0.1709 | AC52: 0.1187 | AD52: 0.1278 | AE52: 0.1155 | AF52: 0.1186 | AG52: 0.1154 | AH52: 0.1984 | AI52: 0.1104 | AJ52: 0.116 | AK52: 0.1133 | AL52: 0.1189 | AM52: 0.1137
B53: =B52+30 -> 1490 | C53: 0.1113 | D53: 0.1082 | E53: 0.1065 | F53: 0.1715 | G53: 0.1189 | H53: 0.1227 | I53: 0.1706 | J53: 0.11 | K53: 0.1204 | L53: 0.1229 | M53: 0.1232 | N53: 0.1315 | O53: 0.118 | P53: 0.1187 | Q53: 0.1161 | R53: 0.1118 | S53: 0.1151 | T53: 0.1108 | V53: 0.1113 | W53: 0.1082 | X53: 0.1065 | Y53: 0.1229 | Z53: 0.1232 | AA53: 0.1315 | AB53: 0.1715 | AC53: 0.1189 | AD53: 0.1227 | AE53: 0.118 | AF53: 0.1187 | AG53: 0.1161 | AH53: 0.1706 | AI53: 0.11 | AJ53: 0.1204 | AK53: 0.1118 | AL53: 0.1151 | AM53: 0.1108
B54: =B53+30 -> 1520 | C54: 0.1114 | D54: 0.1086 | E54: 0.1068 | F54: 0.1659 | G54: 0.119 | H54: 0.1411 | I54: 0.1891 | J54: 0.1127 | K54: 0.1163 | L54: 0.1195 | M54: 0.1231 | N54: 0.1247 | O54: 0.1143 | P54: 0.1194 | Q54: 0.1157 | R54: 0.1147 | S54: 0.1177 | T54: 0.1113 | V54: 0.1114 | W54: 0.1086 | X54: 0.1068 | Y54: 0.1195 | Z54: 0.1231 | AA54: 0.1247 | AB54: 0.1659 | AC54: 0.119 | AD54: 0.1411 | AE54: 0.1143 | AF54: 0.1194 | AG54: 0.1157 | AH54: 0.1891 | AI54: 0.1127 | AJ54: 0.1163 | AK54: 0.1147 | AL54: 0.1177 | AM54: 0.1113
B55: =B54+30 -> 1550 | C55: 0.1113 | D55: 0.1081 | E55: 0.1068 | F55: 0.1656 | G55: 0.1209 | H55: 0.1287 | I55: 0.1943 | J55: 0.1096 | K55: 0.1182 | L55: 0.121 | M55: 0.1224 | N55: 0.1252 | O55: 0.1162 | P55: 0.1197 | Q55: 0.1172 | R55: 0.1158 | S55: 0.1215 | T55: 0.1099 | V55: 0.1113 | W55: 0.1081 | X55: 0.1068 | Y55: 0.121 | Z55: 0.1224 | AA55: 0.1252 | AB55: 0.1656 | AC55: 0.1209 | AD55: 0.1287 | AE55: 0.1162 | AF55: 0.1197 | AG55: 0.1172 | AH55: 0.1943 | AI55: 0.1096 | AJ55: 0.1182 | AK55: 0.1158 | AL55: 0.1215 | AM55: 0.1099
B56: =B55+30 -> 1580 | C56: 0.1113 | D56: 0.1078 | E56: 0.1063 | F56: 0.1865 | G56: 0.1197 | H56: 0.1316 | I56: 0.1854 | J56: 0.1115 | K56: 0.1153 | L56: 0.1233 | M56: 0.1223 | N56: 0.1308 | O56: 0.1132 | P56: 0.1191 | Q56: 0.1151 | R56: 0.1106 | S56: 0.1202 | T56: 0.1159 | V56: 0.1113 | W56: 0.1078 | X56: 0.1063 | Y56: 0.1233 | Z56: 0.1223 | AA56: 0.1308 | AB56: 0.1865 | AC56: 0.1197 | AD56: 0.1316 | AE56: 0.1132 | AF56: 0.1191 | AG56: 0.1151 | AH56: 0.1854 | AI56: 0.1115 | AJ56: 0.1153 | AK56: 0.1106 | AL56: 0.1202 | AM56: 0.1159
B57: =B56+30 -> 1610 | C57: 0.1111 | D57: 0.108 | E57: 0.1063 | F57: 0.1607 | G57: 0.1282 | H57: 0.1222 | I57: 0.2079 | J57: 0.1104 | K57: 0.1166 | L57: 0.1232 | M57: 0.1222 | N57: 0.1292 | O57: 0.1145 | P57: 0.1187 | Q57: 0.115 | R57: 0.11 | S57: 0.1132 | T57: 0.1123 | V57: 0.1111 | W57: 0.108 | X57: 0.1063 | Y57: 0.1232 | Z57: 0.1222 | AA57: 0.1292 | AB57: 0.1607 | AC57: 0.1282 | AD57: 0.1222 | AE57: 0.1145 | AF57: 0.1187 | AG57: 0.115 | AH57: 0.2079 | AI57: 0.1104 | AJ57: 0.1166 | AK57: 0.11 | AL57: 0.1132 | AM57: 0.1123
... B89: =B88+30 -> 2570 | C89: 0.1095 | D89: 0.1064 | E89: 0.105 | F89: 0.1904 | G89: 0.1129 | H89: 0.1209 | I89: 0.1951 | J89: 0.1156 | K89: 0.1112 | L89: 0.1146 | M89: 0.1151 | N89: 0.12 | O89: 0.1198 | P89: 0.111 | Q89: 0.1101 | R89: 0.1055 | S89: 0.1062 | T89: 0.109 | V89: 0.1095 | W89: 0.1064 | X89: 0.105 | Y89: 0.1146 | Z89: 0.1151 | AA89: 0.12 | AB89: 0.1904 | AC89: 0.1129 | AD89: 0.1209 | AE89: 0.1198 | AF89: 0.111 | AG89: 0.1101 | AH89: 0.1951 | AI89: 0.1156 | AJ89: 0.1112 | AK89: 0.1055 | AL89: 0.1062 | AM89: 0.109
A90: 46076.732 | B90: =B89+30 -> 2600 | C90: 0.1093 | D90: 0.1061 | E90: 0.1042 | F90: 0.1794 | G90: 0.1229 | H90: 0.1338 | I90: 0.2191 | J90: 0.1134 | K90: 0.1085 | L90: 0.1145 | M90: 0.1159 | N90: 0.126 | O90: 0.1104 | P90: 0.1111 | Q90: 0.11 | R90: 0.1069 | S90: 0.1044 | T90: 0.105 | V90: 0.1093 | W90: 0.1061 | X90: 0.1042 | Y90: 0.1145 | Z90: 0.1159 | AA90: 0.126 | AB90: 0.1794 | AC90: 0.1229 | AD90: 0.1338 | AE90: 0.1104 | AF90: 0.1111 | AG90: 0.11 | AH90: 0.2191 | AI90: 0.1134 | AJ90: 0.1085 | AK90: 0.1069 | AL90: 0.1044 | AM90: 0.105
B93: △ | C93: =C90-C3 -> -0.0162 | D93: =D90-D3 -> -0.0203 | E93: =E90-E3 -> -0.0198 | F93: =F90-F3 -> -0.0202 | G93: =G90-G3 -> -0.0109 | H93: =H90-H3 -> -0.0062 | I93: =I90-I3 -> 0.0479 | J93: =J90-J3 -> -0.0113 | ... T93: =T90-T3 -> -0.0201

Sheet r1.raw.A
A1: Data-Time | B1: Time | C1: Dark | L1: IR | V1: RAW
A2: Data-Time | B2: Time 1 | C2: Dark-A-C1 | D2: Dark-A-C2 | E2: Dark-A-C3 | F2: Dark-A-Ac1 | G2: Dark-A-Ac2 | H2: Dark-A-Ac3 | I2: Dark-A-S1 | J2: Dark-A-S2 | K2: Dark-A-S3 | L2: IR-A-C1 | M2: IR-A-C2 | N2: IR-A-C3 | O2: IR-A-Ac1 | P2: IR-A-Ac2 | Q2: IR-A-Ac3 | R2: IR-A-S1 | S2: IR-A-S2 | T2: IR-A-S3 | U2: Tips | V2: C-D | Y2: C-I | AB2: Ac-D | AE2: Ac-I | AH2: S-D | AK2: S-I
A3: 46063.842 | B3: 0 | C3: 0.1165 | D3: 0.1157 | E3: 0.1159 | F3: 0.1151 | G3: 0.1147 | H3: 0.1152 | I3: 0.1157 | J3: 0.1155 | K3: 0.1192 | L3: 0.1232 | M3: 0.115 | N3: 0.1139 | O3: 0.1158 | P3: 0.1153 | Q3: 0.1158 | R3: 0.114 | S3: 0.1176 | T3: 0.1182 | V3: 0.1165 | W3: 0.1157 | X3: 0.1159 | Y3: 0.1232 | Z3: 0.115 | AA3: 0.1139 | AB3: 0.1151 | AC3: 0.1147 | AD3: 0.1152 | AE3: 0.1158 | AF3: 0.1153 | AG3: 0.1158 | AH3: 0.1157 | AI3: 0.1155 | AJ3: 0.1192 | AK3: 0.114 | AL3: 0.1176 | AM3: 0.1182
B4: 30 | C4: 0.1162 | D4: 0.115 | E4: 0.1156 | F4: 0.115 | G4: 0.1139 | H4: 0.1143 | I4: 0.115 | J4: 0.1145 | K4: 0.1184 | L4: 0.1142 | M4: 0.1147 | N4: 0.1134 | O4: 0.1152 | P4: 0.1143 | Q4: 0.1156 | R4: 0.1134 | S4: 0.1171 | T4: 0.1174 | V4: 0.1162 | W4: 0.115 | X4: 0.1156 | Y4: 0.1142 | Z4: 0.1147 | AA4: 0.1134 | AB4: 0.115 | AC4: 0.1139 | AD4: 0.1143 | AE4: 0.1152 | AF4: 0.1143 | AG4: 0.1156 | AH4: 0.115 | AI4: 0.1145 | AJ4: 0.1184 | AK4: 0.1134 | AL4: 0.1171 | AM4: 0.1174
B5: =B4+30 -> 60 | C5: 0.1155 | D5: 0.1145 | E5: 0.1151 | F5: 0.1137 | G5: 0.1127 | H5: 0.1135 | I5: 0.1147 | J5: 0.1145 | K5: 0.118 | L5: 0.1138 | M5: 0.1142 | N5: 0.1132 | O5: 0.115 | P5: 0.1139 | Q5: 0.1146 | R5: 0.1131 | S5: 0.1166 | T5: 0.1169 | V5: 0.1155 | W5: 0.1145 | X5: 0.1151 | Y5: 0.1138 | Z5: 0.1142 | AA5: 0.1132 | AB5: 0.1137 | AC5: 0.1127 | AD5: 0.1135 | AE5: 0.115 | AF5: 0.1139 | AG5: 0.1146 | AH5: 0.1147 | AI5: 0.1145 | AJ5: 0.118 | AK5: 0.1131 | AL5: 0.1166 | AM5: 0.1169
B6: =B5+30 -> 90 | C6: 0.1153 | D6: 0.1148 | E6: 0.1149 | F6: 0.1138 | G6: 0.113 | H6: 0.1135 | I6: 0.1145 | J6: 0.1142 | K6: 0.1177 | L6: 0.1138 | M6: 0.1141 | N6: 0.1131 | O6: 0.1146 | P6: 0.1137 | Q6: 0.1141 | R6: 0.1128 | S6: 0.1164 | T6: 0.1171 | V6: 0.1153 | W6: 0.1148 | X6: 0.1149 | Y6: 0.1138 | Z6: 0.1141 | AA6: 0.1131 | AB6: 0.1138 | AC6: 0.113 | AD6: 0.1135 | AE6: 0.1146 | AF6: 0.1137 | AG6: 0.1141 | AH6: 0.1145 | AI6: 0.1142 | AJ6: 0.1177 | AK6: 0.1128 | AL6: 0.1164 | AM6: 0.1171
B7: =B6+30 -> 120 | C7: 0.1151 | D7: 0.1146 | E7: 0.1152 | F7: 0.1133 | G7: 0.1131 | H7: 0.1134 | I7: 0.1145 | J7: 0.1141 | K7: 0.1175 | L7: 0.1131 | M7: 0.1137 | N7: 0.1127 | O7: 0.1139 | P7: 0.1131 | Q7: 0.1137 | R7: 0.1127 | S7: 0.1163 | T7: 0.1171 | V7: 0.1151 | W7: 0.1146 | X7: 0.1152 | Y7: 0.1131 | Z7: 0.1137 | AA7: 0.1127 | AB7: 0.1133 | AC7: 0.1131 | AD7: 0.1134 | AE7: 0.1139 | AF7: 0.1131 | AG7: 0.1137 | AH7: 0.1145 | AI7: 0.1141 | AJ7: 0.1175 | AK7: 0.1127 | AL7: 0.1163 | AM7: 0.1171
B8: =B7+30 -> 150 | C8: 0.115 | D8: 0.1142 | E8: 0.115 | F8: 0.113 | G8: 0.1119 | H8: 0.1127 | I8: 0.114 | J8: 0.114 | K8: 0.1172 | L8: 0.1132 | M8: 0.1137 | N8: 0.1122 | O8: 0.1134 | P8: 0.1128 | Q8: 0.1134 | R8: 0.1128 | S8: 0.1161 | T8: 0.1167 | V8: 0.115 | W8: 0.1142 | X8: 0.115 | Y8: 0.1132 | Z8: 0.1137 | AA8: 0.1122 | AB8: 0.113 | AC8: 0.1119 | AD8: 0.1127 | AE8: 0.1134 | AF8: 0.1128 | AG8: 0.1134 | AH8: 0.114 | AI8: 0.114 | AJ8: 0.1172 | AK8: 0.1128 | AL8: 0.1161 | AM8: 0.1167
B9: =B8+30 -> 180 | C9: 0.115 | D9: 0.1142 | E9: 0.1153 | F9: 0.1127 | G9: 0.1121 | H9: 0.1131 | I9: 0.1141 | J9: 0.1138 | K9: 0.1173 | L9: 0.1134 | M9: 0.1134 | N9: 0.1123 | O9: 0.1131 | P9: 0.1125 | Q9: 0.1129 | R9: 0.1124 | S9: 0.1161 | T9: 0.1167 | V9: 0.115 | W9: 0.1142 | X9: 0.1153 | Y9: 0.1134 | Z9: 0.1134 | AA9: 0.1123 | AB9: 0.1127 | AC9: 0.1121 | AD9: 0.1131 | AE9: 0.1131 | AF9: 0.1125 | AG9: 0.1129 | AH9: 0.1141 | AI9: 0.1138 | AJ9: 0.1173 | AK9: 0.1124 | AL9: 0.1161 | AM9: 0.1167
B10: =B9+30 -> 210 | C10: 0.115 | D10: 0.1146 | E10: 0.115 | F10: 0.1125 | G10: 0.1129 | H10: 0.113 | I10: 0.1139 | J10: 0.1134 | K10: 0.1172 | L10: 0.1132 | M10: 0.1132 | N10: 0.1121 | O10: 0.1127 | P10: 0.1117 | Q10: 0.1127 | R10: 0.1125 | S10: 0.1159 | T10: 0.1167 | V10: 0.115 | W10: 0.1146 | X10: 0.115 | Y10: 0.1132 | Z10: 0.1132 | AA10: 0.1121 | AB10: 0.1125 | AC10: 0.1129 | AD10: 0.113 | AE10: 0.1127 | AF10: 0.1117 | AG10: 0.1127 | AH10: 0.1139 | AI10: 0.1134 | AJ10: 0.1172 | AK10: 0.1125 | AL10: 0.1159 | AM10: 0.1167
B11: =B10+30 -> 240 | C11: 0.1152 | D11: 0.1146 | E11: 0.1153 | F11: 0.112 | G11: 0.1123 | H11: 0.1128 | I11: 0.1139 | J11: 0.1135 | K11: 0.1168 | L11: 0.1131 | M11: 0.1135 | N11: 0.112 | O11: 0.1128 | P11: 0.1113 | Q11: 0.1129 | R11: 0.1124 | S11: 0.1158 | T11: 0.1167 | V11: 0.1152 | W11: 0.1146 | X11: 0.1153 | Y11: 0.1131 | Z11: 0.1135 | AA11: 0.112 | AB11: 0.112 | AC11: 0.1123 | AD11: 0.1128 | AE11: 0.1128 | AF11: 0.1113 | AG11: 0.1129 | AH11: 0.1139 | AI11: 0.1135 | AJ11: 0.1168 | AK11: 0.1124 | AL11: 0.1158 | AM11: 0.1167
B12: =B11+30 -> 270 | C12: 0.1151 | D12: 0.1143 | E12: 0.1152 | F12: 0.1116 | G12: 0.1122 | H12: 0.1129 | I12: 0.1138 | J12: 0.1136 | K12: 0.117 | L12: 0.1129 | M12: 0.1136 | N12: 0.1121 | O12: 0.1128 | P12: 0.1119 | Q12: 0.1129 | R12: 0.1124 | S12: 0.1161 | T12: 0.1167 | V12: 0.1151 | W12: 0.1143 | X12: 0.1152 | Y12: 0.1129 | Z12: 0.1136 | AA12: 0.1121 | AB12: 0.1116 | AC12: 0.1122 | AD12: 0.1129 | AE12: 0.1128 | AF12: 0.1119 | AG12: 0.1129 | AH12: 0.1138 | AI12: 0.1136 | AJ12: 0.117 | AK12: 0.1124 | AL12: 0.1161 | AM12: 0.1167
B13: =B12+30 -> 300 | C13: 0.1152 | D13: 0.1144 | E13: 0.1151 | F13: 0.112 | G13: 0.112 | H13: 0.113 | I13: 0.1139 | J13: 0.1152 | K13: 0.1175 | L13: 0.1132 | M13: 0.1135 | N13: 0.1122 | O13: 0.1125 | P13: 0.1121 | Q13: 0.113 | R13: 0.1127 | S13: 0.116 | T13: 0.1168 | V13: 0.1152 | W13: 0.1144 | X13: 0.1151 | Y13: 0.1132 | Z13: 0.1135 | AA13: 0.1122 | AB13: 0.112 | AC13: 0.112 | AD13: 0.113 | AE13: 0.1125 | AF13: 0.1121 | AG13: 0.113 | AH13: 0.1139 | AI13: 0.1152 | AJ13: 0.1175 | AK13: 0.1127 | AL13: 0.116 | AM13: 0.1168
B14: =B13+30 -> 330 | C14: 0.1153 | D14: 0.1146 | E14: 0.115 | F14: 0.1118 | G14: 0.1122 | H14: 0.1132 | I14: 0.114 | J14: 0.1138 | K14: 0.1172 | L14: 0.113 | M14: 0.1133 | N14: 0.1121 | O14: 0.1125 | P14: 0.1116 | Q14: 0.1129 | R14: 0.1128 | S14: 0.1162 | T14: 0.1168 | V14: 0.1153 | W14: 0.1146 | X14: 0.115 | Y14: 0.113 | Z14: 0.1133 | AA14: 0.1121 | AB14: 0.1118 | AC14: 0.1122 | AD14: 0.1132 | AE14: 0.1125 | AF14: 0.1116 | AG14: 0.1129 | AH14: 0.114 | AI14: 0.1138 | AJ14: 0.1172 | AK14: 0.1128 | AL14: 0.1162 | AM14: 0.1168
B15: =B14+30 -> 360 | C15: 0.1154 | D15: 0.1145 | E15: 0.1149 | F15: 0.1123 | G15: 0.1125 | H15: 0.1137 | I15: 0.1142 | J15: 0.1141 | K15: 0.1176 | L15: 0.1129 | M15: 0.1139 | N15: 0.1123 | O15: 0.1124 | P15: 0.1121 | Q15: 0.1132 | R15: 0.1127 | S15: 0.116 | T15: 0.117 | V15: 0.1154 | W15: 0.1145 | X15: 0.1149 | Y15: 0.1129 | Z15: 0.1139 | AA15: 0.1123 | AB15: 0.1123 | AC15: 0.1125 | AD15: 0.1137 | AE15: 0.1124 | AF15: 0.1121 | AG15: 0.1132 | AH15: 0.1142 | AI15: 0.1141 | AJ15: 0.1176 | AK15: 0.1127 | AL15: 0.116 | AM15: 0.117
B16: =B15+30 -> 390 | C16: 0.1154 | D16: 0.1145 | E16: 0.1152 | F16: 0.1124 | G16: 0.1125 | H16: 0.1136 | I16: 0.114 | J16: 0.1136 | K16: 0.1172 | L16: 0.113 | M16: 0.1137 | N16: 0.1124 | O16: 0.1126 | P16: 0.1116 | Q16: 0.113 | R16: 0.1127 | S16: 0.1159 | T16: 0.1167 | V16: 0.1154 | W16: 0.1145 | X16: 0.1152 | Y16: 0.113 | Z16: 0.1137 | AA16: 0.1124 | AB16: 0.1124 | AC16: 0.1125 | AD16: 0.1136 | AE16: 0.1126 | AF16: 0.1116 | AG16: 0.113 | AH16: 0.114 | AI16: 0.1136 | AJ16: 0.1172 | AK16: 0.1127 | AL16: 0.1159 | AM16: 0.1167
... B42: =B41+30 -> 1170 | C42: 0.1136 | D42: 0.115 | E42: 0.116 | F42: 0.1132 | G42: 0.1139 | H42: 0.1178 | I42: 0.1131 | J42: 0.1131 | K42: 0.1167 | L42: 0.1133 | M42: 0.114 | N42: 0.113 | O42: 0.1113 | P42: 0.1112 | Q42: 0.1147 | R42: 0.1124 | S42: 0.1149 | T42: 0.1155 | V42: 0.1136 | W42: 0.115 | X42: 0.116 | Y42: 0.1133 | Z42: 0.114 | AA42: 0.113 | AB42: 0.1132 | AC42: 0.1139 | AD42: 0.1178 | AE42: 0.1113 | AF42: 0.1112 | AG42: 0.1147 | AH42: 0.1131 | AI42: 0.1131 | AJ42: 0.1167 | AK42: 0.1124 | AL42: 0.1149 | AM42: 0.1155
A43: 46075.762 | B43: =B42+30 -> 1200 | C43: 0.1136 | D43: 0.1149 | E43: 0.116 | F43: 0.1133 | G43: 0.114 | H43: 0.1181 | I43: 0.1127 | J43: 0.1129 | K43: 0.1166 | L43: 0.1134 | M43: 0.1138 | N43: 0.1129 | O43: 0.1112 | P43: 0.1113 | Q43: 0.1149 | R43: 0.1124 | S43: 0.1149 | T43: 0.1153 | V43: 0.1136 | W43: 0.1149 | X43: 0.116 | Y43: 0.1134 | Z43: 0.1138 | AA43: 0.1129 | AB43: 0.1133 | AC43: 0.114 | AD43: 0.1181 | AE43: 0.1112 | AF43: 0.1113 | AG43: 0.1149 | AH43: 0.1127 | AI43: 0.1129 | AJ43: 0.1166 | AK43: 0.1124 | AL43: 0.1149 | AM43: 0.1153
A44: 46075.767 | B44: =B43+10 -> 1210 | C44: 0.115 | D44: 0.1168 | E44: 0.1176 | F44: 0.1199 | G44: 0.1193 | H44: 0.1223 | I44: 0.1164 | J44: 0.1152 | K44: 0.1222 | L44: 0.1164 | M44: 0.1188 | N44: 0.1157 | O44: 0.1156 | P44: 0.1148 | Q44: 0.1181 | R44: 0.1133 | S44: 0.1154 | T44: 0.1166 | V44: 0.115 | W44: 0.1168 | X44: 0.1176 | Y44: 0.1164 | Z44: 0.1188 | AA44: 0.1157 | AB44: 0.1199 | AC44: 0.1193 | AD44: 0.1223 | AE44: 0.1156 | AF44: 0.1148 | AG44: 0.1181 | AH44: 0.1164 | AI44: 0.1152 | AJ44: 0.1222 | AK44: 0.1133 | AL44: 0.1154 | AM44: 0.1166
A45: 46075.794 | B45: =B44+40 -> 1250 | C45: 0.114 | D45: 0.1154 | E45: 0.1163 | F45: 0.1198 | G45: 0.1196 | H45: 0.1226 | I45: 0.1163 | J45: 0.116 | K45: 0.1215 | L45: 0.1168 | M45: 0.1185 | N45: 0.1165 | O45: 0.1157 | P45: 0.1153 | Q45: 0.1186 | R45: 0.1134 | S45: 0.115 | T45: 0.1179 | V45: 0.114 | W45: 0.1154 | X45: 0.1163 | Y45: 0.1168 | Z45: 0.1185 | AA45: 0.1165 | AB45: 0.1198 | AC45: 0.1196 | AD45: 0.1226 | AE45: 0.1157 | AF45: 0.1153 | AG45: 0.1186 | AH45: 0.1163 | AI45: 0.116 | AJ45: 0.1215 | AK45: 0.1134 | AL45: 0.115 | AM45: 0.1179
B46: =B45+30 -> 1280 | C46: 0.1139 | D46: 0.1141 | E46: 0.1162 | F46: 0.1139 | G46: 0.1148 | H46: 0.1178 | I46: 0.113 | J46: 0.1129 | K46: 0.1167 | L46: 0.1134 | M46: 0.1138 | N46: 0.1132 | O46: 0.1114 | P46: 0.1115 | Q46: 0.1148 | R46: 0.1116 | S46: 0.1146 | T46: 0.115 | V46: 0.1139 | W46: 0.1141 | X46: 0.1162 | Y46: 0.1134 | Z46: 0.1138 | AA46: 0.1132 | AB46: 0.1139 | AC46: 0.1148 | AD46: 0.1178 | AE46: 0.1114 | AF46: 0.1115 | AG46: 0.1148 | AH46: 0.113 | AI46: 0.1129 | AJ46: 0.1167 | AK46: 0.1116 | AL46: 0.1146 | AM46: 0.115
B47: =B46+30 -> 1310 | C47: 0.1135 | D47: 0.1142 | E47: 0.1164 | F47: 0.1141 | G47: 0.1148 | H47: 0.1181 | I47: 0.113 | J47: 0.1129 | K47: 0.1167 | L47: 0.1136 | M47: 0.1139 | N47: 0.1134 | O47: 0.1118 | P47: 0.1117 | Q47: 0.1151 | R47: 0.1115 | S47: 0.1143 | T47: 0.1152 | V47: 0.1135 | W47: 0.1142 | X47: 0.1164 | Y47: 0.1136 | Z47: 0.1139 | AA47: 0.1134 | AB47: 0.1141 | AC47: 0.1148 | AD47: 0.1181 | AE47: 0.1118 | AF47: 0.1117 | AG47: 0.1151 | AH47: 0.113 | AI47: 0.1129 | AJ47: 0.1167 | AK47: 0.1115 | AL47: 0.1143 | AM47: 0.1152
B48: =B47+30 -> 1340 | C48: 0.1136 | D48: 0.1142 | E48: 0.1165 | F48: 0.1142 | G48: 0.1148 | H48: 0.1183 | I48: 0.1131 | J48: 0.1129 | K48: 0.1168 | L48: 0.1136 | M48: 0.114 | N48: 0.113 | O48: 0.1118 | P48: 0.1118 | Q48: 0.1152 | R48: 0.1113 | S48: 0.1141 | T48: 0.115 | V48: 0.1136 | W48: 0.1142 | X48: 0.1165 | Y48: 0.1136 | Z48: 0.114 | AA48: 0.113 | AB48: 0.1142 | AC48: 0.1148 | AD48: 0.1183 | AE48: 0.1118 | AF48: 0.1118 | AG48: 0.1152 | AH48: 0.1131 | AI48: 0.1129 | AJ48: 0.1168 | AK48: 0.1113 | AL48: 0.1141 | AM48: 0.115
B49: =B48+30 -> 1370 | C49: 0.1135 | D49: 0.1141 | E49: 0.1148 | F49: 0.114 | G49: 0.1149 | H49: 0.1182 | I49: 0.1129 | J49: 0.1128 | K49: 0.1168 | L49: 0.1134 | M49: 0.1137 | N49: 0.1129 | O49: 0.1116 | P49: 0.1115 | Q49: 0.115 | R49: 0.1113 | S49: 0.114 | T49: 0.1161 | V49: 0.1135 | W49: 0.1141 | X49: 0.1148 | Y49: 0.1134 | Z49: 0.1137 | AA49: 0.1129 | AB49: 0.114 | AC49: 0.1149 | AD49: 0.1182 | AE49: 0.1116 | AF49: 0.1115 | AG49: 0.115 | AH49: 0.1129 | AI49: 0.1128 | AJ49: 0.1168 | AK49: 0.1113 | AL49: 0.114 | AM49: 0.1161
B50: =B49+30 -> 1400 | C50: 0.1133 | D50: 0.1139 | E50: 0.1144 | F50: 0.1141 | G50: 0.1149 | H50: 0.1183 | I50: 0.113 | J50: 0.1127 | K50: 0.1167 | L50: 0.1137 | M50: 0.1141 | N50: 0.1132 | O50: 0.1113 | P50: 0.1119 | Q50: 0.1151 | R50: 0.1111 | S50: 0.114 | T50: 0.1159 | V50: 0.1133 | W50: 0.1139 | X50: 0.1144 | Y50: 0.1137 | Z50: 0.1141 | AA50: 0.1132 | AB50: 0.1141 | AC50: 0.1149 | AD50: 0.1183 | AE50: 0.1113 | AF50: 0.1119 | AG50: 0.1151 | AH50: 0.113 | AI50: 0.1127 | AJ50: 0.1167 | AK50: 0.1111 | AL50: 0.114 | AM50: 0.1159
B51: =B50+30 -> 1430 | C51: 0.1134 | D51: 0.1138 | E51: 0.1148 | F51: 0.114 | G51: 0.1147 | H51: 0.1183 | I51: 0.1126 | J51: 0.1126 | K51: 0.1166 | L51: 0.1137 | M51: 0.1137 | N51: 0.1129 | O51: 0.1115 | P51: 0.1122 | Q51: 0.1151 | R51: 0.1112 | S51: 0.1139 | T51: 0.1151 | V51: 0.1134 | W51: 0.1138 | X51: 0.1148 | Y51: 0.1137 | Z51: 0.1137 | AA51: 0.1129 | AB51: 0.114 | AC51: 0.1147 | AD51: 0.1183 | AE51: 0.1115 | AF51: 0.1122 | AG51: 0.1151 | AH51: 0.1126 | AI51: 0.1126 | AJ51: 0.1166 | AK51: 0.1112 | AL51: 0.1139 | AM51: 0.1151
B52: =B51+30 -> 1460 | C52: 0.1132 | D52: 0.1135 | E52: 0.1147 | F52: 0.1141 | G52: 0.1147 | H52: 0.1182 | I52: 0.1126 | J52: 0.1126 | K52: 0.1164 | L52: 0.1136 | M52: 0.1137 | N52: 0.1129 | O52: 0.1115 | P52: 0.1119 | Q52: 0.115 | R52: 0.1108 | S52: 0.1137 | T52: 0.1148 | V52: 0.1132 | W52: 0.1135 | X52: 0.1147 | Y52: 0.1136 | Z52: 0.1137 | AA52: 0.1129 | AB52: 0.1141 | AC52: 0.1147 | AD52: 0.1182 | AE52: 0.1115 | AF52: 0.1119 | AG52: 0.115 | AH52: 0.1126 | AI52: 0.1126 | AJ52: 0.1164 | AK52: 0.1108 | AL52: 0.1137 | AM52: 0.1148
B53: =B52+30 -> 1490 | C53: 0.1131 | D53: 0.1137 | E53: 0.1151 | F53: 0.1145 | G53: 0.1149 | H53: 0.1183 | I53: 0.1126 | J53: 0.1123 | K53: 0.1161 | L53: 0.1135 | M53: 0.1137 | N53: 0.1129 | O53: 0.1116 | P53: 0.112 | Q53: 0.1155 | R53: 0.1109 | S53: 0.114 | T53: 0.1152 | V53: 0.1131 | W53: 0.1137 | X53: 0.1151 | Y53: 0.1135 | Z53: 0.1137 | AA53: 0.1129 | AB53: 0.1145 | AC53: 0.1149 | AD53: 0.1183 | AE53: 0.1116 | AF53: 0.112 | AG53: 0.1155 | AH53: 0.1126 | AI53: 0.1123 | AJ53: 0.1161 | AK53: 0.1109 | AL53: 0.114 | AM53: 0.1152
B54: =B53+30 -> 1520 | C54: 0.113 | D54: 0.1136 | E54: 0.1151 | F54: 0.1146 | G54: 0.1151 | H54: 0.1187 | I54: 0.1125 | J54: 0.1123 | K54: 0.1165 | L54: 0.1133 | M54: 0.1135 | N54: 0.1128 | O54: 0.1115 | P54: 0.1119 | Q54: 0.1155 | R54: 0.1108 | S54: 0.1141 | T54: 0.1156 | V54: 0.113 | W54: 0.1136 | X54: 0.1151 | Y54: 0.1133 | Z54: 0.1135 | AA54: 0.1128 | AB54: 0.1146 | AC54: 0.1151 | AD54: 0.1187 | AE54: 0.1115 | AF54: 0.1119 | AG54: 0.1155 | AH54: 0.1125 | AI54: 0.1123 | AJ54: 0.1165 | AK54: 0.1108 | AL54: 0.1141 | AM54: 0.1156
B55: =B54+30 -> 1550 | C55: 0.1129 | D55: 0.1137 | E55: 0.1155 | F55: 0.1148 | G55: 0.1153 | H55: 0.1187 | I55: 0.1124 | J55: 0.1123 | K55: 0.1161 | L55: 0.1133 | M55: 0.1136 | N55: 0.113 | O55: 0.1117 | P55: 0.1121 | Q55: 0.1155 | R55: 0.1108 | S55: 0.1138 | T55: 0.1152 | V55: 0.1129 | W55: 0.1137 | X55: 0.1155 | Y55: 0.1133 | Z55: 0.1136 | AA55: 0.113 | AB55: 0.1148 | AC55: 0.1153 | AD55: 0.1187 | AE55: 0.1117 | AF55: 0.1121 | AG55: 0.1155 | AH55: 0.1124 | AI55: 0.1123 | AJ55: 0.1161 | AK55: 0.1108 | AL55: 0.1138 | AM55: 0.1152
B56: =B55+30 -> 1580 | C56: 0.1129 | D56: 0.1138 | E56: 0.1156 | F56: 0.1147 | G56: 0.1151 | H56: 0.1189 | I56: 0.1124 | J56: 0.1122 | K56: 0.1161 | L56: 0.1134 | M56: 0.1135 | N56: 0.1127 | O56: 0.1117 | P56: 0.1121 | Q56: 0.1155 | R56: 0.1109 | S56: 0.1138 | T56: 0.1152 | V56: 0.1129 | W56: 0.1138 | X56: 0.1156 | Y56: 0.1134 | Z56: 0.1135 | AA56: 0.1127 | AB56: 0.1147 | AC56: 0.1151 | AD56: 0.1189 | AE56: 0.1117 | AF56: 0.1121 | AG56: 0.1155 | AH56: 0.1124 | AI56: 0.1122 | AJ56: 0.1161 | AK56: 0.1109 | AL56: 0.1138 | AM56: 0.1152
B57: =B56+30 -> 1610 | C57: 0.1128 | D57: 0.1138 | E57: 0.1157 | F57: 0.1148 | G57: 0.1155 | H57: 0.1189 | I57: 0.1121 | J57: 0.1121 | K57: 0.1159 | L57: 0.1133 | M57: 0.1134 | N57: 0.1127 | O57: 0.1116 | P57: 0.1121 | Q57: 0.1155 | R57: 0.1106 | S57: 0.1137 | T57: 0.1155 | V57: 0.1128 | W57: 0.1138 | X57: 0.1157 | Y57: 0.1133 | Z57: 0.1134 | AA57: 0.1127 | AB57: 0.1148 | AC57: 0.1155 | AD57: 0.1189 | AE57: 0.1116 | AF57: 0.1121 | AG57: 0.1155 | AH57: 0.1121 | AI57: 0.1121 | AJ57: 0.1159 | AK57: 0.1106 | AL57: 0.1137 | AM57: 0.1155
... B89: =B88+30 -> 2570 | C89: 0.1096 | D89: 0.112 | E89: 0.1137 | F89: 0.1142 | G89: 0.1209 | H89: 0.1232 | I89: 0.1089 | J89: 0.1089 | K89: 0.1116 | L89: 0.11 | M89: 0.1105 | N89: 0.1105 | O89: 0.109 | P89: 0.1133 | Q89: 0.1224 | R89: 0.1074 | S89: 0.1115 | T89: 0.1122 | V89: 0.1096 | W89: 0.112 | X89: 0.1137 | Y89: 0.11 | Z89: 0.1105 | AA89: 0.1105 | AB89: 0.1142 | AC89: 0.1209 | AD89: 0.1232 | AE89: 0.109 | AF89: 0.1133 | AG89: 0.1224 | AH89: 0.1089 | AI89: 0.1089 | AJ89: 0.1116 | AK89: 0.1074 | AL89: 0.1115 | AM89: 0.1122
A90: 46076.732 | B90: =B89+30 -> 2600 | C90: 0.1093 | D90: 0.1123 | E90: 0.1137 | F90: 0.1143 | G90: 0.1215 | H90: 0.1234 | I90: 0.1086 | J90: 0.1086 | K90: 0.1114 | L90: 0.1098 | M90: 0.1105 | N90: 0.1104 | O90: 0.109 | P90: 0.1136 | Q90: 0.1228 | R90: 0.1074 | S90: 0.1112 | T90: 0.1121 | V90: 0.1093 | W90: 0.1123 | X90: 0.1137 | Y90: 0.1098 | Z90: 0.1105 | AA90: 0.1104 | AB90: 0.1143 | AC90: 0.1215 | AD90: 0.1234 | AE90: 0.109 | AF90: 0.1136 | AG90: 0.1228 | AH90: 0.1086 | AI90: 0.1086 | AJ90: 0.1114 | AK90: 0.1074 | AL90: 0.1112 | AM90: 0.1121
B93: △ | C93: =C90-C3 -> -0.0072 | D93: =D90-D3 -> -0.0034 | E93: =E90-E3 -> -0.0022 | F93: =F90-F3 -> -0.0008 | G93: =G90-G3 -> 0.0068 | H93: =H90-H3 -> 0.0082 | I93: =I90-I3 -> -0.0071 | J93: =J90-J3 -> -0.0069 | ... T93: =T90-T3 -> -0.0061

Sheet r1.raw.M
A1: Data-Time | B1: Time | C1: Dark | L1: IR | V1: RAW
A2: Data-Time | B2: Time 1 | C2: Dark-M-C1 | D2: Dark-M-C2 | E2: Dark-M-C3 | F2: Dark-M-Ac1 | G2: Dark-M-Ac2 | H2: Dark-M-Ac3 | I2: Dark-M-S1 | J2: Dark-M-S2 | K2: Dark-M-S3 | L2: IR-M-C1 | M2: IR-M-C2 | N2: IR-M-C3 | O2: IR-M-Ac1 | P2: IR-M-Ac2 | Q2: IR-M-Ac3 | R2: IR-M-S1 | S2: IR-M-S2 | T2: IR-M-S3 | U2: Tips | V2: C-D | Y2: C-I | AB2: Ac-D | AE2: Ac-I | AH2: S-D | AK2: S-I
A3: 46063.842 | B3: 0 | C3: 0.1575 | D3: 0.1583 | E3: 0.1556 | F3: 0.1549 | G3: 0.1611 | H3: 0.1577 | I3: 0.1565 | J3: 0.1567 | K3: 0.1585 | L3: 0.1568 | M3: 0.1551 | N3: 0.1573 | O3: 0.1592 | P3: 0.154 | Q3: 0.1559 | R3: 0.1591 | S3: 0.1586 | T3: 0.1724 | V3: 0.1575 | W3: 0.1583 | X3: 0.1556 | Y3: 0.1568 | Z3: 0.1551 | AA3: 0.1573 | AB3: 0.1549 | AC3: 0.1611 | AD3: 0.1577 | AE3: 0.1592 | AF3: 0.154 | AG3: 0.1559 | AH3: 0.1565 | AI3: 0.1567 | AJ3: 0.1585 | AK3: 0.1591 | AL3: 0.1586 | AM3: 0.1724
B4: =B3+30 -> 30 | C4: 0.1582 | D4: 0.1591 | E4: 0.1567 | F4: 0.1546 | G4: 0.1617 | H4: 0.159 | I4: 0.1568 | J4: 0.157 | K4: 0.1593 | L4: 0.1573 | M4: 0.1558 | N4: 0.1578 | O4: 0.1606 | P4: 0.1548 | Q4: 0.157 | R4: 0.1598 | S4: 0.1594 | T4: 0.1735 | V4: 0.1582 | W4: 0.1591 | X4: 0.1567 | Y4: 0.1573 | Z4: 0.1558 | AA4: 0.1578 | AB4: 0.1546 | AC4: 0.1617 | AD4: 0.159 | AE4: 0.1606 | AF4: 0.1548 | AG4: 0.157 | AH4: 0.1568 | AI4: 0.157 | AJ4: 0.1593 | AK4: 0.1598 | AL4: 0.1594 | AM4: 0.1735
B5: =B4+30 -> 60 | C5: 0.1591 | D5: 0.1601 | E5: 0.1561 | F5: 0.1571 | G5: 0.1622 | H5: 0.1616 | I5: 0.1583 | J5: 0.1585 | K5: 0.1609 | L5: 0.1586 | M5: 0.157 | N5: 0.1592 | O5: 0.1608 | P5: 0.1539 | Q5: 0.159 | R5: 0.1604 | S5: 0.1605 | T5: 0.1744 | V5: 0.1591 | W5: 0.1601 | X5: 0.1561 | Y5: 0.1586 | Z5: 0.157 | AA5: 0.1592 | AB5: 0.1571 | AC5: 0.1622 | AD5: 0.1616 | AE5: 0.1608 | AF5: 0.1539 | AG5: 0.159 | AH5: 0.1583 | AI5: 0.1585 | AJ5: 0.1609 | AK5: 0.1604 | AL5: 0.1605 | AM5: 0.1744
B6: =B5+30 -> 90 | C6: 0.1592 | D6: 0.1596 | E6: 0.1571 | F6: 0.1561 | G6: 0.1616 | H6: 0.1587 | I6: 0.1586 | J6: 0.1583 | K6: 0.1614 | L6: 0.1566 | M6: 0.1566 | N6: 0.1599 | O6: 0.16 | P6: 0.1541 | Q6: 0.1578 | R6: 0.1609 | S6: 0.1591 | T6: 0.1748 | V6: 0.1592 | W6: 0.1596 | X6: 0.1571 | Y6: 0.1566 | Z6: 0.1566 | AA6: 0.1599 | AB6: 0.1561 | AC6: 0.1616 | AD6: 0.1587 | AE6: 0.16 | AF6: 0.1541 | AG6: 0.1578 | AH6: 0.1586 | AI6: 0.1583 | AJ6: 0.1614 | AK6: 0.1609 | AL6: 0.1591 | AM6: 0.1748
B7: =B6+30 -> 120 | C7: 0.1583 | D7: 0.1605 | E7: 0.1564 | F7: 0.1592 | G7: 0.1642 | H7: 0.1627 | I7: 0.1569 | J7: 0.1543 | K7: 0.1575 | L7: 0.1586 | M7: 0.1577 | N7: 0.1594 | O7: 0.1608 | P7: 0.1556 | Q7: 0.1568 | R7: 0.1607 | S7: 0.1594 | T7: 0.1748 | V7: 0.1583 | W7: 0.1605 | X7: 0.1564 | Y7: 0.1586 | Z7: 0.1577 | AA7: 0.1594 | AB7: 0.1592 | AC7: 0.1642 | AD7: 0.1627 | AE7: 0.1608 | AF7: 0.1556 | AG7: 0.1568 | AH7: 0.1569 | AI7: 0.1543 | AJ7: 0.1575 | AK7: 0.1607 | AL7: 0.1594 | AM7: 0.1748
B8: =B7+30 -> 150 | C8: 0.1588 | D8: 0.1594 | E8: 0.156 | F8: 0.1557 | G8: 0.1646 | H8: 0.1604 | I8: 0.1538 | J8: 0.1547 | K8: 0.1563 | L8: 0.1592 | M8: 0.1572 | N8: 0.159 | O8: 0.1604 | P8: 0.1559 | Q8: 0.1564 | R8: 0.16 | S8: 0.1583 | T8: 0.175 | V8: 0.1588 | W8: 0.1594 | X8: 0.156 | Y8: 0.1592 | Z8: 0.1572 | AA8: 0.159 | AB8: 0.1557 | AC8: 0.1646 | AD8: 0.1604 | AE8: 0.1604 | AF8: 0.1559 | AG8: 0.1564 | AH8: 0.1538 | AI8: 0.1547 | AJ8: 0.1563 | AK8: 0.16 | AL8: 0.1583 | AM8: 0.175
B9: =B8+30 -> 180 | C9: 0.158 | D9: 0.1583 | E9: 0.1564 | F9: 0.1538 | G9: 0.1621 | H9: 0.1597 | I9: 0.1563 | J9: 0.1564 | K9: 0.1587 | L9: 0.158 | M9: 0.156 | N9: 0.1587 | O9: 0.1601 | P9: 0.1559 | Q9: 0.158 | R9: 0.1599 | S9: 0.1587 | T9: 0.1751 | V9: 0.158 | W9: 0.1583 | X9: 0.1564 | Y9: 0.158 | Z9: 0.156 | AA9: 0.1587 | AB9: 0.1538 | AC9: 0.1621 | AD9: 0.1597 | AE9: 0.1601 | AF9: 0.1559 | AG9: 0.158 | AH9: 0.1563 | AI9: 0.1564 | AJ9: 0.1587 | AK9: 0.1599 | AL9: 0.1587 | AM9: 0.1751
B10: =B9+30 -> 210 | C10: 0.1595 | D10: 0.1594 | E10: 0.1564 | F10: 0.1553 | G10: 0.1644 | H10: 0.1614 | I10: 0.1557 | J10: 0.1566 | K10: 0.1589 | L10: 0.1574 | M10: 0.1552 | N10: 0.1593 | O10: 0.159 | P10: 0.1548 | Q10: 0.1564 | R10: 0.1597 | S10: 0.1591 | T10: 0.1752 | V10: 0.1595 | W10: 0.1594 | X10: 0.1564 | Y10: 0.1574 | Z10: 0.1552 | AA10: 0.1593 | AB10: 0.1553 | AC10: 0.1644 | AD10: 0.1614 | AE10: 0.159 | AF10: 0.1548 | AG10: 0.1564 | AH10: 0.1557 | AI10: 0.1566 | AJ10: 0.1589 | AK10: 0.1597 | AL10: 0.1591 | AM10: 0.1752
B11: =B10+30 -> 240 | C11: 0.1579 | D11: 0.1592 | E11: 0.1559 | F11: 0.1559 | G11: 0.1645 | H11: 0.1621 | I11: 0.1554 | J11: 0.1565 | K11: 0.1594 | L11: 0.1562 | M11: 0.1555 | N11: 0.1574 | O11: 0.1598 | P11: 0.1554 | Q11: 0.1582 | R11: 0.159 | S11: 0.1589 | T11: 0.1747 | V11: 0.1579 | W11: 0.1592 | X11: 0.1559 | Y11: 0.1562 | Z11: 0.1555 | AA11: 0.1574 | AB11: 0.1559 | AC11: 0.1645 | AD11: 0.1621 | AE11: 0.1598 | AF11: 0.1554 | AG11: 0.1582 | AH11: 0.1554 | AI11: 0.1565 | AJ11: 0.1594 | AK11: 0.159 | AL11: 0.1589 | AM11: 0.1747
B12: =B11+30 -> 270 | C12: 0.158 | D12: 0.1587 | E12: 0.1556 | F12: 0.1565 | G12: 0.1636 | H12: 0.1629 | I12: 0.1553 | J12: 0.1554 | K12: 0.1588 | L12: 0.1559 | M12: 0.1537 | N12: 0.1574 | O12: 0.1596 | P12: 0.1555 | Q12: 0.1586 | R12: 0.1589 | S12: 0.1586 | T12: 0.1746 | V12: 0.158 | W12: 0.1587 | X12: 0.1556 | Y12: 0.1559 | Z12: 0.1537 | AA12: 0.1574 | AB12: 0.1565 | AC12: 0.1636 | AD12: 0.1629 | AE12: 0.1596 | AF12: 0.1555 | AG12: 0.1586 | AH12: 0.1553 | AI12: 0.1554 | AJ12: 0.1588 | AK12: 0.1589 | AL12: 0.1586 | AM12: 0.1746
B13: =B12+30 -> 300 | C13: 0.1579 | D13: 0.1587 | E13: 0.1559 | F13: 0.1569 | G13: 0.1644 | H13: 0.1631 | I13: 0.1548 | J13: 0.1556 | K13: 0.1585 | L13: 0.1572 | M13: 0.1525 | N13: 0.1558 | O13: 0.1609 | P13: 0.1551 | Q13: 0.1591 | R13: 0.1581 | S13: 0.1586 | T13: 0.175 | V13: 0.1579 | W13: 0.1587 | X13: 0.1559 | Y13: 0.1572 | Z13: 0.1525 | AA13: 0.1558 | AB13: 0.1569 | AC13: 0.1644 | AD13: 0.1631 | AE13: 0.1609 | AF13: 0.1551 | AG13: 0.1591 | AH13: 0.1548 | AI13: 0.1556 | AJ13: 0.1585 | AK13: 0.1581 | AL13: 0.1586 | AM13: 0.175
B14: =B13+30 -> 330 | C14: 0.1569 | D14: 0.1573 | E14: 0.1552 | F14: 0.1575 | G14: 0.1649 | H14: 0.1629 | I14: 0.1537 | J14: 0.1554 | K14: 0.1585 | L14: 0.1565 | M14: 0.1522 | N14: 0.1546 | O14: 0.1599 | P14: 0.1545 | Q14: 0.1586 | R14: 0.158 | S14: 0.1581 | T14: 0.1754 | V14: 0.1569 | W14: 0.1573 | X14: 0.1552 | Y14: 0.1565 | Z14: 0.1522 | AA14: 0.1546 | AB14: 0.1575 | AC14: 0.1649 | AD14: 0.1629 | AE14: 0.1599 | AF14: 0.1545 | AG14: 0.1586 | AH14: 0.1537 | AI14: 0.1554 | AJ14: 0.1585 | AK14: 0.158 | AL14: 0.1581 | AM14: 0.1754
B15: =B14+30 -> 360 | C15: 0.1566 | D15: 0.158 | E15: 0.1556 | F15: 0.1577 | G15: 0.1656 | H15: 0.1631 | I15: 0.155 | J15: 0.157 | K15: 0.1581 | L15: 0.1575 | M15: 0.152 | N15: 0.1569 | O15: 0.1616 | P15: 0.1558 | Q15: 0.1594 | R15: 0.1578 | S15: 0.1576 | T15: 0.1753 | V15: 0.1566 | W15: 0.158 | X15: 0.1556 | Y15: 0.1575 | Z15: 0.152 | AA15: 0.1569 | AB15: 0.1577 | AC15: 0.1656 | AD15: 0.1631 | AE15: 0.1616 | AF15: 0.1558 | AG15: 0.1594 | AH15: 0.155 | AI15: 0.157 | AJ15: 0.1581 | AK15: 0.1578 | AL15: 0.1576 | AM15: 0.1753
... B29: =B28+30 -> 780 | C29: 0.1507 | D29: 0.1525 | E29: 0.1496 | F29: 0.1533 | G29: 0.1605 | H29: 0.1585 | I29: 0.1504 | J29: 0.1514 | K29: 0.1521 | L29: 0.1516 | M29: 0.1498 | N29: 0.1516 | O29: 0.1567 | P29: 0.1513 | Q29: 0.1553 | R29: 0.1528 | S29: 0.1532 | T29: 0.1534 | V29: 0.1507 | W29: 0.1525 | X29: 0.1496 | Y29: 0.1516 | Z29: 0.1498 | AA29: 0.1516 | AB29: 0.1533 | AC29: 0.1605 | AD29: 0.1585 | AE29: 0.1567 | AF29: 0.1513 | AG29: 0.1553 | AH29: 0.1504 | AI29: 0.1514 | AJ29: 0.1521 | AK29: 0.1528 | AL29: 0.1532 | AM29: 0.1534
B30: =B29+40 -> 820 | C30: 0.1505 | D30: 0.1518 | E30: 0.1491 | F30: 0.1526 | G30: 0.1595 | H30: 0.1582 | I30: 0.15 | J30: 0.1511 | K30: 0.1521 | L30: 0.1513 | M30: 0.1494 | N30: 0.1513 | O30: 0.1566 | P30: 0.1503 | Q30: 0.155 | R30: 0.1525 | S30: 0.1529 | T30: 0.1528 | V30: 0.1505 | W30: 0.1518 | X30: 0.1491 | Y30: 0.1513 | Z30: 0.1494 | AA30: 0.1513 | AB30: 0.1526 | AC30: 0.1595 | AD30: 0.1582 | AE30: 0.1566 | AF30: 0.1503 | AG30: 0.155 | AH30: 0.15 | AI30: 0.1511 | AJ30: 0.1521 | AK30: 0.1525 | AL30: 0.1529 | AM30: 0.1528
B31: =B30+30 -> 850 | C31: 0.1507 | D31: 0.1514 | E31: 0.1485 | F31: 0.1519 | G31: 0.1591 | H31: 0.1579 | I31: 0.1484 | J31: 0.1502 | K31: 0.1521 | L31: 0.1506 | M31: 0.1489 | N31: 0.1503 | O31: 0.156 | P31: 0.1494 | Q31: 0.1547 | R31: 0.1521 | S31: 0.1524 | T31: 0.1522 | V31: 0.1507 | W31: 0.1514 | X31: 0.1485 | Y31: 0.1506 | Z31: 0.1489 | AA31: 0.1503 | AB31: 0.1519 | AC31: 0.1591 | AD31: 0.1579 | AE31: 0.156 | AF31: 0.1494 | AG31: 0.1547 | AH31: 0.1484 | AI31: 0.1502 | AJ31: 0.1521 | AK31: 0.1521 | AL31: 0.1524 | AM31: 0.1522
B32: =B31+30 -> 880 | C32: 0.1496 | D32: 0.151 | E32: 0.1483 | F32: 0.1509 | G32: 0.1578 | H32: 0.1572 | I32: 0.1484 | J32: 0.1493 | K32: 0.1518 | L32: 0.1505 | M32: 0.1487 | N32: 0.1509 | O32: 0.1558 | P32: 0.1494 | Q32: 0.154 | R32: 0.1521 | S32: 0.1522 | T32: 0.1523 | V32: 0.1496 | W32: 0.151 | X32: 0.1483 | Y32: 0.1505 | Z32: 0.1487 | AA32: 0.1509 | AB32: 0.1509 | AC32: 0.1578 | AD32: 0.1572 | AE32: 0.1558 | AF32: 0.1494 | AG32: 0.154 | AH32: 0.1484 | AI32: 0.1493 | AJ32: 0.1518 | AK32: 0.1521 | AL32: 0.1522 | AM32: 0.1523
B33: =B32+30 -> 910 | C33: 0.1491 | D33: 0.1506 | E33: 0.1476 | F33: 0.1509 | G33: 0.1579 | H33: 0.1567 | I33: 0.1481 | J33: 0.1487 | K33: 0.1517 | L33: 0.1504 | M33: 0.1481 | N33: 0.1505 | O33: 0.1558 | P33: 0.149 | Q33: 0.1535 | R33: 0.1516 | S33: 0.1518 | T33: 0.152 | V33: 0.1491 | W33: 0.1506 | X33: 0.1476 | Y33: 0.1504 | Z33: 0.1481 | AA33: 0.1505 | AB33: 0.1509 | AC33: 0.1579 | AD33: 0.1567 | AE33: 0.1558 | AF33: 0.149 | AG33: 0.1535 | AH33: 0.1481 | AI33: 0.1487 | AJ33: 0.1517 | AK33: 0.1516 | AL33: 0.1518 | AM33: 0.152
B34: =B33+30 -> 940 | C34: 0.1493 | D34: 0.1503 | E34: 0.1477 | F34: 0.1499 | G34: 0.1569 | H34: 0.1566 | I34: 0.1477 | J34: 0.1488 | K34: 0.151 | L34: 0.1502 | M34: 0.1476 | N34: 0.1501 | O34: 0.1552 | P34: 0.1485 | Q34: 0.1534 | R34: 0.1515 | S34: 0.1518 | T34: 0.1514 | V34: 0.1493 | W34: 0.1503 | X34: 0.1477 | Y34: 0.1502 | Z34: 0.1476 | AA34: 0.1501 | AB34: 0.1499 | AC34: 0.1569 | AD34: 0.1566 | AE34: 0.1552 | AF34: 0.1485 | AG34: 0.1534 | AH34: 0.1477 | AI34: 0.1488 | AJ34: 0.151 | AK34: 0.1515 | AL34: 0.1518 | AM34: 0.1514
B35: =B34+30 -> 970 | C35: 0.1487 | D35: 0.1502 | E35: 0.1474 | F35: 0.1507 | G35: 0.1573 | H35: 0.1566 | I35: 0.1477 | J35: 0.1485 | K35: 0.151 | L35: 0.1498 | M35: 0.1474 | N35: 0.1496 | O35: 0.1547 | P35: 0.1483 | Q35: 0.1531 | R35: 0.1513 | S35: 0.1513 | T35: 0.1516 | V35: 0.1487 | W35: 0.1502 | X35: 0.1474 | Y35: 0.1498 | Z35: 0.1474 | AA35: 0.1496 | AB35: 0.1507 | AC35: 0.1573 | AD35: 0.1566 | AE35: 0.1547 | AF35: 0.1483 | AG35: 0.1531 | AH35: 0.1477 | AI35: 0.1485 | AJ35: 0.151 | AK35: 0.1513 | AL35: 0.1513 | AM35: 0.1516
B36: =B35+30 -> 1000 | C36: 0.1484 | D36: 0.1499 | E36: 0.1473 | F36: 0.1502 | G36: 0.1569 | H36: 0.1564 | I36: 0.147 | J36: 0.1479 | K36: 0.1506 | L36: 0.1496 | M36: 0.1473 | N36: 0.1494 | O36: 0.1548 | P36: 0.1483 | Q36: 0.1532 | R36: 0.1511 | S36: 0.1512 | T36: 0.1515 | V36: 0.1484 | W36: 0.1499 | X36: 0.1473 | Y36: 0.1496 | Z36: 0.1473 | AA36: 0.1494 | AB36: 0.1502 | AC36: 0.1569 | AD36: 0.1564 | AE36: 0.1548 | AF36: 0.1483 | AG36: 0.1532 | AH36: 0.147 | AI36: 0.1479 | AJ36: 0.1506 | AK36: 0.1511 | AL36: 0.1512 | AM36: 0.1515
B37: =B36+10 -> 1010 | C37: 0.1481 | D37: 0.1495 | E37: 0.1466 | F37: 0.1496 | G37: 0.1563 | H37: 0.156 | I37: 0.1471 | J37: 0.1479 | K37: 0.1502 | L37: 0.1493 | M37: 0.147 | N37: 0.1489 | O37: 0.1544 | P37: 0.1483 | Q37: 0.1529 | R37: 0.1508 | S37: 0.1508 | T37: 0.151 | V37: 0.1481 | W37: 0.1495 | X37: 0.1466 | Y37: 0.1493 | Z37: 0.147 | AA37: 0.1489 | AB37: 0.1496 | AC37: 0.1563 | AD37: 0.156 | AE37: 0.1544 | AF37: 0.1483 | AG37: 0.1529 | AH37: 0.1471 | AI37: 0.1479 | AJ37: 0.1502 | AK37: 0.1508 | AL37: 0.1508 | AM37: 0.151
B38: =B37+30 -> 1040 | C38: 0.1481 | D38: 0.1491 | E38: 0.1468 | F38: 0.1496 | G38: 0.1562 | H38: 0.1559 | I38: 0.1467 | J38: 0.148 | K38: 0.1499 | L38: 0.1489 | M38: 0.1468 | N38: 0.1483 | O38: 0.154 | P38: 0.148 | Q38: 0.1527 | R38: 0.1505 | S38: 0.1507 | T38: 0.1509 | V38: 0.1481 | W38: 0.1491 | X38: 0.1468 | Y38: 0.1489 | Z38: 0.1468 | AA38: 0.1483 | AB38: 0.1496 | AC38: 0.1562 | AD38: 0.1559 | AE38: 0.154 | AF38: 0.148 | AG38: 0.1527 | AH38: 0.1467 | AI38: 0.148 | AJ38: 0.1499 | AK38: 0.1505 | AL38: 0.1507 | AM38: 0.1509
B39: =B38+30 -> 1070 | C39: 0.1479 | D39: 0.1488 | E39: 0.1467 | F39: 0.1496 | G39: 0.1562 | H39: 0.1558 | I39: 0.1466 | J39: 0.1482 | K39: 0.1495 | L39: 0.1487 | M39: 0.1465 | N39: 0.1482 | O39: 0.1536 | P39: 0.148 | Q39: 0.1528 | R39: 0.1502 | S39: 0.1504 | T39: 0.1508 | V39: 0.1479 | W39: 0.1488 | X39: 0.1467 | Y39: 0.1487 | Z39: 0.1465 | AA39: 0.1482 | AB39: 0.1496 | AC39: 0.1562 | AD39: 0.1558 | AE39: 0.1536 | AF39: 0.148 | AG39: 0.1528 | AH39: 0.1466 | AI39: 0.1482 | AJ39: 0.1495 | AK39: 0.1502 | AL39: 0.1504 | AM39: 0.1508
B40: =B39+30 -> 1100 | C40: 0.1478 | D40: 0.1483 | E40: 0.1457 | F40: 0.1494 | G40: 0.1556 | H40: 0.1555 | I40: 0.1464 | J40: 0.1481 | K40: 0.1489 | L40: 0.1482 | M40: 0.1461 | N40: 0.148 | O40: 0.1535 | P40: 0.1475 | Q40: 0.1525 | R40: 0.1503 | S40: 0.1504 | T40: 0.1504 | V40: 0.1478 | W40: 0.1483 | X40: 0.1457 | Y40: 0.1482 | Z40: 0.1461 | AA40: 0.148 | AB40: 0.1494 | AC40: 0.1556 | AD40: 0.1555 | AE40: 0.1535 | AF40: 0.1475 | AG40: 0.1525 | AH40: 0.1464 | AI40: 0.1481 | AJ40: 0.1489 | AK40: 0.1503 | AL40: 0.1504 | AM40: 0.1504
B41: =B40+30 -> 1130 | C41: 0.1472 | D41: 0.148 | E41: 0.1459 | F41: 0.1488 | G41: 0.1552 | H41: 0.1554 | I41: 0.1468 | J41: 0.1482 | K41: 0.1492 | L41: 0.1483 | M41: 0.146 | N41: 0.1476 | O41: 0.1536 | P41: 0.1472 | Q41: 0.1524 | R41: 0.1497 | S41: 0.1497 | T41: 0.15 | V41: 0.1472 | W41: 0.148 | X41: 0.1459 | Y41: 0.1483 | Z41: 0.146 | AA41: 0.1476 | AB41: 0.1488 | AC41: 0.1552 | AD41: 0.1554 | AE41: 0.1536 | AF41: 0.1472 | AG41: 0.1524 | AH41: 0.1468 | AI41: 0.1482 | AJ41: 0.1492 | AK41: 0.1497 | AL41: 0.1497 | AM41: 0.15
B42: =B41+30 -> 1160 | C42: 0.147 | D42: 0.1478 | E42: 0.1455 | F42: 0.1487 | G42: 0.1552 | H42: 0.1553 | I42: 0.146 | J42: 0.1475 | K42: 0.1488 | L42: 0.1477 | M42: 0.1456 | N42: 0.1474 | O42: 0.1529 | P42: 0.147 | Q42: 0.1522 | R42: 0.1494 | S42: 0.1497 | T42: 0.1498 | V42: 0.147 | W42: 0.1478 | X42: 0.1455 | Y42: 0.1477 | Z42: 0.1456 | AA42: 0.1474 | AB42: 0.1487 | AC42: 0.1552 | AD42: 0.1553 | AE42: 0.1529 | AF42: 0.147 | AG42: 0.1522 | AH42: 0.146 | AI42: 0.1475 | AJ42: 0.1488 | AK42: 0.1494 | AL42: 0.1497 | AM42: 0.1498
A43: 46075.762 | B43: =B42+30 -> 1190 | C43: 0.1467 | D43: 0.1474 | E43: 0.1453 | F43: 0.1484 | G43: 0.1549 | H43: 0.1549 | I43: 0.1458 | J43: 0.1474 | K43: 0.1482 | L43: 0.1474 | M43: 0.1456 | N43: 0.1471 | O43: 0.1525 | P43: 0.1469 | Q43: 0.152 | R43: 0.1492 | S43: 0.1492 | T43: 0.1493 | V43: 0.1467 | W43: 0.1474 | X43: 0.1453 | Y43: 0.1474 | Z43: 0.1456 | AA43: 0.1471 | AB43: 0.1484 | AC43: 0.1549 | AD43: 0.1549 | AE43: 0.1525 | AF43: 0.1469 | AG43: 0.152 | AH43: 0.1458 | AI43: 0.1474 | AJ43: 0.1482 | AK43: 0.1492 | AL43: 0.1492 | AM43: 0.1493
A44: 46075.767 | B44: =B43+10 -> 1200 | C44: 0.147 | D44: 0.1476 | E44: 0.1453 | F44: 0.152 | G44: 0.1566 | H44: 0.1583 | I44: 0.15 | J44: 0.1514 | K44: 0.1513 | L44: 0.1493 | M44: 0.1468 | N44: 0.1486 | O44: 0.1546 | P44: 0.1509 | Q44: 0.1565 | R44: 0.1495 | S44: 0.1511 | T44: 0.1518 | V44: 0.147 | W44: 0.1476 | X44: 0.1453 | Y44: 0.1493 | Z44: 0.1468 | AA44: 0.1486 | AB44: 0.152 | AC44: 0.1566 | AD44: 0.1583 | AE44: 0.1546 | AF44: 0.1509 | AG44: 0.1565 | AH44: 0.15 | AI44: 0.1514 | AJ44: 0.1513 | AK44: 0.1495 | AL44: 0.1511 | AM44: 0.1518
A45: 46075.794 | B45: =B44+40 -> 1240 | C45: 0.146 | D45: 0.147 | E45: 0.1451 | F45: 0.1534 | G45: 0.158 | H45: 0.159 | I45: 0.1514 | J45: 0.1528 | K45: 0.153 | L45: 0.1501 | M45: 0.1482 | N45: 0.1501 | O45: 0.156 | P45: 0.1527 | Q45: 0.1578 | R45: 0.1508 | S45: 0.1524 | T45: 0.1525 | V45: 0.146 | W45: 0.147 | X45: 0.1451 | Y45: 0.1501 | Z45: 0.1482 | AA45: 0.1501 | AB45: 0.1534 | AC45: 0.158 | AD45: 0.159 | AE45: 0.156 | AF45: 0.1527 | AG45: 0.1578 | AH45: 0.1514 | AI45: 0.1528 | AJ45: 0.153 | AK45: 0.1508 | AL45: 0.1524 | AM45: 0.1525
B46: =B45+30 -> 1270 | C46: 0.1458 | D46: 0.1471 | E46: 0.1454 | F46: 0.1486 | G46: 0.153 | H46: 0.1542 | I46: 0.146 | J46: 0.1469 | K46: 0.1484 | L46: 0.1467 | M46: 0.1447 | N46: 0.1467 | O46: 0.1516 | P46: 0.1473 | Q46: 0.1516 | R46: 0.1486 | S46: 0.1483 | T46: 0.1492 | V46: 0.1458 | W46: 0.1471 | X46: 0.1454 | Y46: 0.1467 | Z46: 0.1447 | AA46: 0.1467 | AB46: 0.1486 | AC46: 0.153 | AD46: 0.1542 | AE46: 0.1516 | AF46: 0.1473 | AG46: 0.1516 | AH46: 0.146 | AI46: 0.1469 | AJ46: 0.1484 | AK46: 0.1486 | AL46: 0.1483 | AM46: 0.1492
B47: =B46+30 -> 1300 | C47: 0.1461 | D47: 0.1471 | E47: 0.1454 | F47: 0.1488 | G47: 0.1531 | H47: 0.1541 | I47: 0.1455 | J47: 0.147 | K47: 0.1485 | L47: 0.1466 | M47: 0.1446 | N47: 0.147 | O47: 0.1517 | P47: 0.1473 | Q47: 0.1517 | R47: 0.1485 | S47: 0.1484 | T47: 0.1491 | V47: 0.1461 | W47: 0.1471 | X47: 0.1454 | Y47: 0.1466 | Z47: 0.1446 | AA47: 0.147 | AB47: 0.1488 | AC47: 0.1531 | AD47: 0.1541 | AE47: 0.1517 | AF47: 0.1473 | AG47: 0.1517 | AH47: 0.1455 | AI47: 0.147 | AJ47: 0.1485 | AK47: 0.1485 | AL47: 0.1484 | AM47: 0.1491
B48: =B47+30 -> 1330 | C48: 0.146 | D48: 0.1469 | E48: 0.1448 | F48: 0.1489 | G48: 0.1532 | H48: 0.1544 | I48: 0.1457 | J48: 0.1471 | K48: 0.1483 | L48: 0.1461 | M48: 0.1449 | N48: 0.1469 | O48: 0.1518 | P48: 0.1475 | Q48: 0.1522 | R48: 0.1486 | S48: 0.1483 | T48: 0.1492 | V48: 0.146 | W48: 0.1469 | X48: 0.1448 | Y48: 0.1461 | Z48: 0.1449 | AA48: 0.1469 | AB48: 0.1489 | AC48: 0.1532 | AD48: 0.1544 | AE48: 0.1518 | AF48: 0.1475 | AG48: 0.1522 | AH48: 0.1457 | AI48: 0.1471 | AJ48: 0.1483 | AK48: 0.1486 | AL48: 0.1483 | AM48: 0.1492
B49: =B48+30 -> 1360 | C49: 0.1461 | D49: 0.1468 | E49: 0.1448 | F49: 0.149 | G49: 0.1534 | H49: 0.1546 | I49: 0.1454 | J49: 0.1465 | K49: 0.1474 | L49: 0.1455 | M49: 0.1441 | N49: 0.1474 | O49: 0.1514 | P49: 0.1476 | Q49: 0.1524 | R49: 0.148 | S49: 0.1476 | T49: 0.1486 | V49: 0.1461 | W49: 0.1468 | X49: 0.1448 | Y49: 0.1455 | Z49: 0.1441 | AA49: 0.1474 | AB49: 0.149 | AC49: 0.1534 | AD49: 0.1546 | AE49: 0.1514 | AF49: 0.1476 | AG49: 0.1524 | AH49: 0.1454 | AI49: 0.1465 | AJ49: 0.1474 | AK49: 0.148 | AL49: 0.1476 | AM49: 0.1486
B50: =B49+30 -> 1390 | C50: 0.1459 | D50: 0.1465 | E50: 0.1449 | F50: 0.1489 | G50: 0.1535 | H50: 0.1547 | I50: 0.1451 | J50: 0.146 | K50: 0.1474 | L50: 0.1462 | M50: 0.1438 | N50: 0.1459 | O50: 0.1507 | P50: 0.1474 | Q50: 0.1523 | R50: 0.1479 | S50: 0.1474 | T50: 0.1484 | V50: 0.1459 | W50: 0.1465 | X50: 0.1449 | Y50: 0.1462 | Z50: 0.1438 | AA50: 0.1459 | AB50: 0.1489 | AC50: 0.1535 | AD50: 0.1547 | AE50: 0.1507 | AF50: 0.1474 | AG50: 0.1523 | AH50: 0.1451 | AI50: 0.146 | AJ50: 0.1474 | AK50: 0.1479 | AL50: 0.1474 | AM50: 0.1484
B51: =B50+30 -> 1420 | C51: 0.1461 | D51: 0.1463 | E51: 0.1447 | F51: 0.1485 | G51: 0.1526 | H51: 0.1543 | I51: 0.1448 | J51: 0.146 | K51: 0.1471 | L51: 0.1462 | M51: 0.1444 | N51: 0.1467 | O51: 0.1498 | P51: 0.1468 | Q51: 0.1518 | R51: 0.1481 | S51: 0.1473 | T51: 0.149 | V51: 0.1461 | W51: 0.1463 | X51: 0.1447 | Y51: 0.1462 | Z51: 0.1444 | AA51: 0.1467 | AB51: 0.1485 | AC51: 0.1526 | AD51: 0.1543 | AE51: 0.1498 | AF51: 0.1468 | AG51: 0.1518 | AH51: 0.1448 | AI51: 0.146 | AJ51: 0.1471 | AK51: 0.1481 | AL51: 0.1473 | AM51: 0.149
B52: =B51+30 -> 1450 | C52: 0.1454 | D52: 0.1463 | E52: 0.1449 | F52: 0.1466 | G52: 0.1512 | H52: 0.1534 | I52: 0.1443 | J52: 0.1458 | K52: 0.147 | L52: 0.1461 | M52: 0.1437 | N52: 0.1459 | O52: 0.1493 | P52: 0.1459 | Q52: 0.1508 | R52: 0.1475 | S52: 0.1471 | T52: 0.148 | V52: 0.1454 | W52: 0.1463 | X52: 0.1449 | Y52: 0.1461 | Z52: 0.1437 | AA52: 0.1459 | AB52: 0.1466 | AC52: 0.1512 | AD52: 0.1534 | AE52: 0.1493 | AF52: 0.1459 | AG52: 0.1508 | AH52: 0.1443 | AI52: 0.1458 | AJ52: 0.147 | AK52: 0.1475 | AL52: 0.1471 | AM52: 0.148
B53: =B52+30 -> 1480 | C53: 0.1454 | D53: 0.1459 | E53: 0.1445 | F53: 0.1469 | G53: 0.1513 | H53: 0.1527 | I53: 0.1438 | J53: 0.1457 | K53: 0.1461 | L53: 0.146 | M53: 0.1439 | N53: 0.1457 | O53: 0.1496 | P53: 0.1455 | Q53: 0.1503 | R53: 0.1475 | S53: 0.1469 | T53: 0.1484 | V53: 0.1454 | W53: 0.1459 | X53: 0.1445 | Y53: 0.146 | Z53: 0.1439 | AA53: 0.1457 | AB53: 0.1469 | AC53: 0.1513 | AD53: 0.1527 | AE53: 0.1496 | AF53: 0.1455 | AG53: 0.1503 | AH53: 0.1438 | AI53: 0.1457 | AJ53: 0.1461 | AK53: 0.1475 | AL53: 0.1469 | AM53: 0.1484
...

Sheet r1.raw.Syn
A1: Data-Time | B1: Time | C1: Dark | L1: IR | V1: RAW
